2017-10-12 09:13:47 [scrapy.core.scraper] ERROR: Spider error processing <GET https://www.clien.net/service/board/park?&od=T31&po=0> (referer: None)
Traceback (most recent call last):
  File "c:\users\xkdlr\appdata\local\programs\python\python36-32\lib\site-packages\scrapy\utils\defer.py", line 102, in iter_errback
    yield next(it)
  File "c:\users\xkdlr\appdata\local\programs\python\python36-32\lib\site-packages\scrapy\spidermiddlewares\offsite.py", line 29, in process_spider_output
    for x in result:
  File "c:\users\xkdlr\appdata\local\programs\python\python36-32\lib\site-packages\scrapy\spidermiddlewares\referer.py", line 339, in <genexpr>
    return (_set_referer(r) for r in result or ())
  File "c:\users\xkdlr\appdata\local\programs\python\python36-32\lib\site-packages\scrapy\spidermiddlewares\urllength.py", line 37, in <genexpr>
    return (r for r in result or () if _filter(r))
  File "c:\users\xkdlr\appdata\local\programs\python\python36-32\lib\site-packages\scrapy\spidermiddlewares\depth.py", line 58, in <genexpr>
    return (r for r in result or () if _filter(r))
  File "D:\CapstoneDesign\Damoa\Git_Crawler\DamoaCrawler\Crawler\spiders\Clien.py", line 59, in parse
    item['attribute'] = createItemUseBs4(item['link'], tagName, tagAttr, encoding="CP949",texttype="")
  File "D:\CapstoneDesign\Damoa\Git_Crawler\DamoaCrawler\Crawler\CreateItem.py", line 33, in createItemUseBs4
    origin = JoinPostUrl.find(name=name, attrs=attr).text.strip()
AttributeError: 'NoneType' object has no attribute 'text'
2017-10-12 09:23:39 [scrapy.core.scraper] ERROR: Error downloading <GET http://www.clien.net/service/board/pds?&od=T31&po=5>
Traceback (most recent call last):
  File "c:\users\xkdlr\appdata\local\programs\python\python36-32\lib\site-packages\twisted\internet\defer.py", line 1384, in _inlineCallbacks
    result = result.throwExceptionIntoGenerator(g)
  File "c:\users\xkdlr\appdata\local\programs\python\python36-32\lib\site-packages\twisted\python\failure.py", line 408, in throwExceptionIntoGenerator
    return g.throw(self.type, self.value, self.tb)
  File "c:\users\xkdlr\appdata\local\programs\python\python36-32\lib\site-packages\scrapy\core\downloader\middleware.py", line 43, in process_request
    defer.returnValue((yield download_func(request=request,spider=spider)))
  File "c:\users\xkdlr\appdata\local\programs\python\python36-32\lib\site-packages\twisted\internet\defer.py", line 653, in _runCallbacks
    current.result = callback(current.result, *args, **kw)
  File "c:\users\xkdlr\appdata\local\programs\python\python36-32\lib\site-packages\scrapy\core\downloader\handlers\http11.py", line 320, in _cb_timeout
    raise TimeoutError("Getting %s took longer than %s seconds." % (url, timeout))
twisted.internet.error.TimeoutError: User timeout caused connection failure: Getting http://www.clien.net/service/board/pds?&od=T31&po=5 took longer than 30.0 seconds..
2017-10-12 09:23:39 [scrapy.core.scraper] ERROR: Error downloading <GET http://www.clien.net/service/board/use?&od=T31&po=5>
Traceback (most recent call last):
  File "c:\users\xkdlr\appdata\local\programs\python\python36-32\lib\site-packages\twisted\internet\defer.py", line 1384, in _inlineCallbacks
    result = result.throwExceptionIntoGenerator(g)
  File "c:\users\xkdlr\appdata\local\programs\python\python36-32\lib\site-packages\twisted\python\failure.py", line 408, in throwExceptionIntoGenerator
    return g.throw(self.type, self.value, self.tb)
  File "c:\users\xkdlr\appdata\local\programs\python\python36-32\lib\site-packages\scrapy\core\downloader\middleware.py", line 43, in process_request
    defer.returnValue((yield download_func(request=request,spider=spider)))
  File "c:\users\xkdlr\appdata\local\programs\python\python36-32\lib\site-packages\twisted\internet\defer.py", line 653, in _runCallbacks
    current.result = callback(current.result, *args, **kw)
  File "c:\users\xkdlr\appdata\local\programs\python\python36-32\lib\site-packages\scrapy\core\downloader\handlers\http11.py", line 320, in _cb_timeout
    raise TimeoutError("Getting %s took longer than %s seconds." % (url, timeout))
twisted.internet.error.TimeoutError: User timeout caused connection failure: Getting http://www.clien.net/service/board/use?&od=T31&po=5 took longer than 30.0 seconds..
2017-10-12 09:23:39 [scrapy.core.scraper] ERROR: Error downloading <GET http://www.clien.net/service/board/lecture?&od=T31&po=5>
Traceback (most recent call last):
  File "c:\users\xkdlr\appdata\local\programs\python\python36-32\lib\site-packages\twisted\internet\defer.py", line 1384, in _inlineCallbacks
    result = result.throwExceptionIntoGenerator(g)
  File "c:\users\xkdlr\appdata\local\programs\python\python36-32\lib\site-packages\twisted\python\failure.py", line 408, in throwExceptionIntoGenerator
    return g.throw(self.type, self.value, self.tb)
  File "c:\users\xkdlr\appdata\local\programs\python\python36-32\lib\site-packages\scrapy\core\downloader\middleware.py", line 43, in process_request
    defer.returnValue((yield download_func(request=request,spider=spider)))
  File "c:\users\xkdlr\appdata\local\programs\python\python36-32\lib\site-packages\twisted\internet\defer.py", line 653, in _runCallbacks
    current.result = callback(current.result, *args, **kw)
  File "c:\users\xkdlr\appdata\local\programs\python\python36-32\lib\site-packages\scrapy\core\downloader\handlers\http11.py", line 320, in _cb_timeout
    raise TimeoutError("Getting %s took longer than %s seconds." % (url, timeout))
twisted.internet.error.TimeoutError: User timeout caused connection failure: Getting http://www.clien.net/service/board/lecture?&od=T31&po=5 took longer than 30.0 seconds..
2017-10-12 09:23:39 [scrapy.core.scraper] ERROR: Error downloading <GET http://www.clien.net/service/board/bug?&od=T31&po=5>
Traceback (most recent call last):
  File "c:\users\xkdlr\appdata\local\programs\python\python36-32\lib\site-packages\twisted\internet\defer.py", line 1384, in _inlineCallbacks
    result = result.throwExceptionIntoGenerator(g)
  File "c:\users\xkdlr\appdata\local\programs\python\python36-32\lib\site-packages\twisted\python\failure.py", line 408, in throwExceptionIntoGenerator
    return g.throw(self.type, self.value, self.tb)
  File "c:\users\xkdlr\appdata\local\programs\python\python36-32\lib\site-packages\scrapy\core\downloader\middleware.py", line 43, in process_request
    defer.returnValue((yield download_func(request=request,spider=spider)))
  File "c:\users\xkdlr\appdata\local\programs\python\python36-32\lib\site-packages\twisted\internet\defer.py", line 653, in _runCallbacks
    current.result = callback(current.result, *args, **kw)
  File "c:\users\xkdlr\appdata\local\programs\python\python36-32\lib\site-packages\scrapy\core\downloader\handlers\http11.py", line 320, in _cb_timeout
    raise TimeoutError("Getting %s took longer than %s seconds." % (url, timeout))
twisted.internet.error.TimeoutError: User timeout caused connection failure: Getting http://www.clien.net/service/board/bug?&od=T31&po=5 took longer than 30.0 seconds..
2017-10-12 09:24:31 [scrapy.core.scraper] ERROR: Error downloading <GET http://www.clien.net/service/board/chehum?&od=T31&po=5>: User timeout caused connection failure.
2017-10-12 09:24:31 [scrapy.core.scraper] ERROR: Error downloading <GET http://www.clien.net/service/board/news?&od=T31&po=5>
Traceback (most recent call last):
  File "c:\users\xkdlr\appdata\local\programs\python\python36-32\lib\site-packages\twisted\internet\defer.py", line 1384, in _inlineCallbacks
    result = result.throwExceptionIntoGenerator(g)
  File "c:\users\xkdlr\appdata\local\programs\python\python36-32\lib\site-packages\twisted\python\failure.py", line 408, in throwExceptionIntoGenerator
    return g.throw(self.type, self.value, self.tb)
  File "c:\users\xkdlr\appdata\local\programs\python\python36-32\lib\site-packages\scrapy\core\downloader\middleware.py", line 43, in process_request
    defer.returnValue((yield download_func(request=request,spider=spider)))
  File "c:\users\xkdlr\appdata\local\programs\python\python36-32\lib\site-packages\twisted\internet\defer.py", line 653, in _runCallbacks
    current.result = callback(current.result, *args, **kw)
  File "c:\users\xkdlr\appdata\local\programs\python\python36-32\lib\site-packages\scrapy\core\downloader\handlers\http11.py", line 320, in _cb_timeout
    raise TimeoutError("Getting %s took longer than %s seconds." % (url, timeout))
twisted.internet.error.TimeoutError: User timeout caused connection failure: Getting http://www.clien.net/service/board/news?&od=T31&po=5 took longer than 30.0 seconds..
2017-10-12 09:24:31 [scrapy.core.scraper] ERROR: Error downloading <GET http://www.clien.net/service/board/kin?&od=T31&po=6>
Traceback (most recent call last):
  File "c:\users\xkdlr\appdata\local\programs\python\python36-32\lib\site-packages\twisted\internet\defer.py", line 1384, in _inlineCallbacks
    result = result.throwExceptionIntoGenerator(g)
  File "c:\users\xkdlr\appdata\local\programs\python\python36-32\lib\site-packages\twisted\python\failure.py", line 408, in throwExceptionIntoGenerator
    return g.throw(self.type, self.value, self.tb)
  File "c:\users\xkdlr\appdata\local\programs\python\python36-32\lib\site-packages\scrapy\core\downloader\middleware.py", line 43, in process_request
    defer.returnValue((yield download_func(request=request,spider=spider)))
  File "c:\users\xkdlr\appdata\local\programs\python\python36-32\lib\site-packages\twisted\internet\defer.py", line 653, in _runCallbacks
    current.result = callback(current.result, *args, **kw)
  File "c:\users\xkdlr\appdata\local\programs\python\python36-32\lib\site-packages\scrapy\core\downloader\handlers\http11.py", line 320, in _cb_timeout
    raise TimeoutError("Getting %s took longer than %s seconds." % (url, timeout))
twisted.internet.error.TimeoutError: User timeout caused connection failure: Getting http://www.clien.net/service/board/kin?&od=T31&po=6 took longer than 30.0 seconds..
2017-10-12 09:24:31 [scrapy.core.scraper] ERROR: Error downloading <GET http://www.clien.net/service/board/park?&od=T31&po=6>: User timeout caused connection failure.
2017-10-12 09:24:40 [scrapy.core.scraper] ERROR: Error downloading <GET http://www.clien.net/service/board/useful?&od=T31&po=6>
Traceback (most recent call last):
  File "c:\users\xkdlr\appdata\local\programs\python\python36-32\lib\site-packages\twisted\internet\defer.py", line 1384, in _inlineCallbacks
    result = result.throwExceptionIntoGenerator(g)
  File "c:\users\xkdlr\appdata\local\programs\python\python36-32\lib\site-packages\twisted\python\failure.py", line 408, in throwExceptionIntoGenerator
    return g.throw(self.type, self.value, self.tb)
  File "c:\users\xkdlr\appdata\local\programs\python\python36-32\lib\site-packages\scrapy\core\downloader\middleware.py", line 43, in process_request
    defer.returnValue((yield download_func(request=request,spider=spider)))
  File "c:\users\xkdlr\appdata\local\programs\python\python36-32\lib\site-packages\twisted\internet\defer.py", line 653, in _runCallbacks
    current.result = callback(current.result, *args, **kw)
  File "c:\users\xkdlr\appdata\local\programs\python\python36-32\lib\site-packages\scrapy\core\downloader\handlers\http11.py", line 320, in _cb_timeout
    raise TimeoutError("Getting %s took longer than %s seconds." % (url, timeout))
twisted.internet.error.TimeoutError: User timeout caused connection failure: Getting http://www.clien.net/service/board/useful?&od=T31&po=6 took longer than 30.0 seconds..
2017-10-12 09:24:40 [scrapy.core.scraper] ERROR: Error downloading <GET https://www.clien.net/service/board/bug?&od=T31&po=1>
Traceback (most recent call last):
  File "c:\users\xkdlr\appdata\local\programs\python\python36-32\lib\site-packages\twisted\internet\defer.py", line 1384, in _inlineCallbacks
    result = result.throwExceptionIntoGenerator(g)
  File "c:\users\xkdlr\appdata\local\programs\python\python36-32\lib\site-packages\twisted\python\failure.py", line 408, in throwExceptionIntoGenerator
    return g.throw(self.type, self.value, self.tb)
  File "c:\users\xkdlr\appdata\local\programs\python\python36-32\lib\site-packages\scrapy\core\downloader\middleware.py", line 43, in process_request
    defer.returnValue((yield download_func(request=request,spider=spider)))
  File "c:\users\xkdlr\appdata\local\programs\python\python36-32\lib\site-packages\twisted\internet\defer.py", line 653, in _runCallbacks
    current.result = callback(current.result, *args, **kw)
  File "c:\users\xkdlr\appdata\local\programs\python\python36-32\lib\site-packages\scrapy\core\downloader\handlers\http11.py", line 320, in _cb_timeout
    raise TimeoutError("Getting %s took longer than %s seconds." % (url, timeout))
twisted.internet.error.TimeoutError: User timeout caused connection failure: Getting https://www.clien.net/service/board/bug?&od=T31&po=1 took longer than 30.0 seconds..
2017-10-12 09:24:40 [scrapy.core.scraper] ERROR: Error downloading <GET http://www.clien.net/service/board/news?&od=T31&po=6>
Traceback (most recent call last):
  File "c:\users\xkdlr\appdata\local\programs\python\python36-32\lib\site-packages\twisted\internet\defer.py", line 1384, in _inlineCallbacks
    result = result.throwExceptionIntoGenerator(g)
  File "c:\users\xkdlr\appdata\local\programs\python\python36-32\lib\site-packages\twisted\python\failure.py", line 408, in throwExceptionIntoGenerator
    return g.throw(self.type, self.value, self.tb)
  File "c:\users\xkdlr\appdata\local\programs\python\python36-32\lib\site-packages\scrapy\core\downloader\middleware.py", line 43, in process_request
    defer.returnValue((yield download_func(request=request,spider=spider)))
  File "c:\users\xkdlr\appdata\local\programs\python\python36-32\lib\site-packages\twisted\internet\defer.py", line 653, in _runCallbacks
    current.result = callback(current.result, *args, **kw)
  File "c:\users\xkdlr\appdata\local\programs\python\python36-32\lib\site-packages\scrapy\core\downloader\handlers\http11.py", line 320, in _cb_timeout
    raise TimeoutError("Getting %s took longer than %s seconds." % (url, timeout))
twisted.internet.error.TimeoutError: User timeout caused connection failure: Getting http://www.clien.net/service/board/news?&od=T31&po=6 took longer than 30.0 seconds..
2017-10-12 09:24:40 [scrapy.core.scraper] ERROR: Error downloading <GET http://www.clien.net/service/board/pds?&od=T31&po=6>: User timeout caused connection failure.
2017-10-12 09:25:26 [scrapy.core.scraper] ERROR: Error downloading <GET http://www.clien.net/service/board/use?&od=T31&po=6>
Traceback (most recent call last):
  File "c:\users\xkdlr\appdata\local\programs\python\python36-32\lib\site-packages\twisted\internet\defer.py", line 1384, in _inlineCallbacks
    result = result.throwExceptionIntoGenerator(g)
  File "c:\users\xkdlr\appdata\local\programs\python\python36-32\lib\site-packages\twisted\python\failure.py", line 408, in throwExceptionIntoGenerator
    return g.throw(self.type, self.value, self.tb)
  File "c:\users\xkdlr\appdata\local\programs\python\python36-32\lib\site-packages\scrapy\core\downloader\middleware.py", line 43, in process_request
    defer.returnValue((yield download_func(request=request,spider=spider)))
  File "c:\users\xkdlr\appdata\local\programs\python\python36-32\lib\site-packages\twisted\internet\defer.py", line 653, in _runCallbacks
    current.result = callback(current.result, *args, **kw)
  File "c:\users\xkdlr\appdata\local\programs\python\python36-32\lib\site-packages\scrapy\core\downloader\handlers\http11.py", line 320, in _cb_timeout
    raise TimeoutError("Getting %s took longer than %s seconds." % (url, timeout))
twisted.internet.error.TimeoutError: User timeout caused connection failure: Getting http://www.clien.net/service/board/use?&od=T31&po=6 took longer than 30.0 seconds..
2017-10-12 09:25:26 [scrapy.core.scraper] ERROR: Error downloading <GET http://www.clien.net/service/board/lecture?&od=T31&po=6>
Traceback (most recent call last):
  File "c:\users\xkdlr\appdata\local\programs\python\python36-32\lib\site-packages\twisted\internet\defer.py", line 1384, in _inlineCallbacks
    result = result.throwExceptionIntoGenerator(g)
  File "c:\users\xkdlr\appdata\local\programs\python\python36-32\lib\site-packages\twisted\python\failure.py", line 408, in throwExceptionIntoGenerator
    return g.throw(self.type, self.value, self.tb)
  File "c:\users\xkdlr\appdata\local\programs\python\python36-32\lib\site-packages\scrapy\core\downloader\middleware.py", line 43, in process_request
    defer.returnValue((yield download_func(request=request,spider=spider)))
  File "c:\users\xkdlr\appdata\local\programs\python\python36-32\lib\site-packages\twisted\internet\defer.py", line 653, in _runCallbacks
    current.result = callback(current.result, *args, **kw)
  File "c:\users\xkdlr\appdata\local\programs\python\python36-32\lib\site-packages\scrapy\core\downloader\handlers\http11.py", line 320, in _cb_timeout
    raise TimeoutError("Getting %s took longer than %s seconds." % (url, timeout))
twisted.internet.error.TimeoutError: User timeout caused connection failure: Getting http://www.clien.net/service/board/lecture?&od=T31&po=6 took longer than 30.0 seconds..
2017-10-12 09:25:26 [scrapy.core.scraper] ERROR: Error downloading <GET http://www.clien.net/service/board/news?&od=T31&po=7>
Traceback (most recent call last):
  File "c:\users\xkdlr\appdata\local\programs\python\python36-32\lib\site-packages\twisted\internet\defer.py", line 1384, in _inlineCallbacks
    result = result.throwExceptionIntoGenerator(g)
  File "c:\users\xkdlr\appdata\local\programs\python\python36-32\lib\site-packages\twisted\python\failure.py", line 408, in throwExceptionIntoGenerator
    return g.throw(self.type, self.value, self.tb)
  File "c:\users\xkdlr\appdata\local\programs\python\python36-32\lib\site-packages\scrapy\core\downloader\middleware.py", line 43, in process_request
    defer.returnValue((yield download_func(request=request,spider=spider)))
  File "c:\users\xkdlr\appdata\local\programs\python\python36-32\lib\site-packages\twisted\internet\defer.py", line 653, in _runCallbacks
    current.result = callback(current.result, *args, **kw)
  File "c:\users\xkdlr\appdata\local\programs\python\python36-32\lib\site-packages\scrapy\core\downloader\handlers\http11.py", line 320, in _cb_timeout
    raise TimeoutError("Getting %s took longer than %s seconds." % (url, timeout))
twisted.internet.error.TimeoutError: User timeout caused connection failure: Getting http://www.clien.net/service/board/news?&od=T31&po=7 took longer than 30.0 seconds..
2017-10-12 09:25:26 [scrapy.core.scraper] ERROR: Error downloading <GET http://www.clien.net/service/board/park?&od=T31&po=7>
Traceback (most recent call last):
  File "c:\users\xkdlr\appdata\local\programs\python\python36-32\lib\site-packages\twisted\internet\defer.py", line 1384, in _inlineCallbacks
    result = result.throwExceptionIntoGenerator(g)
  File "c:\users\xkdlr\appdata\local\programs\python\python36-32\lib\site-packages\twisted\python\failure.py", line 408, in throwExceptionIntoGenerator
    return g.throw(self.type, self.value, self.tb)
  File "c:\users\xkdlr\appdata\local\programs\python\python36-32\lib\site-packages\scrapy\core\downloader\middleware.py", line 43, in process_request
    defer.returnValue((yield download_func(request=request,spider=spider)))
  File "c:\users\xkdlr\appdata\local\programs\python\python36-32\lib\site-packages\twisted\internet\defer.py", line 653, in _runCallbacks
    current.result = callback(current.result, *args, **kw)
  File "c:\users\xkdlr\appdata\local\programs\python\python36-32\lib\site-packages\scrapy\core\downloader\handlers\http11.py", line 320, in _cb_timeout
    raise TimeoutError("Getting %s took longer than %s seconds." % (url, timeout))
twisted.internet.error.TimeoutError: User timeout caused connection failure: Getting http://www.clien.net/service/board/park?&od=T31&po=7 took longer than 30.0 seconds..
2017-10-12 09:25:38 [scrapy.core.scraper] ERROR: Error downloading <GET http://www.clien.net/service/board/bug?&od=T31&po=6>
Traceback (most recent call last):
  File "c:\users\xkdlr\appdata\local\programs\python\python36-32\lib\site-packages\twisted\internet\defer.py", line 1384, in _inlineCallbacks
    result = result.throwExceptionIntoGenerator(g)
  File "c:\users\xkdlr\appdata\local\programs\python\python36-32\lib\site-packages\twisted\python\failure.py", line 408, in throwExceptionIntoGenerator
    return g.throw(self.type, self.value, self.tb)
  File "c:\users\xkdlr\appdata\local\programs\python\python36-32\lib\site-packages\scrapy\core\downloader\middleware.py", line 43, in process_request
    defer.returnValue((yield download_func(request=request,spider=spider)))
  File "c:\users\xkdlr\appdata\local\programs\python\python36-32\lib\site-packages\twisted\internet\defer.py", line 653, in _runCallbacks
    current.result = callback(current.result, *args, **kw)
  File "c:\users\xkdlr\appdata\local\programs\python\python36-32\lib\site-packages\scrapy\core\downloader\handlers\http11.py", line 320, in _cb_timeout
    raise TimeoutError("Getting %s took longer than %s seconds." % (url, timeout))
twisted.internet.error.TimeoutError: User timeout caused connection failure: Getting http://www.clien.net/service/board/bug?&od=T31&po=6 took longer than 30.0 seconds..
2017-10-12 09:25:38 [scrapy.core.scraper] ERROR: Error downloading <GET http://www.clien.net/service/board/chehum?&od=T31&po=8>
Traceback (most recent call last):
  File "c:\users\xkdlr\appdata\local\programs\python\python36-32\lib\site-packages\twisted\internet\defer.py", line 1384, in _inlineCallbacks
    result = result.throwExceptionIntoGenerator(g)
  File "c:\users\xkdlr\appdata\local\programs\python\python36-32\lib\site-packages\twisted\python\failure.py", line 408, in throwExceptionIntoGenerator
    return g.throw(self.type, self.value, self.tb)
  File "c:\users\xkdlr\appdata\local\programs\python\python36-32\lib\site-packages\scrapy\core\downloader\middleware.py", line 43, in process_request
    defer.returnValue((yield download_func(request=request,spider=spider)))
  File "c:\users\xkdlr\appdata\local\programs\python\python36-32\lib\site-packages\twisted\internet\defer.py", line 653, in _runCallbacks
    current.result = callback(current.result, *args, **kw)
  File "c:\users\xkdlr\appdata\local\programs\python\python36-32\lib\site-packages\scrapy\core\downloader\handlers\http11.py", line 320, in _cb_timeout
    raise TimeoutError("Getting %s took longer than %s seconds." % (url, timeout))
twisted.internet.error.TimeoutError: User timeout caused connection failure: Getting http://www.clien.net/service/board/chehum?&od=T31&po=8 took longer than 30.0 seconds..
2017-10-12 09:25:38 [scrapy.core.scraper] ERROR: Error downloading <GET http://www.clien.net/service/board/useful?&od=T31&po=7>
Traceback (most recent call last):
  File "c:\users\xkdlr\appdata\local\programs\python\python36-32\lib\site-packages\twisted\internet\defer.py", line 1384, in _inlineCallbacks
    result = result.throwExceptionIntoGenerator(g)
  File "c:\users\xkdlr\appdata\local\programs\python\python36-32\lib\site-packages\twisted\python\failure.py", line 408, in throwExceptionIntoGenerator
    return g.throw(self.type, self.value, self.tb)
  File "c:\users\xkdlr\appdata\local\programs\python\python36-32\lib\site-packages\scrapy\core\downloader\middleware.py", line 43, in process_request
    defer.returnValue((yield download_func(request=request,spider=spider)))
  File "c:\users\xkdlr\appdata\local\programs\python\python36-32\lib\site-packages\twisted\internet\defer.py", line 653, in _runCallbacks
    current.result = callback(current.result, *args, **kw)
  File "c:\users\xkdlr\appdata\local\programs\python\python36-32\lib\site-packages\scrapy\core\downloader\handlers\http11.py", line 320, in _cb_timeout
    raise TimeoutError("Getting %s took longer than %s seconds." % (url, timeout))
twisted.internet.error.TimeoutError: User timeout caused connection failure: Getting http://www.clien.net/service/board/useful?&od=T31&po=7 took longer than 30.0 seconds..
2017-10-12 09:25:38 [scrapy.core.scraper] ERROR: Error downloading <GET http://www.clien.net/service/board/kin?&od=T31&po=7>
Traceback (most recent call last):
  File "c:\users\xkdlr\appdata\local\programs\python\python36-32\lib\site-packages\twisted\internet\defer.py", line 1384, in _inlineCallbacks
    result = result.throwExceptionIntoGenerator(g)
  File "c:\users\xkdlr\appdata\local\programs\python\python36-32\lib\site-packages\twisted\python\failure.py", line 408, in throwExceptionIntoGenerator
    return g.throw(self.type, self.value, self.tb)
  File "c:\users\xkdlr\appdata\local\programs\python\python36-32\lib\site-packages\scrapy\core\downloader\middleware.py", line 43, in process_request
    defer.returnValue((yield download_func(request=request,spider=spider)))
  File "c:\users\xkdlr\appdata\local\programs\python\python36-32\lib\site-packages\twisted\internet\defer.py", line 653, in _runCallbacks
    current.result = callback(current.result, *args, **kw)
  File "c:\users\xkdlr\appdata\local\programs\python\python36-32\lib\site-packages\scrapy\core\downloader\handlers\http11.py", line 320, in _cb_timeout
    raise TimeoutError("Getting %s took longer than %s seconds." % (url, timeout))
twisted.internet.error.TimeoutError: User timeout caused connection failure: Getting http://www.clien.net/service/board/kin?&od=T31&po=7 took longer than 30.0 seconds..
2017-10-12 09:26:35 [scrapy.core.scraper] ERROR: Error downloading <GET http://www.clien.net/service/board/chehum?&od=T31&po=6>
Traceback (most recent call last):
  File "c:\users\xkdlr\appdata\local\programs\python\python36-32\lib\site-packages\twisted\internet\defer.py", line 1384, in _inlineCallbacks
    result = result.throwExceptionIntoGenerator(g)
  File "c:\users\xkdlr\appdata\local\programs\python\python36-32\lib\site-packages\twisted\python\failure.py", line 408, in throwExceptionIntoGenerator
    return g.throw(self.type, self.value, self.tb)
  File "c:\users\xkdlr\appdata\local\programs\python\python36-32\lib\site-packages\scrapy\core\downloader\middleware.py", line 43, in process_request
    defer.returnValue((yield download_func(request=request,spider=spider)))
  File "c:\users\xkdlr\appdata\local\programs\python\python36-32\lib\site-packages\twisted\internet\defer.py", line 653, in _runCallbacks
    current.result = callback(current.result, *args, **kw)
  File "c:\users\xkdlr\appdata\local\programs\python\python36-32\lib\site-packages\scrapy\core\downloader\handlers\http11.py", line 320, in _cb_timeout
    raise TimeoutError("Getting %s took longer than %s seconds." % (url, timeout))
twisted.internet.error.TimeoutError: User timeout caused connection failure: Getting http://www.clien.net/service/board/chehum?&od=T31&po=6 took longer than 30.0 seconds..
2017-10-12 09:26:35 [scrapy.core.scraper] ERROR: Error downloading <GET http://www.clien.net/service/board/lecture?&od=T31&po=7>
Traceback (most recent call last):
  File "c:\users\xkdlr\appdata\local\programs\python\python36-32\lib\site-packages\twisted\internet\defer.py", line 1384, in _inlineCallbacks
    result = result.throwExceptionIntoGenerator(g)
  File "c:\users\xkdlr\appdata\local\programs\python\python36-32\lib\site-packages\twisted\python\failure.py", line 408, in throwExceptionIntoGenerator
    return g.throw(self.type, self.value, self.tb)
  File "c:\users\xkdlr\appdata\local\programs\python\python36-32\lib\site-packages\scrapy\core\downloader\middleware.py", line 43, in process_request
    defer.returnValue((yield download_func(request=request,spider=spider)))
  File "c:\users\xkdlr\appdata\local\programs\python\python36-32\lib\site-packages\twisted\internet\defer.py", line 653, in _runCallbacks
    current.result = callback(current.result, *args, **kw)
  File "c:\users\xkdlr\appdata\local\programs\python\python36-32\lib\site-packages\scrapy\core\downloader\handlers\http11.py", line 320, in _cb_timeout
    raise TimeoutError("Getting %s took longer than %s seconds." % (url, timeout))
twisted.internet.error.TimeoutError: User timeout caused connection failure: Getting http://www.clien.net/service/board/lecture?&od=T31&po=7 took longer than 30.0 seconds..
2017-10-12 09:26:35 [scrapy.core.scraper] ERROR: Error downloading <GET http://www.clien.net/service/board/pds?&od=T31&po=7>
Traceback (most recent call last):
  File "c:\users\xkdlr\appdata\local\programs\python\python36-32\lib\site-packages\twisted\internet\defer.py", line 1384, in _inlineCallbacks
    result = result.throwExceptionIntoGenerator(g)
  File "c:\users\xkdlr\appdata\local\programs\python\python36-32\lib\site-packages\twisted\python\failure.py", line 408, in throwExceptionIntoGenerator
    return g.throw(self.type, self.value, self.tb)
  File "c:\users\xkdlr\appdata\local\programs\python\python36-32\lib\site-packages\scrapy\core\downloader\middleware.py", line 43, in process_request
    defer.returnValue((yield download_func(request=request,spider=spider)))
  File "c:\users\xkdlr\appdata\local\programs\python\python36-32\lib\site-packages\twisted\internet\defer.py", line 653, in _runCallbacks
    current.result = callback(current.result, *args, **kw)
  File "c:\users\xkdlr\appdata\local\programs\python\python36-32\lib\site-packages\scrapy\core\downloader\handlers\http11.py", line 320, in _cb_timeout
    raise TimeoutError("Getting %s took longer than %s seconds." % (url, timeout))
twisted.internet.error.TimeoutError: User timeout caused connection failure: Getting http://www.clien.net/service/board/pds?&od=T31&po=7 took longer than 30.0 seconds..
2017-10-12 09:26:35 [scrapy.core.scraper] ERROR: Error downloading <GET http://www.clien.net/service/board/chehum?&od=T31&po=7>
Traceback (most recent call last):
  File "c:\users\xkdlr\appdata\local\programs\python\python36-32\lib\site-packages\twisted\internet\defer.py", line 1384, in _inlineCallbacks
    result = result.throwExceptionIntoGenerator(g)
  File "c:\users\xkdlr\appdata\local\programs\python\python36-32\lib\site-packages\twisted\python\failure.py", line 408, in throwExceptionIntoGenerator
    return g.throw(self.type, self.value, self.tb)
  File "c:\users\xkdlr\appdata\local\programs\python\python36-32\lib\site-packages\scrapy\core\downloader\middleware.py", line 43, in process_request
    defer.returnValue((yield download_func(request=request,spider=spider)))
  File "c:\users\xkdlr\appdata\local\programs\python\python36-32\lib\site-packages\twisted\internet\defer.py", line 653, in _runCallbacks
    current.result = callback(current.result, *args, **kw)
  File "c:\users\xkdlr\appdata\local\programs\python\python36-32\lib\site-packages\scrapy\core\downloader\handlers\http11.py", line 320, in _cb_timeout
    raise TimeoutError("Getting %s took longer than %s seconds." % (url, timeout))
twisted.internet.error.TimeoutError: User timeout caused connection failure: Getting http://www.clien.net/service/board/chehum?&od=T31&po=7 took longer than 30.0 seconds..
2017-10-12 09:26:46 [scrapy.core.scraper] ERROR: Error downloading <GET http://www.clien.net/service/board/use?&od=T31&po=7>
Traceback (most recent call last):
  File "c:\users\xkdlr\appdata\local\programs\python\python36-32\lib\site-packages\twisted\internet\defer.py", line 1384, in _inlineCallbacks
    result = result.throwExceptionIntoGenerator(g)
  File "c:\users\xkdlr\appdata\local\programs\python\python36-32\lib\site-packages\twisted\python\failure.py", line 408, in throwExceptionIntoGenerator
    return g.throw(self.type, self.value, self.tb)
  File "c:\users\xkdlr\appdata\local\programs\python\python36-32\lib\site-packages\scrapy\core\downloader\middleware.py", line 43, in process_request
    defer.returnValue((yield download_func(request=request,spider=spider)))
  File "c:\users\xkdlr\appdata\local\programs\python\python36-32\lib\site-packages\twisted\internet\defer.py", line 653, in _runCallbacks
    current.result = callback(current.result, *args, **kw)
  File "c:\users\xkdlr\appdata\local\programs\python\python36-32\lib\site-packages\scrapy\core\downloader\handlers\http11.py", line 320, in _cb_timeout
    raise TimeoutError("Getting %s took longer than %s seconds." % (url, timeout))
twisted.internet.error.TimeoutError: User timeout caused connection failure: Getting http://www.clien.net/service/board/use?&od=T31&po=7 took longer than 30.0 seconds..
2017-10-12 09:26:46 [scrapy.core.scraper] ERROR: Error downloading <GET https://www.clien.net/service/board/use?&od=T31&po=1>
Traceback (most recent call last):
  File "c:\users\xkdlr\appdata\local\programs\python\python36-32\lib\site-packages\twisted\internet\defer.py", line 1384, in _inlineCallbacks
    result = result.throwExceptionIntoGenerator(g)
  File "c:\users\xkdlr\appdata\local\programs\python\python36-32\lib\site-packages\twisted\python\failure.py", line 408, in throwExceptionIntoGenerator
    return g.throw(self.type, self.value, self.tb)
  File "c:\users\xkdlr\appdata\local\programs\python\python36-32\lib\site-packages\scrapy\core\downloader\middleware.py", line 43, in process_request
    defer.returnValue((yield download_func(request=request,spider=spider)))
  File "c:\users\xkdlr\appdata\local\programs\python\python36-32\lib\site-packages\twisted\internet\defer.py", line 653, in _runCallbacks
    current.result = callback(current.result, *args, **kw)
  File "c:\users\xkdlr\appdata\local\programs\python\python36-32\lib\site-packages\scrapy\core\downloader\handlers\http11.py", line 320, in _cb_timeout
    raise TimeoutError("Getting %s took longer than %s seconds." % (url, timeout))
twisted.internet.error.TimeoutError: User timeout caused connection failure: Getting https://www.clien.net/service/board/use?&od=T31&po=1 took longer than 30.0 seconds..
2017-10-12 09:26:46 [scrapy.core.scraper] ERROR: Error downloading <GET http://www.clien.net/service/board/bug?&od=T31&po=7>
Traceback (most recent call last):
  File "c:\users\xkdlr\appdata\local\programs\python\python36-32\lib\site-packages\twisted\internet\defer.py", line 1384, in _inlineCallbacks
    result = result.throwExceptionIntoGenerator(g)
  File "c:\users\xkdlr\appdata\local\programs\python\python36-32\lib\site-packages\twisted\python\failure.py", line 408, in throwExceptionIntoGenerator
    return g.throw(self.type, self.value, self.tb)
  File "c:\users\xkdlr\appdata\local\programs\python\python36-32\lib\site-packages\scrapy\core\downloader\middleware.py", line 43, in process_request
    defer.returnValue((yield download_func(request=request,spider=spider)))
  File "c:\users\xkdlr\appdata\local\programs\python\python36-32\lib\site-packages\twisted\internet\defer.py", line 653, in _runCallbacks
    current.result = callback(current.result, *args, **kw)
  File "c:\users\xkdlr\appdata\local\programs\python\python36-32\lib\site-packages\scrapy\core\downloader\handlers\http11.py", line 320, in _cb_timeout
    raise TimeoutError("Getting %s took longer than %s seconds." % (url, timeout))
twisted.internet.error.TimeoutError: User timeout caused connection failure: Getting http://www.clien.net/service/board/bug?&od=T31&po=7 took longer than 30.0 seconds..
2017-10-12 09:26:46 [scrapy.core.scraper] ERROR: Error downloading <GET http://www.clien.net/service/board/park?&od=T31&po=8>
Traceback (most recent call last):
  File "c:\users\xkdlr\appdata\local\programs\python\python36-32\lib\site-packages\twisted\internet\defer.py", line 1384, in _inlineCallbacks
    result = result.throwExceptionIntoGenerator(g)
  File "c:\users\xkdlr\appdata\local\programs\python\python36-32\lib\site-packages\twisted\python\failure.py", line 408, in throwExceptionIntoGenerator
    return g.throw(self.type, self.value, self.tb)
  File "c:\users\xkdlr\appdata\local\programs\python\python36-32\lib\site-packages\scrapy\core\downloader\middleware.py", line 43, in process_request
    defer.returnValue((yield download_func(request=request,spider=spider)))
  File "c:\users\xkdlr\appdata\local\programs\python\python36-32\lib\site-packages\twisted\internet\defer.py", line 653, in _runCallbacks
    current.result = callback(current.result, *args, **kw)
  File "c:\users\xkdlr\appdata\local\programs\python\python36-32\lib\site-packages\scrapy\core\downloader\handlers\http11.py", line 320, in _cb_timeout
    raise TimeoutError("Getting %s took longer than %s seconds." % (url, timeout))
twisted.internet.error.TimeoutError: User timeout caused connection failure: Getting http://www.clien.net/service/board/park?&od=T31&po=8 took longer than 30.0 seconds..
2017-10-12 09:27:42 [scrapy.core.scraper] ERROR: Error downloading <GET http://www.clien.net/service/board/kin?&od=T31&po=8>: User timeout caused connection failure.
2017-10-12 09:27:42 [scrapy.core.scraper] ERROR: Error downloading <GET http://www.clien.net/service/board/use?&od=T31&po=8>: User timeout caused connection failure.
2017-10-12 09:27:42 [scrapy.core.scraper] ERROR: Error downloading <GET http://www.clien.net/service/board/useful?&od=T31&po=8>: User timeout caused connection failure.
2017-10-12 09:27:42 [scrapy.core.scraper] ERROR: Error downloading <GET http://www.clien.net/service/board/pds?&od=T31&po=8>
Traceback (most recent call last):
  File "c:\users\xkdlr\appdata\local\programs\python\python36-32\lib\site-packages\twisted\internet\defer.py", line 1384, in _inlineCallbacks
    result = result.throwExceptionIntoGenerator(g)
  File "c:\users\xkdlr\appdata\local\programs\python\python36-32\lib\site-packages\twisted\python\failure.py", line 408, in throwExceptionIntoGenerator
    return g.throw(self.type, self.value, self.tb)
  File "c:\users\xkdlr\appdata\local\programs\python\python36-32\lib\site-packages\scrapy\core\downloader\middleware.py", line 43, in process_request
    defer.returnValue((yield download_func(request=request,spider=spider)))
  File "c:\users\xkdlr\appdata\local\programs\python\python36-32\lib\site-packages\twisted\internet\defer.py", line 653, in _runCallbacks
    current.result = callback(current.result, *args, **kw)
  File "c:\users\xkdlr\appdata\local\programs\python\python36-32\lib\site-packages\scrapy\core\downloader\handlers\http11.py", line 320, in _cb_timeout
    raise TimeoutError("Getting %s took longer than %s seconds." % (url, timeout))
twisted.internet.error.TimeoutError: User timeout caused connection failure: Getting http://www.clien.net/service/board/pds?&od=T31&po=8 took longer than 30.0 seconds..
2017-10-12 09:27:51 [scrapy.core.scraper] ERROR: Error downloading <GET http://www.clien.net/service/board/news?&od=T31&po=8>
Traceback (most recent call last):
  File "c:\users\xkdlr\appdata\local\programs\python\python36-32\lib\site-packages\twisted\internet\defer.py", line 1384, in _inlineCallbacks
    result = result.throwExceptionIntoGenerator(g)
  File "c:\users\xkdlr\appdata\local\programs\python\python36-32\lib\site-packages\twisted\python\failure.py", line 408, in throwExceptionIntoGenerator
    return g.throw(self.type, self.value, self.tb)
  File "c:\users\xkdlr\appdata\local\programs\python\python36-32\lib\site-packages\scrapy\core\downloader\middleware.py", line 43, in process_request
    defer.returnValue((yield download_func(request=request,spider=spider)))
  File "c:\users\xkdlr\appdata\local\programs\python\python36-32\lib\site-packages\twisted\internet\defer.py", line 653, in _runCallbacks
    current.result = callback(current.result, *args, **kw)
  File "c:\users\xkdlr\appdata\local\programs\python\python36-32\lib\site-packages\scrapy\core\downloader\handlers\http11.py", line 320, in _cb_timeout
    raise TimeoutError("Getting %s took longer than %s seconds." % (url, timeout))
twisted.internet.error.TimeoutError: User timeout caused connection failure: Getting http://www.clien.net/service/board/news?&od=T31&po=8 took longer than 30.0 seconds..
2017-10-12 09:27:51 [scrapy.core.scraper] ERROR: Error downloading <GET https://www.clien.net/service/board/news?&od=T31&po=2>
Traceback (most recent call last):
  File "c:\users\xkdlr\appdata\local\programs\python\python36-32\lib\site-packages\twisted\internet\defer.py", line 1384, in _inlineCallbacks
    result = result.throwExceptionIntoGenerator(g)
  File "c:\users\xkdlr\appdata\local\programs\python\python36-32\lib\site-packages\twisted\python\failure.py", line 408, in throwExceptionIntoGenerator
    return g.throw(self.type, self.value, self.tb)
  File "c:\users\xkdlr\appdata\local\programs\python\python36-32\lib\site-packages\scrapy\core\downloader\middleware.py", line 43, in process_request
    defer.returnValue((yield download_func(request=request,spider=spider)))
  File "c:\users\xkdlr\appdata\local\programs\python\python36-32\lib\site-packages\twisted\internet\defer.py", line 653, in _runCallbacks
    current.result = callback(current.result, *args, **kw)
  File "c:\users\xkdlr\appdata\local\programs\python\python36-32\lib\site-packages\scrapy\core\downloader\handlers\http11.py", line 320, in _cb_timeout
    raise TimeoutError("Getting %s took longer than %s seconds." % (url, timeout))
twisted.internet.error.TimeoutError: User timeout caused connection failure: Getting https://www.clien.net/service/board/news?&od=T31&po=2 took longer than 30.0 seconds..
2017-10-12 09:27:51 [scrapy.core.scraper] ERROR: Error downloading <GET https://www.clien.net/service/board/park?&od=T31&po=2>
Traceback (most recent call last):
  File "c:\users\xkdlr\appdata\local\programs\python\python36-32\lib\site-packages\twisted\internet\defer.py", line 1384, in _inlineCallbacks
    result = result.throwExceptionIntoGenerator(g)
  File "c:\users\xkdlr\appdata\local\programs\python\python36-32\lib\site-packages\twisted\python\failure.py", line 408, in throwExceptionIntoGenerator
    return g.throw(self.type, self.value, self.tb)
  File "c:\users\xkdlr\appdata\local\programs\python\python36-32\lib\site-packages\scrapy\core\downloader\middleware.py", line 43, in process_request
    defer.returnValue((yield download_func(request=request,spider=spider)))
  File "c:\users\xkdlr\appdata\local\programs\python\python36-32\lib\site-packages\twisted\internet\defer.py", line 653, in _runCallbacks
    current.result = callback(current.result, *args, **kw)
  File "c:\users\xkdlr\appdata\local\programs\python\python36-32\lib\site-packages\scrapy\core\downloader\handlers\http11.py", line 320, in _cb_timeout
    raise TimeoutError("Getting %s took longer than %s seconds." % (url, timeout))
twisted.internet.error.TimeoutError: User timeout caused connection failure: Getting https://www.clien.net/service/board/park?&od=T31&po=2 took longer than 30.0 seconds..
2017-10-12 09:27:51 [scrapy.core.scraper] ERROR: Error downloading <GET https://www.clien.net/service/board/chehum?&od=T31&po=1>
Traceback (most recent call last):
  File "c:\users\xkdlr\appdata\local\programs\python\python36-32\lib\site-packages\twisted\internet\defer.py", line 1384, in _inlineCallbacks
    result = result.throwExceptionIntoGenerator(g)
  File "c:\users\xkdlr\appdata\local\programs\python\python36-32\lib\site-packages\twisted\python\failure.py", line 408, in throwExceptionIntoGenerator
    return g.throw(self.type, self.value, self.tb)
  File "c:\users\xkdlr\appdata\local\programs\python\python36-32\lib\site-packages\scrapy\core\downloader\middleware.py", line 43, in process_request
    defer.returnValue((yield download_func(request=request,spider=spider)))
  File "c:\users\xkdlr\appdata\local\programs\python\python36-32\lib\site-packages\twisted\internet\defer.py", line 653, in _runCallbacks
    current.result = callback(current.result, *args, **kw)
  File "c:\users\xkdlr\appdata\local\programs\python\python36-32\lib\site-packages\scrapy\core\downloader\handlers\http11.py", line 320, in _cb_timeout
    raise TimeoutError("Getting %s took longer than %s seconds." % (url, timeout))
twisted.internet.error.TimeoutError: User timeout caused connection failure: Getting https://www.clien.net/service/board/chehum?&od=T31&po=1 took longer than 30.0 seconds..
2017-10-12 09:28:52 [scrapy.core.scraper] ERROR: Error downloading <GET https://www.clien.net/service/board/lecture?&od=T31&po=2>
Traceback (most recent call last):
  File "c:\users\xkdlr\appdata\local\programs\python\python36-32\lib\site-packages\twisted\internet\defer.py", line 1384, in _inlineCallbacks
    result = result.throwExceptionIntoGenerator(g)
  File "c:\users\xkdlr\appdata\local\programs\python\python36-32\lib\site-packages\twisted\python\failure.py", line 408, in throwExceptionIntoGenerator
    return g.throw(self.type, self.value, self.tb)
  File "c:\users\xkdlr\appdata\local\programs\python\python36-32\lib\site-packages\scrapy\core\downloader\middleware.py", line 43, in process_request
    defer.returnValue((yield download_func(request=request,spider=spider)))
  File "c:\users\xkdlr\appdata\local\programs\python\python36-32\lib\site-packages\twisted\internet\defer.py", line 653, in _runCallbacks
    current.result = callback(current.result, *args, **kw)
  File "c:\users\xkdlr\appdata\local\programs\python\python36-32\lib\site-packages\scrapy\core\downloader\handlers\http11.py", line 320, in _cb_timeout
    raise TimeoutError("Getting %s took longer than %s seconds." % (url, timeout))
twisted.internet.error.TimeoutError: User timeout caused connection failure: Getting https://www.clien.net/service/board/lecture?&od=T31&po=2 took longer than 30.0 seconds..
2017-10-12 09:28:52 [scrapy.core.scraper] ERROR: Error downloading <GET https://www.clien.net/service/board/kin?&od=T31&po=2>
Traceback (most recent call last):
  File "c:\users\xkdlr\appdata\local\programs\python\python36-32\lib\site-packages\twisted\internet\defer.py", line 1384, in _inlineCallbacks
    result = result.throwExceptionIntoGenerator(g)
  File "c:\users\xkdlr\appdata\local\programs\python\python36-32\lib\site-packages\twisted\python\failure.py", line 408, in throwExceptionIntoGenerator
    return g.throw(self.type, self.value, self.tb)
  File "c:\users\xkdlr\appdata\local\programs\python\python36-32\lib\site-packages\scrapy\core\downloader\middleware.py", line 43, in process_request
    defer.returnValue((yield download_func(request=request,spider=spider)))
  File "c:\users\xkdlr\appdata\local\programs\python\python36-32\lib\site-packages\twisted\internet\defer.py", line 653, in _runCallbacks
    current.result = callback(current.result, *args, **kw)
  File "c:\users\xkdlr\appdata\local\programs\python\python36-32\lib\site-packages\scrapy\core\downloader\handlers\http11.py", line 320, in _cb_timeout
    raise TimeoutError("Getting %s took longer than %s seconds." % (url, timeout))
twisted.internet.error.TimeoutError: User timeout caused connection failure: Getting https://www.clien.net/service/board/kin?&od=T31&po=2 took longer than 30.0 seconds..
2017-10-12 09:28:52 [scrapy.core.scraper] ERROR: Error downloading <GET https://www.clien.net/service/board/bug?&od=T31&po=2>
Traceback (most recent call last):
  File "c:\users\xkdlr\appdata\local\programs\python\python36-32\lib\site-packages\twisted\internet\defer.py", line 1384, in _inlineCallbacks
    result = result.throwExceptionIntoGenerator(g)
  File "c:\users\xkdlr\appdata\local\programs\python\python36-32\lib\site-packages\twisted\python\failure.py", line 408, in throwExceptionIntoGenerator
    return g.throw(self.type, self.value, self.tb)
  File "c:\users\xkdlr\appdata\local\programs\python\python36-32\lib\site-packages\scrapy\core\downloader\middleware.py", line 43, in process_request
    defer.returnValue((yield download_func(request=request,spider=spider)))
  File "c:\users\xkdlr\appdata\local\programs\python\python36-32\lib\site-packages\twisted\internet\defer.py", line 653, in _runCallbacks
    current.result = callback(current.result, *args, **kw)
  File "c:\users\xkdlr\appdata\local\programs\python\python36-32\lib\site-packages\scrapy\core\downloader\handlers\http11.py", line 320, in _cb_timeout
    raise TimeoutError("Getting %s took longer than %s seconds." % (url, timeout))
twisted.internet.error.TimeoutError: User timeout caused connection failure: Getting https://www.clien.net/service/board/bug?&od=T31&po=2 took longer than 30.0 seconds..
2017-10-12 09:28:52 [scrapy.core.scraper] ERROR: Error downloading <GET http://www.clien.net/service/board/bug?&od=T31&po=8>
Traceback (most recent call last):
  File "c:\users\xkdlr\appdata\local\programs\python\python36-32\lib\site-packages\twisted\internet\defer.py", line 1384, in _inlineCallbacks
    result = result.throwExceptionIntoGenerator(g)
  File "c:\users\xkdlr\appdata\local\programs\python\python36-32\lib\site-packages\twisted\python\failure.py", line 408, in throwExceptionIntoGenerator
    return g.throw(self.type, self.value, self.tb)
  File "c:\users\xkdlr\appdata\local\programs\python\python36-32\lib\site-packages\scrapy\core\downloader\middleware.py", line 43, in process_request
    defer.returnValue((yield download_func(request=request,spider=spider)))
  File "c:\users\xkdlr\appdata\local\programs\python\python36-32\lib\site-packages\twisted\internet\defer.py", line 653, in _runCallbacks
    current.result = callback(current.result, *args, **kw)
  File "c:\users\xkdlr\appdata\local\programs\python\python36-32\lib\site-packages\scrapy\core\downloader\handlers\http11.py", line 320, in _cb_timeout
    raise TimeoutError("Getting %s took longer than %s seconds." % (url, timeout))
twisted.internet.error.TimeoutError: User timeout caused connection failure: Getting http://www.clien.net/service/board/bug?&od=T31&po=8 took longer than 30.0 seconds..
2017-10-12 09:29:05 [scrapy.core.scraper] ERROR: Error downloading <GET http://www.clien.net/service/board/lecture?&od=T31&po=8>
Traceback (most recent call last):
  File "c:\users\xkdlr\appdata\local\programs\python\python36-32\lib\site-packages\twisted\internet\defer.py", line 1384, in _inlineCallbacks
    result = result.throwExceptionIntoGenerator(g)
  File "c:\users\xkdlr\appdata\local\programs\python\python36-32\lib\site-packages\twisted\python\failure.py", line 408, in throwExceptionIntoGenerator
    return g.throw(self.type, self.value, self.tb)
  File "c:\users\xkdlr\appdata\local\programs\python\python36-32\lib\site-packages\scrapy\core\downloader\middleware.py", line 43, in process_request
    defer.returnValue((yield download_func(request=request,spider=spider)))
  File "c:\users\xkdlr\appdata\local\programs\python\python36-32\lib\site-packages\twisted\internet\defer.py", line 653, in _runCallbacks
    current.result = callback(current.result, *args, **kw)
  File "c:\users\xkdlr\appdata\local\programs\python\python36-32\lib\site-packages\scrapy\core\downloader\handlers\http11.py", line 320, in _cb_timeout
    raise TimeoutError("Getting %s took longer than %s seconds." % (url, timeout))
twisted.internet.error.TimeoutError: User timeout caused connection failure: Getting http://www.clien.net/service/board/lecture?&od=T31&po=8 took longer than 30.0 seconds..
2017-10-12 09:29:05 [scrapy.core.scraper] ERROR: Error downloading <GET https://www.clien.net/service/board/park?&od=T31&po=5>
Traceback (most recent call last):
  File "c:\users\xkdlr\appdata\local\programs\python\python36-32\lib\site-packages\twisted\internet\defer.py", line 1384, in _inlineCallbacks
    result = result.throwExceptionIntoGenerator(g)
  File "c:\users\xkdlr\appdata\local\programs\python\python36-32\lib\site-packages\twisted\python\failure.py", line 408, in throwExceptionIntoGenerator
    return g.throw(self.type, self.value, self.tb)
  File "c:\users\xkdlr\appdata\local\programs\python\python36-32\lib\site-packages\scrapy\core\downloader\middleware.py", line 43, in process_request
    defer.returnValue((yield download_func(request=request,spider=spider)))
  File "c:\users\xkdlr\appdata\local\programs\python\python36-32\lib\site-packages\twisted\internet\defer.py", line 653, in _runCallbacks
    current.result = callback(current.result, *args, **kw)
  File "c:\users\xkdlr\appdata\local\programs\python\python36-32\lib\site-packages\scrapy\core\downloader\handlers\http11.py", line 320, in _cb_timeout
    raise TimeoutError("Getting %s took longer than %s seconds." % (url, timeout))
twisted.internet.error.TimeoutError: User timeout caused connection failure: Getting https://www.clien.net/service/board/park?&od=T31&po=5 took longer than 30.0 seconds..
2017-10-12 09:29:05 [scrapy.core.scraper] ERROR: Error downloading <GET https://www.clien.net/service/board/useful?&od=T31&po=2>
Traceback (most recent call last):
  File "c:\users\xkdlr\appdata\local\programs\python\python36-32\lib\site-packages\twisted\internet\defer.py", line 1384, in _inlineCallbacks
    result = result.throwExceptionIntoGenerator(g)
  File "c:\users\xkdlr\appdata\local\programs\python\python36-32\lib\site-packages\twisted\python\failure.py", line 408, in throwExceptionIntoGenerator
    return g.throw(self.type, self.value, self.tb)
  File "c:\users\xkdlr\appdata\local\programs\python\python36-32\lib\site-packages\scrapy\core\downloader\middleware.py", line 43, in process_request
    defer.returnValue((yield download_func(request=request,spider=spider)))
  File "c:\users\xkdlr\appdata\local\programs\python\python36-32\lib\site-packages\twisted\internet\defer.py", line 653, in _runCallbacks
    current.result = callback(current.result, *args, **kw)
  File "c:\users\xkdlr\appdata\local\programs\python\python36-32\lib\site-packages\scrapy\core\downloader\handlers\http11.py", line 320, in _cb_timeout
    raise TimeoutError("Getting %s took longer than %s seconds." % (url, timeout))
twisted.internet.error.TimeoutError: User timeout caused connection failure: Getting https://www.clien.net/service/board/useful?&od=T31&po=2 took longer than 30.0 seconds..
2017-10-12 09:29:05 [scrapy.core.scraper] ERROR: Error downloading <GET https://www.clien.net/service/board/kin?&od=T31&po=3>
Traceback (most recent call last):
  File "c:\users\xkdlr\appdata\local\programs\python\python36-32\lib\site-packages\twisted\internet\defer.py", line 1384, in _inlineCallbacks
    result = result.throwExceptionIntoGenerator(g)
  File "c:\users\xkdlr\appdata\local\programs\python\python36-32\lib\site-packages\twisted\python\failure.py", line 408, in throwExceptionIntoGenerator
    return g.throw(self.type, self.value, self.tb)
  File "c:\users\xkdlr\appdata\local\programs\python\python36-32\lib\site-packages\scrapy\core\downloader\middleware.py", line 43, in process_request
    defer.returnValue((yield download_func(request=request,spider=spider)))
  File "c:\users\xkdlr\appdata\local\programs\python\python36-32\lib\site-packages\twisted\internet\defer.py", line 653, in _runCallbacks
    current.result = callback(current.result, *args, **kw)
  File "c:\users\xkdlr\appdata\local\programs\python\python36-32\lib\site-packages\scrapy\core\downloader\handlers\http11.py", line 320, in _cb_timeout
    raise TimeoutError("Getting %s took longer than %s seconds." % (url, timeout))
twisted.internet.error.TimeoutError: User timeout caused connection failure: Getting https://www.clien.net/service/board/kin?&od=T31&po=3 took longer than 30.0 seconds..
2017-10-12 09:29:48 [scrapy.core.scraper] ERROR: Error downloading <GET https://www.clien.net/service/board/use?&od=T31&po=2>
Traceback (most recent call last):
  File "c:\users\xkdlr\appdata\local\programs\python\python36-32\lib\site-packages\twisted\internet\defer.py", line 1384, in _inlineCallbacks
    result = result.throwExceptionIntoGenerator(g)
  File "c:\users\xkdlr\appdata\local\programs\python\python36-32\lib\site-packages\twisted\python\failure.py", line 408, in throwExceptionIntoGenerator
    return g.throw(self.type, self.value, self.tb)
  File "c:\users\xkdlr\appdata\local\programs\python\python36-32\lib\site-packages\scrapy\core\downloader\middleware.py", line 43, in process_request
    defer.returnValue((yield download_func(request=request,spider=spider)))
  File "c:\users\xkdlr\appdata\local\programs\python\python36-32\lib\site-packages\twisted\internet\defer.py", line 653, in _runCallbacks
    current.result = callback(current.result, *args, **kw)
  File "c:\users\xkdlr\appdata\local\programs\python\python36-32\lib\site-packages\scrapy\core\downloader\handlers\http11.py", line 320, in _cb_timeout
    raise TimeoutError("Getting %s took longer than %s seconds." % (url, timeout))
twisted.internet.error.TimeoutError: User timeout caused connection failure: Getting https://www.clien.net/service/board/use?&od=T31&po=2 took longer than 30.0 seconds..
2017-10-12 09:29:48 [scrapy.core.scraper] ERROR: Error downloading <GET https://www.clien.net/service/board/news?&od=T31&po=3>
Traceback (most recent call last):
  File "c:\users\xkdlr\appdata\local\programs\python\python36-32\lib\site-packages\twisted\internet\defer.py", line 1384, in _inlineCallbacks
    result = result.throwExceptionIntoGenerator(g)
  File "c:\users\xkdlr\appdata\local\programs\python\python36-32\lib\site-packages\twisted\python\failure.py", line 408, in throwExceptionIntoGenerator
    return g.throw(self.type, self.value, self.tb)
  File "c:\users\xkdlr\appdata\local\programs\python\python36-32\lib\site-packages\scrapy\core\downloader\middleware.py", line 43, in process_request
    defer.returnValue((yield download_func(request=request,spider=spider)))
  File "c:\users\xkdlr\appdata\local\programs\python\python36-32\lib\site-packages\twisted\internet\defer.py", line 653, in _runCallbacks
    current.result = callback(current.result, *args, **kw)
  File "c:\users\xkdlr\appdata\local\programs\python\python36-32\lib\site-packages\scrapy\core\downloader\handlers\http11.py", line 320, in _cb_timeout
    raise TimeoutError("Getting %s took longer than %s seconds." % (url, timeout))
twisted.internet.error.TimeoutError: User timeout caused connection failure: Getting https://www.clien.net/service/board/news?&od=T31&po=3 took longer than 30.0 seconds..
2017-10-12 09:29:48 [scrapy.core.scraper] ERROR: Error downloading <GET https://www.clien.net/service/board/useful?&od=T31&po=3>
Traceback (most recent call last):
  File "c:\users\xkdlr\appdata\local\programs\python\python36-32\lib\site-packages\twisted\internet\defer.py", line 1384, in _inlineCallbacks
    result = result.throwExceptionIntoGenerator(g)
  File "c:\users\xkdlr\appdata\local\programs\python\python36-32\lib\site-packages\twisted\python\failure.py", line 408, in throwExceptionIntoGenerator
    return g.throw(self.type, self.value, self.tb)
  File "c:\users\xkdlr\appdata\local\programs\python\python36-32\lib\site-packages\scrapy\core\downloader\middleware.py", line 43, in process_request
    defer.returnValue((yield download_func(request=request,spider=spider)))
  File "c:\users\xkdlr\appdata\local\programs\python\python36-32\lib\site-packages\twisted\internet\defer.py", line 653, in _runCallbacks
    current.result = callback(current.result, *args, **kw)
  File "c:\users\xkdlr\appdata\local\programs\python\python36-32\lib\site-packages\scrapy\core\downloader\handlers\http11.py", line 320, in _cb_timeout
    raise TimeoutError("Getting %s took longer than %s seconds." % (url, timeout))
twisted.internet.error.TimeoutError: User timeout caused connection failure: Getting https://www.clien.net/service/board/useful?&od=T31&po=3 took longer than 30.0 seconds..
2017-10-12 09:29:48 [scrapy.core.scraper] ERROR: Error downloading <GET https://www.clien.net/service/board/park?&od=T31&po=3>
Traceback (most recent call last):
  File "c:\users\xkdlr\appdata\local\programs\python\python36-32\lib\site-packages\twisted\internet\defer.py", line 1384, in _inlineCallbacks
    result = result.throwExceptionIntoGenerator(g)
  File "c:\users\xkdlr\appdata\local\programs\python\python36-32\lib\site-packages\twisted\python\failure.py", line 408, in throwExceptionIntoGenerator
    return g.throw(self.type, self.value, self.tb)
  File "c:\users\xkdlr\appdata\local\programs\python\python36-32\lib\site-packages\scrapy\core\downloader\middleware.py", line 43, in process_request
    defer.returnValue((yield download_func(request=request,spider=spider)))
  File "c:\users\xkdlr\appdata\local\programs\python\python36-32\lib\site-packages\twisted\internet\defer.py", line 653, in _runCallbacks
    current.result = callback(current.result, *args, **kw)
  File "c:\users\xkdlr\appdata\local\programs\python\python36-32\lib\site-packages\scrapy\core\downloader\handlers\http11.py", line 320, in _cb_timeout
    raise TimeoutError("Getting %s took longer than %s seconds." % (url, timeout))
twisted.internet.error.TimeoutError: User timeout caused connection failure: Getting https://www.clien.net/service/board/park?&od=T31&po=3 took longer than 30.0 seconds..
2017-10-12 09:29:58 [scrapy.core.scraper] ERROR: Error downloading <GET https://www.clien.net/service/board/lecture?&od=T31&po=3>
Traceback (most recent call last):
  File "c:\users\xkdlr\appdata\local\programs\python\python36-32\lib\site-packages\twisted\internet\defer.py", line 1384, in _inlineCallbacks
    result = result.throwExceptionIntoGenerator(g)
  File "c:\users\xkdlr\appdata\local\programs\python\python36-32\lib\site-packages\twisted\python\failure.py", line 408, in throwExceptionIntoGenerator
    return g.throw(self.type, self.value, self.tb)
  File "c:\users\xkdlr\appdata\local\programs\python\python36-32\lib\site-packages\scrapy\core\downloader\middleware.py", line 43, in process_request
    defer.returnValue((yield download_func(request=request,spider=spider)))
  File "c:\users\xkdlr\appdata\local\programs\python\python36-32\lib\site-packages\twisted\internet\defer.py", line 653, in _runCallbacks
    current.result = callback(current.result, *args, **kw)
  File "c:\users\xkdlr\appdata\local\programs\python\python36-32\lib\site-packages\scrapy\core\downloader\handlers\http11.py", line 320, in _cb_timeout
    raise TimeoutError("Getting %s took longer than %s seconds." % (url, timeout))
twisted.internet.error.TimeoutError: User timeout caused connection failure: Getting https://www.clien.net/service/board/lecture?&od=T31&po=3 took longer than 30.0 seconds..
2017-10-12 09:29:58 [scrapy.core.scraper] ERROR: Error downloading <GET https://www.clien.net/service/board/kin?&od=T31&po=5>: User timeout caused connection failure.
2017-10-12 09:29:58 [scrapy.core.scraper] ERROR: Error downloading <GET https://www.clien.net/service/board/bug?&od=T31&po=4>
Traceback (most recent call last):
  File "c:\users\xkdlr\appdata\local\programs\python\python36-32\lib\site-packages\twisted\internet\defer.py", line 1384, in _inlineCallbacks
    result = result.throwExceptionIntoGenerator(g)
  File "c:\users\xkdlr\appdata\local\programs\python\python36-32\lib\site-packages\twisted\python\failure.py", line 408, in throwExceptionIntoGenerator
    return g.throw(self.type, self.value, self.tb)
  File "c:\users\xkdlr\appdata\local\programs\python\python36-32\lib\site-packages\scrapy\core\downloader\middleware.py", line 43, in process_request
    defer.returnValue((yield download_func(request=request,spider=spider)))
  File "c:\users\xkdlr\appdata\local\programs\python\python36-32\lib\site-packages\twisted\internet\defer.py", line 653, in _runCallbacks
    current.result = callback(current.result, *args, **kw)
  File "c:\users\xkdlr\appdata\local\programs\python\python36-32\lib\site-packages\scrapy\core\downloader\handlers\http11.py", line 320, in _cb_timeout
    raise TimeoutError("Getting %s took longer than %s seconds." % (url, timeout))
twisted.internet.error.TimeoutError: User timeout caused connection failure: Getting https://www.clien.net/service/board/bug?&od=T31&po=4 took longer than 30.0 seconds..
2017-10-12 09:29:58 [scrapy.core.scraper] ERROR: Error downloading <GET https://www.clien.net/service/board/lecture?&od=T31&po=4>: User timeout caused connection failure.
2017-10-12 09:30:57 [scrapy.core.scraper] ERROR: Error downloading <GET https://www.clien.net/service/board/use?&od=T31&po=3>
Traceback (most recent call last):
  File "c:\users\xkdlr\appdata\local\programs\python\python36-32\lib\site-packages\twisted\internet\defer.py", line 1384, in _inlineCallbacks
    result = result.throwExceptionIntoGenerator(g)
  File "c:\users\xkdlr\appdata\local\programs\python\python36-32\lib\site-packages\twisted\python\failure.py", line 408, in throwExceptionIntoGenerator
    return g.throw(self.type, self.value, self.tb)
  File "c:\users\xkdlr\appdata\local\programs\python\python36-32\lib\site-packages\scrapy\core\downloader\middleware.py", line 43, in process_request
    defer.returnValue((yield download_func(request=request,spider=spider)))
  File "c:\users\xkdlr\appdata\local\programs\python\python36-32\lib\site-packages\twisted\internet\defer.py", line 653, in _runCallbacks
    current.result = callback(current.result, *args, **kw)
  File "c:\users\xkdlr\appdata\local\programs\python\python36-32\lib\site-packages\scrapy\core\downloader\handlers\http11.py", line 320, in _cb_timeout
    raise TimeoutError("Getting %s took longer than %s seconds." % (url, timeout))
twisted.internet.error.TimeoutError: User timeout caused connection failure: Getting https://www.clien.net/service/board/use?&od=T31&po=3 took longer than 30.0 seconds..
2017-10-12 09:30:57 [scrapy.core.scraper] ERROR: Error downloading <GET https://www.clien.net/service/board/chehum?&od=T31&po=3>
Traceback (most recent call last):
  File "c:\users\xkdlr\appdata\local\programs\python\python36-32\lib\site-packages\twisted\internet\defer.py", line 1384, in _inlineCallbacks
    result = result.throwExceptionIntoGenerator(g)
  File "c:\users\xkdlr\appdata\local\programs\python\python36-32\lib\site-packages\twisted\python\failure.py", line 408, in throwExceptionIntoGenerator
    return g.throw(self.type, self.value, self.tb)
  File "c:\users\xkdlr\appdata\local\programs\python\python36-32\lib\site-packages\scrapy\core\downloader\middleware.py", line 43, in process_request
    defer.returnValue((yield download_func(request=request,spider=spider)))
  File "c:\users\xkdlr\appdata\local\programs\python\python36-32\lib\site-packages\twisted\internet\defer.py", line 653, in _runCallbacks
    current.result = callback(current.result, *args, **kw)
  File "c:\users\xkdlr\appdata\local\programs\python\python36-32\lib\site-packages\scrapy\core\downloader\handlers\http11.py", line 320, in _cb_timeout
    raise TimeoutError("Getting %s took longer than %s seconds." % (url, timeout))
twisted.internet.error.TimeoutError: User timeout caused connection failure: Getting https://www.clien.net/service/board/chehum?&od=T31&po=3 took longer than 30.0 seconds..
2017-10-12 09:30:57 [scrapy.core.scraper] ERROR: Error downloading <GET https://www.clien.net/service/board/useful?&od=T31&po=5>
Traceback (most recent call last):
  File "c:\users\xkdlr\appdata\local\programs\python\python36-32\lib\site-packages\twisted\internet\defer.py", line 1384, in _inlineCallbacks
    result = result.throwExceptionIntoGenerator(g)
  File "c:\users\xkdlr\appdata\local\programs\python\python36-32\lib\site-packages\twisted\python\failure.py", line 408, in throwExceptionIntoGenerator
    return g.throw(self.type, self.value, self.tb)
  File "c:\users\xkdlr\appdata\local\programs\python\python36-32\lib\site-packages\scrapy\core\downloader\middleware.py", line 43, in process_request
    defer.returnValue((yield download_func(request=request,spider=spider)))
  File "c:\users\xkdlr\appdata\local\programs\python\python36-32\lib\site-packages\twisted\internet\defer.py", line 653, in _runCallbacks
    current.result = callback(current.result, *args, **kw)
  File "c:\users\xkdlr\appdata\local\programs\python\python36-32\lib\site-packages\scrapy\core\downloader\handlers\http11.py", line 320, in _cb_timeout
    raise TimeoutError("Getting %s took longer than %s seconds." % (url, timeout))
twisted.internet.error.TimeoutError: User timeout caused connection failure: Getting https://www.clien.net/service/board/useful?&od=T31&po=5 took longer than 30.0 seconds..
