2017-10-11 23:34:38 [scrapy.core.scraper] ERROR: Spider error processing <GET http://web.humoruniv.com/board/humor/list.html?table=thema2&pg=0> (referer: None)
Traceback (most recent call last):
  File "c:\users\xkdlr\appdata\local\programs\python\python36-32\lib\site-packages\scrapy\utils\defer.py", line 102, in iter_errback
    yield next(it)
  File "c:\users\xkdlr\appdata\local\programs\python\python36-32\lib\site-packages\scrapy\spidermiddlewares\offsite.py", line 29, in process_spider_output
    for x in result:
  File "c:\users\xkdlr\appdata\local\programs\python\python36-32\lib\site-packages\scrapy\spidermiddlewares\referer.py", line 339, in <genexpr>
    return (_set_referer(r) for r in result or ())
  File "c:\users\xkdlr\appdata\local\programs\python\python36-32\lib\site-packages\scrapy\spidermiddlewares\urllength.py", line 37, in <genexpr>
    return (r for r in result or () if _filter(r))
  File "c:\users\xkdlr\appdata\local\programs\python\python36-32\lib\site-packages\scrapy\spidermiddlewares\depth.py", line 58, in <genexpr>
    return (r for r in result or () if _filter(r))
  File "D:\CapstoneDesign\Damoa\Git_Crawler\DamoaCrawler\Crawler\spiders\HumorUniv.py", line 90, in parse_site
    item['attribute'] = createItemUseBs4(item['link'],tagName, tagAttr, encoding="CP949", texttype="")
  File "D:\CapstoneDesign\Damoa\Git_Crawler\DamoaCrawler\Crawler\CreateItem.py", line 33, in createItemUseBs4
    origin = JoinPostUrl.find(name=name, attrs=attr).text.strip()
AttributeError: 'NoneType' object has no attribute 'text'
2017-10-11 23:42:12 [scrapy.core.scraper] ERROR: Spider error processing <GET http://web.humoruniv.com//board/humor/list.html?table=pdswait&pg=3> (referer: None)
Traceback (most recent call last):
  File "c:\users\xkdlr\appdata\local\programs\python\python36-32\lib\site-packages\scrapy\utils\defer.py", line 102, in iter_errback
    yield next(it)
  File "c:\users\xkdlr\appdata\local\programs\python\python36-32\lib\site-packages\scrapy\spidermiddlewares\offsite.py", line 29, in process_spider_output
    for x in result:
  File "c:\users\xkdlr\appdata\local\programs\python\python36-32\lib\site-packages\scrapy\spidermiddlewares\referer.py", line 339, in <genexpr>
    return (_set_referer(r) for r in result or ())
  File "c:\users\xkdlr\appdata\local\programs\python\python36-32\lib\site-packages\scrapy\spidermiddlewares\urllength.py", line 37, in <genexpr>
    return (r for r in result or () if _filter(r))
  File "c:\users\xkdlr\appdata\local\programs\python\python36-32\lib\site-packages\scrapy\spidermiddlewares\depth.py", line 58, in <genexpr>
    return (r for r in result or () if _filter(r))
  File "D:\CapstoneDesign\Damoa\Git_Crawler\DamoaCrawler\Crawler\spiders\HumorUniv.py", line 90, in parse_site
    item['attribute'] = createItemUseBs4(item['link'],tagName, tagAttr, encoding="CP949", texttype="")
  File "D:\CapstoneDesign\Damoa\Git_Crawler\DamoaCrawler\Crawler\CreateItem.py", line 33, in createItemUseBs4
    origin = JoinPostUrl.find(name=name, attrs=attr).text.strip()
AttributeError: 'NoneType' object has no attribute 'text'
2017-10-11 23:43:19 [scrapy.core.scraper] ERROR: Spider error processing <GET http://web.humoruniv.com/board/humor/list.html?table=thema2&pg=1> (referer: None)
Traceback (most recent call last):
  File "c:\users\xkdlr\appdata\local\programs\python\python36-32\lib\site-packages\urllib3\connection.py", line 141, in _new_conn
    (self.host, self.port), self.timeout, **extra_kw)
  File "c:\users\xkdlr\appdata\local\programs\python\python36-32\lib\site-packages\urllib3\util\connection.py", line 83, in create_connection
    raise err
  File "c:\users\xkdlr\appdata\local\programs\python\python36-32\lib\site-packages\urllib3\util\connection.py", line 73, in create_connection
    sock.connect(sa)
TimeoutError: [WinError 10060] 연결된 구성원으로부터 응답이 없어 연결하지 못했거나, 호스트로부터 응답이 없어 연결이 끊어졌습니다

During handling of the above exception, another exception occurred:

Traceback (most recent call last):
  File "c:\users\xkdlr\appdata\local\programs\python\python36-32\lib\site-packages\urllib3\connectionpool.py", line 601, in urlopen
    chunked=chunked)
  File "c:\users\xkdlr\appdata\local\programs\python\python36-32\lib\site-packages\urllib3\connectionpool.py", line 357, in _make_request
    conn.request(method, url, **httplib_request_kw)
  File "c:\users\xkdlr\appdata\local\programs\python\python36-32\lib\http\client.py", line 1239, in request
    self._send_request(method, url, body, headers, encode_chunked)
  File "c:\users\xkdlr\appdata\local\programs\python\python36-32\lib\http\client.py", line 1285, in _send_request
    self.endheaders(body, encode_chunked=encode_chunked)
  File "c:\users\xkdlr\appdata\local\programs\python\python36-32\lib\http\client.py", line 1234, in endheaders
    self._send_output(message_body, encode_chunked=encode_chunked)
  File "c:\users\xkdlr\appdata\local\programs\python\python36-32\lib\http\client.py", line 1026, in _send_output
    self.send(msg)
  File "c:\users\xkdlr\appdata\local\programs\python\python36-32\lib\http\client.py", line 964, in send
    self.connect()
  File "c:\users\xkdlr\appdata\local\programs\python\python36-32\lib\site-packages\urllib3\connection.py", line 166, in connect
    conn = self._new_conn()
  File "c:\users\xkdlr\appdata\local\programs\python\python36-32\lib\site-packages\urllib3\connection.py", line 150, in _new_conn
    self, "Failed to establish a new connection: %s" % e)
urllib3.exceptions.NewConnectionError: <urllib3.connection.HTTPConnection object at 0x06144430>: Failed to establish a new connection: [WinError 10060] 연결된 구성원으로부터 응답이 없어 연결하지 못했거나, 호스트로부터 응답이 없어 연결이 끊어졌습니다

During handling of the above exception, another exception occurred:

Traceback (most recent call last):
  File "c:\users\xkdlr\appdata\local\programs\python\python36-32\lib\site-packages\requests\adapters.py", line 440, in send
    timeout=timeout
  File "c:\users\xkdlr\appdata\local\programs\python\python36-32\lib\site-packages\urllib3\connectionpool.py", line 639, in urlopen
    _stacktrace=sys.exc_info()[2])
  File "c:\users\xkdlr\appdata\local\programs\python\python36-32\lib\site-packages\urllib3\util\retry.py", line 388, in increment
    raise MaxRetryError(_pool, url, error or ResponseError(cause))
urllib3.exceptions.MaxRetryError: HTTPConnectionPool(host='web.humoruniv.com', port=80): Max retries exceeded with url: /board/humor/read.html?table=thema2&pg=1&number=769215 (Caused by NewConnectionError('<urllib3.connection.HTTPConnection object at 0x06144430>: Failed to establish a new connection: [WinError 10060] 연결된 구성원으로부터 응답이 없어 연결하지 못했거나, 호스트로부터 응답이 없어 연결이 끊어졌습니다',))

During handling of the above exception, another exception occurred:

Traceback (most recent call last):
  File "c:\users\xkdlr\appdata\local\programs\python\python36-32\lib\site-packages\scrapy\utils\defer.py", line 102, in iter_errback
    yield next(it)
  File "c:\users\xkdlr\appdata\local\programs\python\python36-32\lib\site-packages\scrapy\spidermiddlewares\offsite.py", line 29, in process_spider_output
    for x in result:
  File "c:\users\xkdlr\appdata\local\programs\python\python36-32\lib\site-packages\scrapy\spidermiddlewares\referer.py", line 339, in <genexpr>
    return (_set_referer(r) for r in result or ())
  File "c:\users\xkdlr\appdata\local\programs\python\python36-32\lib\site-packages\scrapy\spidermiddlewares\urllength.py", line 37, in <genexpr>
    return (r for r in result or () if _filter(r))
  File "c:\users\xkdlr\appdata\local\programs\python\python36-32\lib\site-packages\scrapy\spidermiddlewares\depth.py", line 58, in <genexpr>
    return (r for r in result or () if _filter(r))
  File "D:\CapstoneDesign\Damoa\Git_Crawler\DamoaCrawler\Crawler\spiders\HumorUniv.py", line 118, in parse_site
    item['text'] = createItemUseBs4(item['link'], tagName, tagAttr, encoding="CP949", texttype="")
  File "D:\CapstoneDesign\Damoa\Git_Crawler\DamoaCrawler\Crawler\CreateItem.py", line 32, in createItemUseBs4
    JoinPostUrl = BeautifulSoup(requests.get(url).content, "html.parser", from_encoding=encoding)
  File "c:\users\xkdlr\appdata\local\programs\python\python36-32\lib\site-packages\requests\api.py", line 72, in get
    return request('get', url, params=params, **kwargs)
  File "c:\users\xkdlr\appdata\local\programs\python\python36-32\lib\site-packages\requests\api.py", line 58, in request
    return session.request(method=method, url=url, **kwargs)
  File "c:\users\xkdlr\appdata\local\programs\python\python36-32\lib\site-packages\requests\sessions.py", line 508, in request
    resp = self.send(prep, **send_kwargs)
  File "c:\users\xkdlr\appdata\local\programs\python\python36-32\lib\site-packages\requests\sessions.py", line 618, in send
    r = adapter.send(request, **kwargs)
  File "c:\users\xkdlr\appdata\local\programs\python\python36-32\lib\site-packages\requests\adapters.py", line 508, in send
    raise ConnectionError(e, request=request)
requests.exceptions.ConnectionError: HTTPConnectionPool(host='web.humoruniv.com', port=80): Max retries exceeded with url: /board/humor/read.html?table=thema2&pg=1&number=769215 (Caused by NewConnectionError('<urllib3.connection.HTTPConnection object at 0x06144430>: Failed to establish a new connection: [WinError 10060] 연결된 구성원으로부터 응답이 없어 연결하지 못했거나, 호스트로부터 응답이 없어 연결이 끊어졌습니다',))
2017-10-11 23:47:12 [scrapy.core.scraper] ERROR: Error downloading <GET http://web.humoruniv.com/board/humor/list.html?table=spnatural&pg=0>: [<twisted.python.failure.Failure twisted.internet.error.ConnectionDone: Connection was closed cleanly.>]
2017-10-11 23:47:29 [scrapy.core.scraper] ERROR: Error downloading <GET http://web.humoruniv.com/board/humor/list.html?table=love&pg=0>
Traceback (most recent call last):
  File "c:\users\xkdlr\appdata\local\programs\python\python36-32\lib\site-packages\twisted\internet\defer.py", line 1384, in _inlineCallbacks
    result = result.throwExceptionIntoGenerator(g)
  File "c:\users\xkdlr\appdata\local\programs\python\python36-32\lib\site-packages\twisted\python\failure.py", line 408, in throwExceptionIntoGenerator
    return g.throw(self.type, self.value, self.tb)
  File "c:\users\xkdlr\appdata\local\programs\python\python36-32\lib\site-packages\scrapy\core\downloader\middleware.py", line 43, in process_request
    defer.returnValue((yield download_func(request=request,spider=spider)))
  File "c:\users\xkdlr\appdata\local\programs\python\python36-32\lib\site-packages\twisted\internet\defer.py", line 653, in _runCallbacks
    current.result = callback(current.result, *args, **kw)
  File "c:\users\xkdlr\appdata\local\programs\python\python36-32\lib\site-packages\scrapy\core\downloader\handlers\http11.py", line 320, in _cb_timeout
    raise TimeoutError("Getting %s took longer than %s seconds." % (url, timeout))
twisted.internet.error.TimeoutError: User timeout caused connection failure: Getting http://web.humoruniv.com/board/humor/list.html?table=love&pg=0 took longer than 30.0 seconds..
2017-10-11 23:47:41 [scrapy.core.scraper] ERROR: Error downloading <GET http://web.humoruniv.com/board/humor/list.html?table=moofama&pg=0>
Traceback (most recent call last):
  File "c:\users\xkdlr\appdata\local\programs\python\python36-32\lib\site-packages\twisted\internet\defer.py", line 1384, in _inlineCallbacks
    result = result.throwExceptionIntoGenerator(g)
  File "c:\users\xkdlr\appdata\local\programs\python\python36-32\lib\site-packages\twisted\python\failure.py", line 408, in throwExceptionIntoGenerator
    return g.throw(self.type, self.value, self.tb)
  File "c:\users\xkdlr\appdata\local\programs\python\python36-32\lib\site-packages\scrapy\core\downloader\middleware.py", line 43, in process_request
    defer.returnValue((yield download_func(request=request,spider=spider)))
  File "c:\users\xkdlr\appdata\local\programs\python\python36-32\lib\site-packages\twisted\internet\defer.py", line 653, in _runCallbacks
    current.result = callback(current.result, *args, **kw)
  File "c:\users\xkdlr\appdata\local\programs\python\python36-32\lib\site-packages\scrapy\core\downloader\handlers\http11.py", line 320, in _cb_timeout
    raise TimeoutError("Getting %s took longer than %s seconds." % (url, timeout))
twisted.internet.error.TimeoutError: User timeout caused connection failure: Getting http://web.humoruniv.com/board/humor/list.html?table=moofama&pg=0 took longer than 30.0 seconds..
2017-10-11 23:47:50 [scrapy.core.scraper] ERROR: Error downloading <GET http://web.humoruniv.com/board/humor/list.html?table=workshop&pg=0>
Traceback (most recent call last):
  File "c:\users\xkdlr\appdata\local\programs\python\python36-32\lib\site-packages\twisted\internet\defer.py", line 1384, in _inlineCallbacks
    result = result.throwExceptionIntoGenerator(g)
  File "c:\users\xkdlr\appdata\local\programs\python\python36-32\lib\site-packages\twisted\python\failure.py", line 408, in throwExceptionIntoGenerator
    return g.throw(self.type, self.value, self.tb)
  File "c:\users\xkdlr\appdata\local\programs\python\python36-32\lib\site-packages\scrapy\core\downloader\middleware.py", line 43, in process_request
    defer.returnValue((yield download_func(request=request,spider=spider)))
  File "c:\users\xkdlr\appdata\local\programs\python\python36-32\lib\site-packages\twisted\internet\defer.py", line 653, in _runCallbacks
    current.result = callback(current.result, *args, **kw)
  File "c:\users\xkdlr\appdata\local\programs\python\python36-32\lib\site-packages\scrapy\core\downloader\handlers\http11.py", line 320, in _cb_timeout
    raise TimeoutError("Getting %s took longer than %s seconds." % (url, timeout))
twisted.internet.error.TimeoutError: User timeout caused connection failure: Getting http://web.humoruniv.com/board/humor/list.html?table=workshop&pg=0 took longer than 30.0 seconds..
2017-10-11 23:47:50 [scrapy.core.scraper] ERROR: Error downloading <GET http://web.humoruniv.com/board/humor/list.html?table=solo&pg=0>
Traceback (most recent call last):
  File "c:\users\xkdlr\appdata\local\programs\python\python36-32\lib\site-packages\twisted\internet\defer.py", line 1384, in _inlineCallbacks
    result = result.throwExceptionIntoGenerator(g)
  File "c:\users\xkdlr\appdata\local\programs\python\python36-32\lib\site-packages\twisted\python\failure.py", line 408, in throwExceptionIntoGenerator
    return g.throw(self.type, self.value, self.tb)
  File "c:\users\xkdlr\appdata\local\programs\python\python36-32\lib\site-packages\scrapy\core\downloader\middleware.py", line 43, in process_request
    defer.returnValue((yield download_func(request=request,spider=spider)))
  File "c:\users\xkdlr\appdata\local\programs\python\python36-32\lib\site-packages\twisted\internet\defer.py", line 653, in _runCallbacks
    current.result = callback(current.result, *args, **kw)
  File "c:\users\xkdlr\appdata\local\programs\python\python36-32\lib\site-packages\scrapy\core\downloader\handlers\http11.py", line 320, in _cb_timeout
    raise TimeoutError("Getting %s took longer than %s seconds." % (url, timeout))
twisted.internet.error.TimeoutError: User timeout caused connection failure: Getting http://web.humoruniv.com/board/humor/list.html?table=solo&pg=0 took longer than 30.0 seconds..
2017-10-11 23:48:27 [scrapy.core.scraper] ERROR: Error downloading <GET http://web.humoruniv.com/board/humor/list.html?table=studying&pg=0>
Traceback (most recent call last):
  File "c:\users\xkdlr\appdata\local\programs\python\python36-32\lib\site-packages\twisted\internet\defer.py", line 1384, in _inlineCallbacks
    result = result.throwExceptionIntoGenerator(g)
  File "c:\users\xkdlr\appdata\local\programs\python\python36-32\lib\site-packages\twisted\python\failure.py", line 408, in throwExceptionIntoGenerator
    return g.throw(self.type, self.value, self.tb)
  File "c:\users\xkdlr\appdata\local\programs\python\python36-32\lib\site-packages\scrapy\core\downloader\middleware.py", line 43, in process_request
    defer.returnValue((yield download_func(request=request,spider=spider)))
  File "c:\users\xkdlr\appdata\local\programs\python\python36-32\lib\site-packages\twisted\internet\defer.py", line 653, in _runCallbacks
    current.result = callback(current.result, *args, **kw)
  File "c:\users\xkdlr\appdata\local\programs\python\python36-32\lib\site-packages\scrapy\core\downloader\handlers\http11.py", line 320, in _cb_timeout
    raise TimeoutError("Getting %s took longer than %s seconds." % (url, timeout))
twisted.internet.error.TimeoutError: User timeout caused connection failure: Getting http://web.humoruniv.com/board/humor/list.html?table=studying&pg=0 took longer than 30.0 seconds..
2017-10-11 23:48:29 [scrapy.core.scraper] ERROR: Error downloading <GET http://web.humoruniv.com/board/humor/list.html?table=army&pg=0>: [<twisted.python.failure.Failure twisted.internet.error.ConnectionDone: Connection was closed cleanly.>]
2017-10-11 23:48:50 [scrapy.core.scraper] ERROR: Error downloading <GET http://web.humoruniv.com/board/humor/list.html?table=dump&pg=0>
Traceback (most recent call last):
  File "c:\users\xkdlr\appdata\local\programs\python\python36-32\lib\site-packages\twisted\internet\defer.py", line 1384, in _inlineCallbacks
    result = result.throwExceptionIntoGenerator(g)
  File "c:\users\xkdlr\appdata\local\programs\python\python36-32\lib\site-packages\twisted\python\failure.py", line 408, in throwExceptionIntoGenerator
    return g.throw(self.type, self.value, self.tb)
  File "c:\users\xkdlr\appdata\local\programs\python\python36-32\lib\site-packages\scrapy\core\downloader\middleware.py", line 43, in process_request
    defer.returnValue((yield download_func(request=request,spider=spider)))
  File "c:\users\xkdlr\appdata\local\programs\python\python36-32\lib\site-packages\twisted\internet\defer.py", line 653, in _runCallbacks
    current.result = callback(current.result, *args, **kw)
  File "c:\users\xkdlr\appdata\local\programs\python\python36-32\lib\site-packages\scrapy\core\downloader\handlers\http11.py", line 320, in _cb_timeout
    raise TimeoutError("Getting %s took longer than %s seconds." % (url, timeout))
twisted.internet.error.TimeoutError: User timeout caused connection failure: Getting http://web.humoruniv.com/board/humor/list.html?table=dump&pg=0 took longer than 30.0 seconds..
2017-10-11 23:48:56 [scrapy.core.scraper] ERROR: Error downloading <GET http://web.humoruniv.com//board/humor/list.html?table=art_toon&pg=1>: [<twisted.python.failure.Failure twisted.internet.error.ConnectionDone: Connection was closed cleanly.>]
2017-10-11 23:49:31 [scrapy.core.scraper] ERROR: Error downloading <GET http://web.humoruniv.com/board/humor/list.html?table=poll&pg=1>: [<twisted.python.failure.Failure twisted.internet.error.ConnectionDone: Connection was closed cleanly.>]
2017-10-11 23:49:31 [scrapy.core.scraper] ERROR: Error downloading <GET http://web.humoruniv.com/board/humor/list.html?table=guest&pg=1>: [<twisted.python.failure.Failure twisted.internet.error.ConnectionDone: Connection was closed cleanly.>]
2017-10-11 23:49:54 [scrapy.core.scraper] ERROR: Error downloading <GET http://web.humoruniv.com/board/humor/list.html?table=thema3&pg=1>: [<twisted.python.failure.Failure twisted.internet.error.ConnectionDone: Connection was closed cleanly.>]
2017-10-11 23:50:05 [scrapy.core.scraper] ERROR: Error downloading <GET http://web.humoruniv.com/board/humor/list.html?table=workshop&pg=1>: [<twisted.python.failure.Failure twisted.internet.error.ConnectionDone: Connection was closed cleanly.>]
2017-10-11 23:50:05 [scrapy.core.scraper] ERROR: Error downloading <GET http://web.humoruniv.com/board/humor/list.html?table=moofama&pg=1>: [<twisted.python.failure.Failure twisted.internet.error.ConnectionDone: Connection was closed cleanly.>]
2017-10-11 23:50:05 [scrapy.core.scraper] ERROR: Error downloading <GET http://web.humoruniv.com/board/humor/list.html?table=whitehand&pg=1>: [<twisted.python.failure.Failure twisted.internet.error.ConnectionDone: Connection was closed cleanly.>]
2017-10-11 23:50:15 [scrapy.core.scraper] ERROR: Error downloading <GET http://web.humoruniv.com/board/humor/list.html?table=com&pg=1>
Traceback (most recent call last):
  File "c:\users\xkdlr\appdata\local\programs\python\python36-32\lib\site-packages\twisted\internet\defer.py", line 1384, in _inlineCallbacks
    result = result.throwExceptionIntoGenerator(g)
  File "c:\users\xkdlr\appdata\local\programs\python\python36-32\lib\site-packages\twisted\python\failure.py", line 408, in throwExceptionIntoGenerator
    return g.throw(self.type, self.value, self.tb)
  File "c:\users\xkdlr\appdata\local\programs\python\python36-32\lib\site-packages\scrapy\core\downloader\middleware.py", line 43, in process_request
    defer.returnValue((yield download_func(request=request,spider=spider)))
  File "c:\users\xkdlr\appdata\local\programs\python\python36-32\lib\site-packages\twisted\internet\defer.py", line 653, in _runCallbacks
    current.result = callback(current.result, *args, **kw)
  File "c:\users\xkdlr\appdata\local\programs\python\python36-32\lib\site-packages\scrapy\core\downloader\handlers\http11.py", line 320, in _cb_timeout
    raise TimeoutError("Getting %s took longer than %s seconds." % (url, timeout))
twisted.internet.error.TimeoutError: User timeout caused connection failure: Getting http://web.humoruniv.com/board/humor/list.html?table=com&pg=1 took longer than 30.0 seconds..
2017-10-11 23:50:36 [scrapy.core.scraper] ERROR: Error downloading <GET http://web.humoruniv.com/board/humor/list.html?table=solo&pg=1>
Traceback (most recent call last):
  File "c:\users\xkdlr\appdata\local\programs\python\python36-32\lib\site-packages\twisted\internet\defer.py", line 1384, in _inlineCallbacks
    result = result.throwExceptionIntoGenerator(g)
  File "c:\users\xkdlr\appdata\local\programs\python\python36-32\lib\site-packages\twisted\python\failure.py", line 408, in throwExceptionIntoGenerator
    return g.throw(self.type, self.value, self.tb)
  File "c:\users\xkdlr\appdata\local\programs\python\python36-32\lib\site-packages\scrapy\core\downloader\middleware.py", line 43, in process_request
    defer.returnValue((yield download_func(request=request,spider=spider)))
  File "c:\users\xkdlr\appdata\local\programs\python\python36-32\lib\site-packages\twisted\internet\defer.py", line 653, in _runCallbacks
    current.result = callback(current.result, *args, **kw)
  File "c:\users\xkdlr\appdata\local\programs\python\python36-32\lib\site-packages\scrapy\core\downloader\handlers\http11.py", line 320, in _cb_timeout
    raise TimeoutError("Getting %s took longer than %s seconds." % (url, timeout))
twisted.internet.error.TimeoutError: User timeout caused connection failure: Getting http://web.humoruniv.com/board/humor/list.html?table=solo&pg=1 took longer than 30.0 seconds..
2017-10-11 23:50:39 [scrapy.core.scraper] ERROR: Error downloading <GET http://web.humoruniv.com/board/humor/list.html?table=muzik&pg=1>
Traceback (most recent call last):
  File "c:\users\xkdlr\appdata\local\programs\python\python36-32\lib\site-packages\twisted\internet\defer.py", line 1384, in _inlineCallbacks
    result = result.throwExceptionIntoGenerator(g)
  File "c:\users\xkdlr\appdata\local\programs\python\python36-32\lib\site-packages\twisted\python\failure.py", line 408, in throwExceptionIntoGenerator
    return g.throw(self.type, self.value, self.tb)
  File "c:\users\xkdlr\appdata\local\programs\python\python36-32\lib\site-packages\scrapy\core\downloader\middleware.py", line 43, in process_request
    defer.returnValue((yield download_func(request=request,spider=spider)))
  File "c:\users\xkdlr\appdata\local\programs\python\python36-32\lib\site-packages\twisted\internet\defer.py", line 653, in _runCallbacks
    current.result = callback(current.result, *args, **kw)
  File "c:\users\xkdlr\appdata\local\programs\python\python36-32\lib\site-packages\scrapy\core\downloader\handlers\http11.py", line 320, in _cb_timeout
    raise TimeoutError("Getting %s took longer than %s seconds." % (url, timeout))
twisted.internet.error.TimeoutError: User timeout caused connection failure: Getting http://web.humoruniv.com/board/humor/list.html?table=muzik&pg=1 took longer than 30.0 seconds..
2017-10-11 23:50:40 [scrapy.core.scraper] ERROR: Error downloading <GET http://web.humoruniv.com/board/humor/list.html?table=memory&pg=1>: [<twisted.python.failure.Failure twisted.internet.error.ConnectionDone: Connection was closed cleanly.>]
2017-10-11 23:50:47 [scrapy.core.scraper] ERROR: Error downloading <GET http://web.humoruniv.com/board/humor/list.html?table=sns&pg=1>
Traceback (most recent call last):
  File "c:\users\xkdlr\appdata\local\programs\python\python36-32\lib\site-packages\twisted\internet\defer.py", line 1384, in _inlineCallbacks
    result = result.throwExceptionIntoGenerator(g)
  File "c:\users\xkdlr\appdata\local\programs\python\python36-32\lib\site-packages\twisted\python\failure.py", line 408, in throwExceptionIntoGenerator
    return g.throw(self.type, self.value, self.tb)
  File "c:\users\xkdlr\appdata\local\programs\python\python36-32\lib\site-packages\scrapy\core\downloader\middleware.py", line 43, in process_request
    defer.returnValue((yield download_func(request=request,spider=spider)))
  File "c:\users\xkdlr\appdata\local\programs\python\python36-32\lib\site-packages\twisted\internet\defer.py", line 653, in _runCallbacks
    current.result = callback(current.result, *args, **kw)
  File "c:\users\xkdlr\appdata\local\programs\python\python36-32\lib\site-packages\scrapy\core\downloader\handlers\http11.py", line 320, in _cb_timeout
    raise TimeoutError("Getting %s took longer than %s seconds." % (url, timeout))
twisted.internet.error.TimeoutError: User timeout caused connection failure: Getting http://web.humoruniv.com/board/humor/list.html?table=sns&pg=1 took longer than 30.0 seconds..
2017-10-11 23:51:18 [scrapy.core.scraper] ERROR: Error downloading <GET http://web.humoruniv.com//board/humor/list.html?table=kin&pg=2>: [<twisted.python.failure.Failure twisted.internet.error.ConnectionDone: Connection was closed cleanly.>]
2017-10-11 23:51:18 [scrapy.core.scraper] ERROR: Error downloading <GET http://web.humoruniv.com/board/humor/list.html?table=pds&pg=2>: [<twisted.python.failure.Failure twisted.internet.error.ConnectionDone: Connection was closed cleanly.>]
2017-10-11 23:51:18 [scrapy.core.scraper] ERROR: Error downloading <GET http://web.humoruniv.com//board/humor/list.html?table=pdswait&pg=2>: [<twisted.python.failure.Failure twisted.internet.error.ConnectionDone: Connection was closed cleanly.>]
2017-10-11 23:51:52 [scrapy.core.scraper] ERROR: Error downloading <GET http://web.humoruniv.com//board/humor/list.html?table=art_toon&pg=2>: [<twisted.python.failure.Failure twisted.internet.error.ConnectionDone: Connection was closed cleanly.>]
2017-10-11 23:51:52 [scrapy.core.scraper] ERROR: Error downloading <GET http://web.humoruniv.com//board/humor/list.html?table=nova_toon&pg=2>: [<twisted.python.failure.Failure twisted.internet.error.ConnectionDone: Connection was closed cleanly.>]
2017-10-11 23:51:55 [scrapy.core.scraper] ERROR: Error downloading <GET http://web.humoruniv.com/board/humor/list.html?table=free&pg=2>
Traceback (most recent call last):
  File "c:\users\xkdlr\appdata\local\programs\python\python36-32\lib\site-packages\twisted\internet\defer.py", line 1384, in _inlineCallbacks
    result = result.throwExceptionIntoGenerator(g)
  File "c:\users\xkdlr\appdata\local\programs\python\python36-32\lib\site-packages\twisted\python\failure.py", line 408, in throwExceptionIntoGenerator
    return g.throw(self.type, self.value, self.tb)
  File "c:\users\xkdlr\appdata\local\programs\python\python36-32\lib\site-packages\scrapy\core\downloader\middleware.py", line 43, in process_request
    defer.returnValue((yield download_func(request=request,spider=spider)))
  File "c:\users\xkdlr\appdata\local\programs\python\python36-32\lib\site-packages\twisted\internet\defer.py", line 653, in _runCallbacks
    current.result = callback(current.result, *args, **kw)
  File "c:\users\xkdlr\appdata\local\programs\python\python36-32\lib\site-packages\scrapy\core\downloader\handlers\http11.py", line 320, in _cb_timeout
    raise TimeoutError("Getting %s took longer than %s seconds." % (url, timeout))
twisted.internet.error.TimeoutError: User timeout caused connection failure: Getting http://web.humoruniv.com/board/humor/list.html?table=free&pg=2 took longer than 30.0 seconds..
2017-10-11 23:54:32 [scrapy.core.scraper] ERROR: Error downloading <GET http://web.humoruniv.com/board/humor/list.html?table=guest&pg=3>
Traceback (most recent call last):
  File "c:\users\xkdlr\appdata\local\programs\python\python36-32\lib\site-packages\twisted\internet\defer.py", line 1384, in _inlineCallbacks
    result = result.throwExceptionIntoGenerator(g)
  File "c:\users\xkdlr\appdata\local\programs\python\python36-32\lib\site-packages\twisted\python\failure.py", line 408, in throwExceptionIntoGenerator
    return g.throw(self.type, self.value, self.tb)
  File "c:\users\xkdlr\appdata\local\programs\python\python36-32\lib\site-packages\scrapy\core\downloader\middleware.py", line 43, in process_request
    defer.returnValue((yield download_func(request=request,spider=spider)))
  File "c:\users\xkdlr\appdata\local\programs\python\python36-32\lib\site-packages\twisted\internet\defer.py", line 653, in _runCallbacks
    current.result = callback(current.result, *args, **kw)
  File "c:\users\xkdlr\appdata\local\programs\python\python36-32\lib\site-packages\scrapy\core\downloader\handlers\http11.py", line 320, in _cb_timeout
    raise TimeoutError("Getting %s took longer than %s seconds." % (url, timeout))
twisted.internet.error.TimeoutError: User timeout caused connection failure: Getting http://web.humoruniv.com/board/humor/list.html?table=guest&pg=3 took longer than 30.0 seconds..
2017-10-11 23:55:16 [scrapy.core.scraper] ERROR: Error downloading <GET http://web.humoruniv.com/board/humor/list.html?table=free&pg=3>
Traceback (most recent call last):
  File "c:\users\xkdlr\appdata\local\programs\python\python36-32\lib\site-packages\twisted\internet\defer.py", line 1384, in _inlineCallbacks
    result = result.throwExceptionIntoGenerator(g)
  File "c:\users\xkdlr\appdata\local\programs\python\python36-32\lib\site-packages\twisted\python\failure.py", line 408, in throwExceptionIntoGenerator
    return g.throw(self.type, self.value, self.tb)
  File "c:\users\xkdlr\appdata\local\programs\python\python36-32\lib\site-packages\scrapy\core\downloader\middleware.py", line 43, in process_request
    defer.returnValue((yield download_func(request=request,spider=spider)))
  File "c:\users\xkdlr\appdata\local\programs\python\python36-32\lib\site-packages\twisted\internet\defer.py", line 653, in _runCallbacks
    current.result = callback(current.result, *args, **kw)
  File "c:\users\xkdlr\appdata\local\programs\python\python36-32\lib\site-packages\scrapy\core\downloader\handlers\http11.py", line 320, in _cb_timeout
    raise TimeoutError("Getting %s took longer than %s seconds." % (url, timeout))
twisted.internet.error.TimeoutError: User timeout caused connection failure: Getting http://web.humoruniv.com/board/humor/list.html?table=free&pg=3 took longer than 30.0 seconds..
2017-10-11 23:58:13 [scrapy.core.scraper] ERROR: Error downloading <GET http://web.humoruniv.com/board/humor/list.html?table=lol&pg=3>: [<twisted.python.failure.Failure twisted.internet.error.ConnectionDone: Connection was closed cleanly.>]
2017-10-11 23:58:13 [scrapy.core.scraper] ERROR: Error downloading <GET http://web.humoruniv.com/board/humor/list.html?table=pride&pg=3>: [<twisted.python.failure.Failure twisted.internet.error.ConnectionDone: Connection was closed cleanly.>]
2017-10-12 00:00:16 [scrapy.core.scraper] ERROR: Error downloading <GET http://web.humoruniv.com//board/humor/list.html?table=pdswait&pg=4>: [<twisted.python.failure.Failure twisted.internet.error.ConnectionDone: Connection was closed cleanly.>]
2017-10-12 00:00:56 [scrapy.core.scraper] ERROR: Error downloading <GET http://web.humoruniv.com/board/humor/list.html?table=pds&pg=4>
Traceback (most recent call last):
  File "c:\users\xkdlr\appdata\local\programs\python\python36-32\lib\site-packages\twisted\internet\defer.py", line 1384, in _inlineCallbacks
    result = result.throwExceptionIntoGenerator(g)
  File "c:\users\xkdlr\appdata\local\programs\python\python36-32\lib\site-packages\twisted\python\failure.py", line 408, in throwExceptionIntoGenerator
    return g.throw(self.type, self.value, self.tb)
  File "c:\users\xkdlr\appdata\local\programs\python\python36-32\lib\site-packages\scrapy\core\downloader\middleware.py", line 43, in process_request
    defer.returnValue((yield download_func(request=request,spider=spider)))
  File "c:\users\xkdlr\appdata\local\programs\python\python36-32\lib\site-packages\twisted\internet\defer.py", line 653, in _runCallbacks
    current.result = callback(current.result, *args, **kw)
  File "c:\users\xkdlr\appdata\local\programs\python\python36-32\lib\site-packages\scrapy\core\downloader\handlers\http11.py", line 320, in _cb_timeout
    raise TimeoutError("Getting %s took longer than %s seconds." % (url, timeout))
twisted.internet.error.TimeoutError: User timeout caused connection failure: Getting http://web.humoruniv.com/board/humor/list.html?table=pds&pg=4 took longer than 30.0 seconds..
2017-10-12 00:01:42 [scrapy.core.scraper] ERROR: Error downloading <GET http://web.humoruniv.com//board/humor/list.html?table=art_toon&pg=4>
Traceback (most recent call last):
  File "c:\users\xkdlr\appdata\local\programs\python\python36-32\lib\site-packages\twisted\internet\defer.py", line 1384, in _inlineCallbacks
    result = result.throwExceptionIntoGenerator(g)
  File "c:\users\xkdlr\appdata\local\programs\python\python36-32\lib\site-packages\twisted\python\failure.py", line 408, in throwExceptionIntoGenerator
    return g.throw(self.type, self.value, self.tb)
  File "c:\users\xkdlr\appdata\local\programs\python\python36-32\lib\site-packages\scrapy\core\downloader\middleware.py", line 43, in process_request
    defer.returnValue((yield download_func(request=request,spider=spider)))
  File "c:\users\xkdlr\appdata\local\programs\python\python36-32\lib\site-packages\twisted\internet\defer.py", line 653, in _runCallbacks
    current.result = callback(current.result, *args, **kw)
  File "c:\users\xkdlr\appdata\local\programs\python\python36-32\lib\site-packages\scrapy\core\downloader\handlers\http11.py", line 320, in _cb_timeout
    raise TimeoutError("Getting %s took longer than %s seconds." % (url, timeout))
twisted.internet.error.TimeoutError: User timeout caused connection failure: Getting http://web.humoruniv.com//board/humor/list.html?table=art_toon&pg=4 took longer than 30.0 seconds..
2017-10-12 00:01:47 [scrapy.core.scraper] ERROR: Error downloading <GET http://web.humoruniv.com//board/humor/list.html?table=kin&pg=4>
Traceback (most recent call last):
  File "c:\users\xkdlr\appdata\local\programs\python\python36-32\lib\site-packages\twisted\internet\defer.py", line 1384, in _inlineCallbacks
    result = result.throwExceptionIntoGenerator(g)
  File "c:\users\xkdlr\appdata\local\programs\python\python36-32\lib\site-packages\twisted\python\failure.py", line 408, in throwExceptionIntoGenerator
    return g.throw(self.type, self.value, self.tb)
  File "c:\users\xkdlr\appdata\local\programs\python\python36-32\lib\site-packages\scrapy\core\downloader\middleware.py", line 43, in process_request
    defer.returnValue((yield download_func(request=request,spider=spider)))
  File "c:\users\xkdlr\appdata\local\programs\python\python36-32\lib\site-packages\twisted\internet\defer.py", line 653, in _runCallbacks
    current.result = callback(current.result, *args, **kw)
  File "c:\users\xkdlr\appdata\local\programs\python\python36-32\lib\site-packages\scrapy\core\downloader\handlers\http11.py", line 320, in _cb_timeout
    raise TimeoutError("Getting %s took longer than %s seconds." % (url, timeout))
twisted.internet.error.TimeoutError: User timeout caused connection failure: Getting http://web.humoruniv.com//board/humor/list.html?table=kin&pg=4 took longer than 30.0 seconds..
2017-10-12 00:02:45 [scrapy.core.scraper] ERROR: Error downloading <GET http://web.humoruniv.com/board/humor/list.html?table=thema2&pg=4>
Traceback (most recent call last):
  File "c:\users\xkdlr\appdata\local\programs\python\python36-32\lib\site-packages\twisted\internet\defer.py", line 1384, in _inlineCallbacks
    result = result.throwExceptionIntoGenerator(g)
  File "c:\users\xkdlr\appdata\local\programs\python\python36-32\lib\site-packages\twisted\python\failure.py", line 408, in throwExceptionIntoGenerator
    return g.throw(self.type, self.value, self.tb)
  File "c:\users\xkdlr\appdata\local\programs\python\python36-32\lib\site-packages\scrapy\core\downloader\middleware.py", line 43, in process_request
    defer.returnValue((yield download_func(request=request,spider=spider)))
  File "c:\users\xkdlr\appdata\local\programs\python\python36-32\lib\site-packages\twisted\internet\defer.py", line 653, in _runCallbacks
    current.result = callback(current.result, *args, **kw)
  File "c:\users\xkdlr\appdata\local\programs\python\python36-32\lib\site-packages\scrapy\core\downloader\handlers\http11.py", line 320, in _cb_timeout
    raise TimeoutError("Getting %s took longer than %s seconds." % (url, timeout))
twisted.internet.error.TimeoutError: User timeout caused connection failure: Getting http://web.humoruniv.com/board/humor/list.html?table=thema2&pg=4 took longer than 30.0 seconds..
2017-10-12 00:02:45 [scrapy.core.scraper] ERROR: Error downloading <GET http://web.humoruniv.com/board/humor/list.html?table=game&pg=4>
Traceback (most recent call last):
  File "c:\users\xkdlr\appdata\local\programs\python\python36-32\lib\site-packages\twisted\internet\defer.py", line 1384, in _inlineCallbacks
    result = result.throwExceptionIntoGenerator(g)
  File "c:\users\xkdlr\appdata\local\programs\python\python36-32\lib\site-packages\twisted\python\failure.py", line 408, in throwExceptionIntoGenerator
    return g.throw(self.type, self.value, self.tb)
  File "c:\users\xkdlr\appdata\local\programs\python\python36-32\lib\site-packages\scrapy\core\downloader\middleware.py", line 43, in process_request
    defer.returnValue((yield download_func(request=request,spider=spider)))
  File "c:\users\xkdlr\appdata\local\programs\python\python36-32\lib\site-packages\twisted\internet\defer.py", line 653, in _runCallbacks
    current.result = callback(current.result, *args, **kw)
  File "c:\users\xkdlr\appdata\local\programs\python\python36-32\lib\site-packages\scrapy\core\downloader\handlers\http11.py", line 320, in _cb_timeout
    raise TimeoutError("Getting %s took longer than %s seconds." % (url, timeout))
twisted.internet.error.TimeoutError: User timeout caused connection failure: Getting http://web.humoruniv.com/board/humor/list.html?table=game&pg=4 took longer than 30.0 seconds..
2017-10-12 00:03:21 [scrapy.core.scraper] ERROR: Error downloading <GET http://web.humoruniv.com/board/humor/list.html?table=lol&pg=4>
Traceback (most recent call last):
  File "c:\users\xkdlr\appdata\local\programs\python\python36-32\lib\site-packages\twisted\internet\defer.py", line 1384, in _inlineCallbacks
    result = result.throwExceptionIntoGenerator(g)
  File "c:\users\xkdlr\appdata\local\programs\python\python36-32\lib\site-packages\twisted\python\failure.py", line 408, in throwExceptionIntoGenerator
    return g.throw(self.type, self.value, self.tb)
  File "c:\users\xkdlr\appdata\local\programs\python\python36-32\lib\site-packages\scrapy\core\downloader\middleware.py", line 43, in process_request
    defer.returnValue((yield download_func(request=request,spider=spider)))
  File "c:\users\xkdlr\appdata\local\programs\python\python36-32\lib\site-packages\twisted\internet\defer.py", line 653, in _runCallbacks
    current.result = callback(current.result, *args, **kw)
  File "c:\users\xkdlr\appdata\local\programs\python\python36-32\lib\site-packages\scrapy\core\downloader\handlers\http11.py", line 320, in _cb_timeout
    raise TimeoutError("Getting %s took longer than %s seconds." % (url, timeout))
twisted.internet.error.TimeoutError: User timeout caused connection failure: Getting http://web.humoruniv.com/board/humor/list.html?table=lol&pg=4 took longer than 30.0 seconds..
2017-10-12 00:03:38 [scrapy.core.scraper] ERROR: Error downloading <GET http://web.humoruniv.com/board/humor/list.html?table=muzik&pg=4>
Traceback (most recent call last):
  File "c:\users\xkdlr\appdata\local\programs\python\python36-32\lib\site-packages\twisted\internet\defer.py", line 1384, in _inlineCallbacks
    result = result.throwExceptionIntoGenerator(g)
  File "c:\users\xkdlr\appdata\local\programs\python\python36-32\lib\site-packages\twisted\python\failure.py", line 408, in throwExceptionIntoGenerator
    return g.throw(self.type, self.value, self.tb)
  File "c:\users\xkdlr\appdata\local\programs\python\python36-32\lib\site-packages\scrapy\core\downloader\middleware.py", line 43, in process_request
    defer.returnValue((yield download_func(request=request,spider=spider)))
  File "c:\users\xkdlr\appdata\local\programs\python\python36-32\lib\site-packages\twisted\internet\defer.py", line 653, in _runCallbacks
    current.result = callback(current.result, *args, **kw)
  File "c:\users\xkdlr\appdata\local\programs\python\python36-32\lib\site-packages\scrapy\core\downloader\handlers\http11.py", line 320, in _cb_timeout
    raise TimeoutError("Getting %s took longer than %s seconds." % (url, timeout))
twisted.internet.error.TimeoutError: User timeout caused connection failure: Getting http://web.humoruniv.com/board/humor/list.html?table=muzik&pg=4 took longer than 30.0 seconds..
2017-10-12 00:03:38 [scrapy.core.scraper] ERROR: Error downloading <GET http://web.humoruniv.com/board/humor/list.html?table=pride&pg=4>
Traceback (most recent call last):
  File "c:\users\xkdlr\appdata\local\programs\python\python36-32\lib\site-packages\twisted\internet\defer.py", line 1384, in _inlineCallbacks
    result = result.throwExceptionIntoGenerator(g)
  File "c:\users\xkdlr\appdata\local\programs\python\python36-32\lib\site-packages\twisted\python\failure.py", line 408, in throwExceptionIntoGenerator
    return g.throw(self.type, self.value, self.tb)
  File "c:\users\xkdlr\appdata\local\programs\python\python36-32\lib\site-packages\scrapy\core\downloader\middleware.py", line 43, in process_request
    defer.returnValue((yield download_func(request=request,spider=spider)))
  File "c:\users\xkdlr\appdata\local\programs\python\python36-32\lib\site-packages\twisted\internet\defer.py", line 653, in _runCallbacks
    current.result = callback(current.result, *args, **kw)
  File "c:\users\xkdlr\appdata\local\programs\python\python36-32\lib\site-packages\scrapy\core\downloader\handlers\http11.py", line 320, in _cb_timeout
    raise TimeoutError("Getting %s took longer than %s seconds." % (url, timeout))
twisted.internet.error.TimeoutError: User timeout caused connection failure: Getting http://web.humoruniv.com/board/humor/list.html?table=pride&pg=4 took longer than 30.0 seconds..
2017-10-12 00:04:23 [scrapy.core.scraper] ERROR: Error downloading <GET http://web.humoruniv.com/board/humor/list.html?table=love&pg=4>
Traceback (most recent call last):
  File "c:\users\xkdlr\appdata\local\programs\python\python36-32\lib\site-packages\twisted\internet\defer.py", line 1384, in _inlineCallbacks
    result = result.throwExceptionIntoGenerator(g)
  File "c:\users\xkdlr\appdata\local\programs\python\python36-32\lib\site-packages\twisted\python\failure.py", line 408, in throwExceptionIntoGenerator
    return g.throw(self.type, self.value, self.tb)
  File "c:\users\xkdlr\appdata\local\programs\python\python36-32\lib\site-packages\scrapy\core\downloader\middleware.py", line 43, in process_request
    defer.returnValue((yield download_func(request=request,spider=spider)))
  File "c:\users\xkdlr\appdata\local\programs\python\python36-32\lib\site-packages\twisted\internet\defer.py", line 653, in _runCallbacks
    current.result = callback(current.result, *args, **kw)
  File "c:\users\xkdlr\appdata\local\programs\python\python36-32\lib\site-packages\scrapy\core\downloader\handlers\http11.py", line 320, in _cb_timeout
    raise TimeoutError("Getting %s took longer than %s seconds." % (url, timeout))
twisted.internet.error.TimeoutError: User timeout caused connection failure: Getting http://web.humoruniv.com/board/humor/list.html?table=love&pg=4 took longer than 30.0 seconds..
2017-10-12 00:04:51 [scrapy.core.scraper] ERROR: Error downloading <GET http://web.humoruniv.com/board/humor/list.html?table=spnatural&pg=4>
Traceback (most recent call last):
  File "c:\users\xkdlr\appdata\local\programs\python\python36-32\lib\site-packages\twisted\internet\defer.py", line 1384, in _inlineCallbacks
    result = result.throwExceptionIntoGenerator(g)
  File "c:\users\xkdlr\appdata\local\programs\python\python36-32\lib\site-packages\twisted\python\failure.py", line 408, in throwExceptionIntoGenerator
    return g.throw(self.type, self.value, self.tb)
  File "c:\users\xkdlr\appdata\local\programs\python\python36-32\lib\site-packages\scrapy\core\downloader\middleware.py", line 43, in process_request
    defer.returnValue((yield download_func(request=request,spider=spider)))
  File "c:\users\xkdlr\appdata\local\programs\python\python36-32\lib\site-packages\twisted\internet\defer.py", line 653, in _runCallbacks
    current.result = callback(current.result, *args, **kw)
  File "c:\users\xkdlr\appdata\local\programs\python\python36-32\lib\site-packages\scrapy\core\downloader\handlers\http11.py", line 320, in _cb_timeout
    raise TimeoutError("Getting %s took longer than %s seconds." % (url, timeout))
twisted.internet.error.TimeoutError: User timeout caused connection failure: Getting http://web.humoruniv.com/board/humor/list.html?table=spnatural&pg=4 took longer than 30.0 seconds..
2017-10-12 00:04:51 [scrapy.core.scraper] ERROR: Error downloading <GET http://web.humoruniv.com/board/humor/list.html?table=workshop&pg=4>
Traceback (most recent call last):
  File "c:\users\xkdlr\appdata\local\programs\python\python36-32\lib\site-packages\twisted\internet\defer.py", line 1384, in _inlineCallbacks
    result = result.throwExceptionIntoGenerator(g)
  File "c:\users\xkdlr\appdata\local\programs\python\python36-32\lib\site-packages\twisted\python\failure.py", line 408, in throwExceptionIntoGenerator
    return g.throw(self.type, self.value, self.tb)
  File "c:\users\xkdlr\appdata\local\programs\python\python36-32\lib\site-packages\scrapy\core\downloader\middleware.py", line 43, in process_request
    defer.returnValue((yield download_func(request=request,spider=spider)))
  File "c:\users\xkdlr\appdata\local\programs\python\python36-32\lib\site-packages\twisted\internet\defer.py", line 653, in _runCallbacks
    current.result = callback(current.result, *args, **kw)
  File "c:\users\xkdlr\appdata\local\programs\python\python36-32\lib\site-packages\scrapy\core\downloader\handlers\http11.py", line 320, in _cb_timeout
    raise TimeoutError("Getting %s took longer than %s seconds." % (url, timeout))
twisted.internet.error.TimeoutError: User timeout caused connection failure: Getting http://web.humoruniv.com/board/humor/list.html?table=workshop&pg=4 took longer than 30.0 seconds..
2017-10-12 00:04:59 [scrapy.core.scraper] ERROR: Error downloading <GET http://web.humoruniv.com/board/humor/list.html?table=solo&pg=4>
Traceback (most recent call last):
  File "c:\users\xkdlr\appdata\local\programs\python\python36-32\lib\site-packages\twisted\internet\defer.py", line 1384, in _inlineCallbacks
    result = result.throwExceptionIntoGenerator(g)
  File "c:\users\xkdlr\appdata\local\programs\python\python36-32\lib\site-packages\twisted\python\failure.py", line 408, in throwExceptionIntoGenerator
    return g.throw(self.type, self.value, self.tb)
  File "c:\users\xkdlr\appdata\local\programs\python\python36-32\lib\site-packages\scrapy\core\downloader\middleware.py", line 43, in process_request
    defer.returnValue((yield download_func(request=request,spider=spider)))
  File "c:\users\xkdlr\appdata\local\programs\python\python36-32\lib\site-packages\twisted\internet\defer.py", line 653, in _runCallbacks
    current.result = callback(current.result, *args, **kw)
  File "c:\users\xkdlr\appdata\local\programs\python\python36-32\lib\site-packages\scrapy\core\downloader\handlers\http11.py", line 320, in _cb_timeout
    raise TimeoutError("Getting %s took longer than %s seconds." % (url, timeout))
twisted.internet.error.TimeoutError: User timeout caused connection failure: Getting http://web.humoruniv.com/board/humor/list.html?table=solo&pg=4 took longer than 30.0 seconds..
2017-10-12 00:05:08 [scrapy.core.scraper] ERROR: Error downloading <GET http://web.humoruniv.com/board/humor/list.html?table=car&pg=4>: [<twisted.python.failure.Failure twisted.internet.error.ConnectionDone: Connection was closed cleanly.>]
