2017-10-11 14:17:04 [scrapy.core.scraper] ERROR: Spider error processing <GET http://web.humoruniv.com//board/humor/list.html?table=pdswait&pg=0> (referer: None)
Traceback (most recent call last):
  File "c:\users\xkdlr\appdata\local\programs\python\python36-32\lib\site-packages\scrapy\utils\defer.py", line 102, in iter_errback
    yield next(it)
  File "c:\users\xkdlr\appdata\local\programs\python\python36-32\lib\site-packages\scrapy\spidermiddlewares\offsite.py", line 29, in process_spider_output
    for x in result:
  File "c:\users\xkdlr\appdata\local\programs\python\python36-32\lib\site-packages\scrapy\spidermiddlewares\referer.py", line 339, in <genexpr>
    return (_set_referer(r) for r in result or ())
  File "c:\users\xkdlr\appdata\local\programs\python\python36-32\lib\site-packages\scrapy\spidermiddlewares\urllength.py", line 37, in <genexpr>
    return (r for r in result or () if _filter(r))
  File "c:\users\xkdlr\appdata\local\programs\python\python36-32\lib\site-packages\scrapy\spidermiddlewares\depth.py", line 58, in <genexpr>
    return (r for r in result or () if _filter(r))
  File "D:\CapstoneDesign\Damoa\Git_Crawler\DamoaCrawler\Crawler\spiders\HumorUniv.py", line 90, in parse_site
    item['attribute'] = createItemUseBs4(item['link'],tagName, tagAttr, encoding="CP949", texttype="")
  File "D:\CapstoneDesign\Damoa\Git_Crawler\DamoaCrawler\Crawler\CreateItem.py", line 33, in createItemUseBs4
    origin = JoinPostUrl.find(name=name, attrs=attr).text.strip()
AttributeError: 'NoneType' object has no attribute 'text'
2017-10-11 14:28:42 [scrapy.core.scraper] ERROR: Spider error processing <GET http://web.humoruniv.com/board/humor/list.html?table=thema2&pg=3> (referer: None)
Traceback (most recent call last):
  File "c:\users\xkdlr\appdata\local\programs\python\python36-32\lib\site-packages\urllib3\connection.py", line 141, in _new_conn
    (self.host, self.port), self.timeout, **extra_kw)
  File "c:\users\xkdlr\appdata\local\programs\python\python36-32\lib\site-packages\urllib3\util\connection.py", line 83, in create_connection
    raise err
  File "c:\users\xkdlr\appdata\local\programs\python\python36-32\lib\site-packages\urllib3\util\connection.py", line 73, in create_connection
    sock.connect(sa)
TimeoutError: [WinError 10060] 연결된 구성원으로부터 응답이 없어 연결하지 못했거나, 호스트로부터 응답이 없어 연결이 끊어졌습니다

During handling of the above exception, another exception occurred:

Traceback (most recent call last):
  File "c:\users\xkdlr\appdata\local\programs\python\python36-32\lib\site-packages\urllib3\connectionpool.py", line 601, in urlopen
    chunked=chunked)
  File "c:\users\xkdlr\appdata\local\programs\python\python36-32\lib\site-packages\urllib3\connectionpool.py", line 357, in _make_request
    conn.request(method, url, **httplib_request_kw)
  File "c:\users\xkdlr\appdata\local\programs\python\python36-32\lib\http\client.py", line 1239, in request
    self._send_request(method, url, body, headers, encode_chunked)
  File "c:\users\xkdlr\appdata\local\programs\python\python36-32\lib\http\client.py", line 1285, in _send_request
    self.endheaders(body, encode_chunked=encode_chunked)
  File "c:\users\xkdlr\appdata\local\programs\python\python36-32\lib\http\client.py", line 1234, in endheaders
    self._send_output(message_body, encode_chunked=encode_chunked)
  File "c:\users\xkdlr\appdata\local\programs\python\python36-32\lib\http\client.py", line 1026, in _send_output
    self.send(msg)
  File "c:\users\xkdlr\appdata\local\programs\python\python36-32\lib\http\client.py", line 964, in send
    self.connect()
  File "c:\users\xkdlr\appdata\local\programs\python\python36-32\lib\site-packages\urllib3\connection.py", line 166, in connect
    conn = self._new_conn()
  File "c:\users\xkdlr\appdata\local\programs\python\python36-32\lib\site-packages\urllib3\connection.py", line 150, in _new_conn
    self, "Failed to establish a new connection: %s" % e)
urllib3.exceptions.NewConnectionError: <urllib3.connection.HTTPConnection object at 0x0759D990>: Failed to establish a new connection: [WinError 10060] 연결된 구성원으로부터 응답이 없어 연결하지 못했거나, 호스트로부터 응답이 없어 연결이 끊어졌습니다

During handling of the above exception, another exception occurred:

Traceback (most recent call last):
  File "c:\users\xkdlr\appdata\local\programs\python\python36-32\lib\site-packages\requests\adapters.py", line 440, in send
    timeout=timeout
  File "c:\users\xkdlr\appdata\local\programs\python\python36-32\lib\site-packages\urllib3\connectionpool.py", line 639, in urlopen
    _stacktrace=sys.exc_info()[2])
  File "c:\users\xkdlr\appdata\local\programs\python\python36-32\lib\site-packages\urllib3\util\retry.py", line 388, in increment
    raise MaxRetryError(_pool, url, error or ResponseError(cause))
urllib3.exceptions.MaxRetryError: HTTPConnectionPool(host='web.humoruniv.com', port=80): Max retries exceeded with url: /board/humor/read.html?table=thema2&pg=3&number=768832 (Caused by NewConnectionError('<urllib3.connection.HTTPConnection object at 0x0759D990>: Failed to establish a new connection: [WinError 10060] 연결된 구성원으로부터 응답이 없어 연결하지 못했거나, 호스트로부터 응답이 없어 연결이 끊어졌습니다',))

During handling of the above exception, another exception occurred:

Traceback (most recent call last):
  File "c:\users\xkdlr\appdata\local\programs\python\python36-32\lib\site-packages\scrapy\utils\defer.py", line 102, in iter_errback
    yield next(it)
  File "c:\users\xkdlr\appdata\local\programs\python\python36-32\lib\site-packages\scrapy\spidermiddlewares\offsite.py", line 29, in process_spider_output
    for x in result:
  File "c:\users\xkdlr\appdata\local\programs\python\python36-32\lib\site-packages\scrapy\spidermiddlewares\referer.py", line 339, in <genexpr>
    return (_set_referer(r) for r in result or ())
  File "c:\users\xkdlr\appdata\local\programs\python\python36-32\lib\site-packages\scrapy\spidermiddlewares\urllength.py", line 37, in <genexpr>
    return (r for r in result or () if _filter(r))
  File "c:\users\xkdlr\appdata\local\programs\python\python36-32\lib\site-packages\scrapy\spidermiddlewares\depth.py", line 58, in <genexpr>
    return (r for r in result or () if _filter(r))
  File "D:\CapstoneDesign\Damoa\Git_Crawler\DamoaCrawler\Crawler\spiders\HumorUniv.py", line 118, in parse_site
    item['text'] = createItemUseBs4(item['link'], tagName, tagAttr, encoding="CP949", texttype="")
  File "D:\CapstoneDesign\Damoa\Git_Crawler\DamoaCrawler\Crawler\CreateItem.py", line 32, in createItemUseBs4
    JoinPostUrl = BeautifulSoup(requests.get(url).content, "html.parser", from_encoding=encoding)
  File "c:\users\xkdlr\appdata\local\programs\python\python36-32\lib\site-packages\requests\api.py", line 72, in get
    return request('get', url, params=params, **kwargs)
  File "c:\users\xkdlr\appdata\local\programs\python\python36-32\lib\site-packages\requests\api.py", line 58, in request
    return session.request(method=method, url=url, **kwargs)
  File "c:\users\xkdlr\appdata\local\programs\python\python36-32\lib\site-packages\requests\sessions.py", line 508, in request
    resp = self.send(prep, **send_kwargs)
  File "c:\users\xkdlr\appdata\local\programs\python\python36-32\lib\site-packages\requests\sessions.py", line 618, in send
    r = adapter.send(request, **kwargs)
  File "c:\users\xkdlr\appdata\local\programs\python\python36-32\lib\site-packages\requests\adapters.py", line 508, in send
    raise ConnectionError(e, request=request)
requests.exceptions.ConnectionError: HTTPConnectionPool(host='web.humoruniv.com', port=80): Max retries exceeded with url: /board/humor/read.html?table=thema2&pg=3&number=768832 (Caused by NewConnectionError('<urllib3.connection.HTTPConnection object at 0x0759D990>: Failed to establish a new connection: [WinError 10060] 연결된 구성원으로부터 응답이 없어 연결하지 못했거나, 호스트로부터 응답이 없어 연결이 끊어졌습니다',))
2017-10-11 14:31:15 [scrapy.core.scraper] ERROR: Error downloading <GET http://web.humoruniv.com//board/humor/list.html?table=nova_toon&pg=1>: [<twisted.python.failure.Failure twisted.internet.error.ConnectionDone: Connection was closed cleanly.>]
2017-10-11 14:31:15 [scrapy.core.scraper] ERROR: Error downloading <GET http://web.humoruniv.com/board/humor/list.html?table=guest&pg=1>: [<twisted.python.failure.Failure twisted.internet.error.ConnectionDone: Connection was closed cleanly.>]
2017-10-11 14:31:15 [scrapy.core.scraper] ERROR: Error downloading <GET http://web.humoruniv.com//board/humor/list.html?table=art_toon&pg=1>: [<twisted.python.failure.Failure twisted.internet.error.ConnectionDone: Connection was closed cleanly.>]
2017-10-11 14:31:15 [scrapy.core.scraper] ERROR: Error downloading <GET http://web.humoruniv.com/board/humor/list.html?table=mild&pg=1>: [<twisted.python.failure.Failure twisted.internet.error.ConnectionDone: Connection was closed cleanly.>]
2017-10-11 14:31:15 [scrapy.core.scraper] ERROR: Error downloading <GET http://web.humoruniv.com/board/humor/list.html?table=muzik&pg=1>: [<twisted.python.failure.Failure twisted.internet.error.ConnectionDone: Connection was closed cleanly.>]
2017-10-11 14:31:53 [scrapy.core.scraper] ERROR: Error downloading <GET http://web.humoruniv.com/board/humor/list.html?table=thema2&pg=1>: [<twisted.python.failure.Failure twisted.internet.error.ConnectionDone: Connection was closed cleanly.>]
2017-10-11 14:32:12 [scrapy.core.scraper] ERROR: Error downloading <GET http://web.humoruniv.com/board/humor/list.html?table=lol&pg=1>
Traceback (most recent call last):
  File "c:\users\xkdlr\appdata\local\programs\python\python36-32\lib\site-packages\twisted\internet\defer.py", line 1384, in _inlineCallbacks
    result = result.throwExceptionIntoGenerator(g)
  File "c:\users\xkdlr\appdata\local\programs\python\python36-32\lib\site-packages\twisted\python\failure.py", line 408, in throwExceptionIntoGenerator
    return g.throw(self.type, self.value, self.tb)
  File "c:\users\xkdlr\appdata\local\programs\python\python36-32\lib\site-packages\scrapy\core\downloader\middleware.py", line 43, in process_request
    defer.returnValue((yield download_func(request=request,spider=spider)))
  File "c:\users\xkdlr\appdata\local\programs\python\python36-32\lib\site-packages\twisted\internet\defer.py", line 653, in _runCallbacks
    current.result = callback(current.result, *args, **kw)
  File "c:\users\xkdlr\appdata\local\programs\python\python36-32\lib\site-packages\scrapy\core\downloader\handlers\http11.py", line 320, in _cb_timeout
    raise TimeoutError("Getting %s took longer than %s seconds." % (url, timeout))
twisted.internet.error.TimeoutError: User timeout caused connection failure: Getting http://web.humoruniv.com/board/humor/list.html?table=lol&pg=1 took longer than 30.0 seconds..
2017-10-11 14:32:33 [scrapy.core.scraper] ERROR: Error downloading <GET http://web.humoruniv.com/board/humor/list.html?table=solo&pg=1>
Traceback (most recent call last):
  File "c:\users\xkdlr\appdata\local\programs\python\python36-32\lib\site-packages\twisted\internet\defer.py", line 1384, in _inlineCallbacks
    result = result.throwExceptionIntoGenerator(g)
  File "c:\users\xkdlr\appdata\local\programs\python\python36-32\lib\site-packages\twisted\python\failure.py", line 408, in throwExceptionIntoGenerator
    return g.throw(self.type, self.value, self.tb)
  File "c:\users\xkdlr\appdata\local\programs\python\python36-32\lib\site-packages\scrapy\core\downloader\middleware.py", line 43, in process_request
    defer.returnValue((yield download_func(request=request,spider=spider)))
  File "c:\users\xkdlr\appdata\local\programs\python\python36-32\lib\site-packages\twisted\internet\defer.py", line 653, in _runCallbacks
    current.result = callback(current.result, *args, **kw)
  File "c:\users\xkdlr\appdata\local\programs\python\python36-32\lib\site-packages\scrapy\core\downloader\handlers\http11.py", line 320, in _cb_timeout
    raise TimeoutError("Getting %s took longer than %s seconds." % (url, timeout))
twisted.internet.error.TimeoutError: User timeout caused connection failure: Getting http://web.humoruniv.com/board/humor/list.html?table=solo&pg=1 took longer than 30.0 seconds..
2017-10-11 14:32:33 [scrapy.core.scraper] ERROR: Error downloading <GET http://web.humoruniv.com/board/humor/list.html?table=car&pg=1>
Traceback (most recent call last):
  File "c:\users\xkdlr\appdata\local\programs\python\python36-32\lib\site-packages\twisted\internet\defer.py", line 1384, in _inlineCallbacks
    result = result.throwExceptionIntoGenerator(g)
  File "c:\users\xkdlr\appdata\local\programs\python\python36-32\lib\site-packages\twisted\python\failure.py", line 408, in throwExceptionIntoGenerator
    return g.throw(self.type, self.value, self.tb)
  File "c:\users\xkdlr\appdata\local\programs\python\python36-32\lib\site-packages\scrapy\core\downloader\middleware.py", line 43, in process_request
    defer.returnValue((yield download_func(request=request,spider=spider)))
  File "c:\users\xkdlr\appdata\local\programs\python\python36-32\lib\site-packages\twisted\internet\defer.py", line 653, in _runCallbacks
    current.result = callback(current.result, *args, **kw)
  File "c:\users\xkdlr\appdata\local\programs\python\python36-32\lib\site-packages\scrapy\core\downloader\handlers\http11.py", line 320, in _cb_timeout
    raise TimeoutError("Getting %s took longer than %s seconds." % (url, timeout))
twisted.internet.error.TimeoutError: User timeout caused connection failure: Getting http://web.humoruniv.com/board/humor/list.html?table=car&pg=1 took longer than 30.0 seconds..
2017-10-11 14:32:50 [scrapy.core.scraper] ERROR: Error downloading <GET http://web.humoruniv.com/board/humor/list.html?table=workshop&pg=1>
Traceback (most recent call last):
  File "c:\users\xkdlr\appdata\local\programs\python\python36-32\lib\site-packages\twisted\internet\defer.py", line 1384, in _inlineCallbacks
    result = result.throwExceptionIntoGenerator(g)
  File "c:\users\xkdlr\appdata\local\programs\python\python36-32\lib\site-packages\twisted\python\failure.py", line 408, in throwExceptionIntoGenerator
    return g.throw(self.type, self.value, self.tb)
  File "c:\users\xkdlr\appdata\local\programs\python\python36-32\lib\site-packages\scrapy\core\downloader\middleware.py", line 43, in process_request
    defer.returnValue((yield download_func(request=request,spider=spider)))
  File "c:\users\xkdlr\appdata\local\programs\python\python36-32\lib\site-packages\twisted\internet\defer.py", line 653, in _runCallbacks
    current.result = callback(current.result, *args, **kw)
  File "c:\users\xkdlr\appdata\local\programs\python\python36-32\lib\site-packages\scrapy\core\downloader\handlers\http11.py", line 320, in _cb_timeout
    raise TimeoutError("Getting %s took longer than %s seconds." % (url, timeout))
twisted.internet.error.TimeoutError: User timeout caused connection failure: Getting http://web.humoruniv.com/board/humor/list.html?table=workshop&pg=1 took longer than 30.0 seconds..
2017-10-11 14:34:19 [scrapy.core.scraper] ERROR: Error downloading <GET http://web.humoruniv.com/board/humor/list.html?table=pride&pg=2>
Traceback (most recent call last):
  File "c:\users\xkdlr\appdata\local\programs\python\python36-32\lib\site-packages\twisted\internet\defer.py", line 1384, in _inlineCallbacks
    result = result.throwExceptionIntoGenerator(g)
  File "c:\users\xkdlr\appdata\local\programs\python\python36-32\lib\site-packages\twisted\python\failure.py", line 408, in throwExceptionIntoGenerator
    return g.throw(self.type, self.value, self.tb)
  File "c:\users\xkdlr\appdata\local\programs\python\python36-32\lib\site-packages\scrapy\core\downloader\middleware.py", line 43, in process_request
    defer.returnValue((yield download_func(request=request,spider=spider)))
  File "c:\users\xkdlr\appdata\local\programs\python\python36-32\lib\site-packages\twisted\internet\defer.py", line 653, in _runCallbacks
    current.result = callback(current.result, *args, **kw)
  File "c:\users\xkdlr\appdata\local\programs\python\python36-32\lib\site-packages\scrapy\core\downloader\handlers\http11.py", line 320, in _cb_timeout
    raise TimeoutError("Getting %s took longer than %s seconds." % (url, timeout))
twisted.internet.error.TimeoutError: User timeout caused connection failure: Getting http://web.humoruniv.com/board/humor/list.html?table=pride&pg=2 took longer than 30.0 seconds..
2017-10-11 14:34:20 [scrapy.core.scraper] ERROR: Error downloading <GET http://web.humoruniv.com/board/humor/list.html?table=animaluniv&pg=2>: [<twisted.python.failure.Failure twisted.internet.error.ConnectionDone: Connection was closed cleanly.>]
2017-10-11 14:34:27 [scrapy.core.scraper] ERROR: Error downloading <GET http://web.humoruniv.com/board/humor/list.html?table=free&pg=2>
Traceback (most recent call last):
  File "c:\users\xkdlr\appdata\local\programs\python\python36-32\lib\site-packages\twisted\internet\defer.py", line 1384, in _inlineCallbacks
    result = result.throwExceptionIntoGenerator(g)
  File "c:\users\xkdlr\appdata\local\programs\python\python36-32\lib\site-packages\twisted\python\failure.py", line 408, in throwExceptionIntoGenerator
    return g.throw(self.type, self.value, self.tb)
  File "c:\users\xkdlr\appdata\local\programs\python\python36-32\lib\site-packages\scrapy\core\downloader\middleware.py", line 43, in process_request
    defer.returnValue((yield download_func(request=request,spider=spider)))
  File "c:\users\xkdlr\appdata\local\programs\python\python36-32\lib\site-packages\twisted\internet\defer.py", line 653, in _runCallbacks
    current.result = callback(current.result, *args, **kw)
  File "c:\users\xkdlr\appdata\local\programs\python\python36-32\lib\site-packages\scrapy\core\downloader\handlers\http11.py", line 320, in _cb_timeout
    raise TimeoutError("Getting %s took longer than %s seconds." % (url, timeout))
twisted.internet.error.TimeoutError: User timeout caused connection failure: Getting http://web.humoruniv.com/board/humor/list.html?table=free&pg=2 took longer than 30.0 seconds..
2017-10-11 14:34:27 [scrapy.core.scraper] ERROR: Error downloading <GET http://web.humoruniv.com/board/humor/list.html?table=lol&pg=2>
Traceback (most recent call last):
  File "c:\users\xkdlr\appdata\local\programs\python\python36-32\lib\site-packages\twisted\internet\defer.py", line 1384, in _inlineCallbacks
    result = result.throwExceptionIntoGenerator(g)
  File "c:\users\xkdlr\appdata\local\programs\python\python36-32\lib\site-packages\twisted\python\failure.py", line 408, in throwExceptionIntoGenerator
    return g.throw(self.type, self.value, self.tb)
  File "c:\users\xkdlr\appdata\local\programs\python\python36-32\lib\site-packages\scrapy\core\downloader\middleware.py", line 43, in process_request
    defer.returnValue((yield download_func(request=request,spider=spider)))
  File "c:\users\xkdlr\appdata\local\programs\python\python36-32\lib\site-packages\twisted\internet\defer.py", line 653, in _runCallbacks
    current.result = callback(current.result, *args, **kw)
  File "c:\users\xkdlr\appdata\local\programs\python\python36-32\lib\site-packages\scrapy\core\downloader\handlers\http11.py", line 320, in _cb_timeout
    raise TimeoutError("Getting %s took longer than %s seconds." % (url, timeout))
twisted.internet.error.TimeoutError: User timeout caused connection failure: Getting http://web.humoruniv.com/board/humor/list.html?table=lol&pg=2 took longer than 30.0 seconds..
2017-10-11 14:34:27 [scrapy.core.scraper] ERROR: Error downloading <GET http://web.humoruniv.com/board/humor/list.html?table=poll&pg=2>
Traceback (most recent call last):
  File "c:\users\xkdlr\appdata\local\programs\python\python36-32\lib\site-packages\twisted\internet\defer.py", line 1384, in _inlineCallbacks
    result = result.throwExceptionIntoGenerator(g)
  File "c:\users\xkdlr\appdata\local\programs\python\python36-32\lib\site-packages\twisted\python\failure.py", line 408, in throwExceptionIntoGenerator
    return g.throw(self.type, self.value, self.tb)
  File "c:\users\xkdlr\appdata\local\programs\python\python36-32\lib\site-packages\scrapy\core\downloader\middleware.py", line 43, in process_request
    defer.returnValue((yield download_func(request=request,spider=spider)))
  File "c:\users\xkdlr\appdata\local\programs\python\python36-32\lib\site-packages\twisted\internet\defer.py", line 653, in _runCallbacks
    current.result = callback(current.result, *args, **kw)
  File "c:\users\xkdlr\appdata\local\programs\python\python36-32\lib\site-packages\scrapy\core\downloader\handlers\http11.py", line 320, in _cb_timeout
    raise TimeoutError("Getting %s took longer than %s seconds." % (url, timeout))
twisted.internet.error.TimeoutError: User timeout caused connection failure: Getting http://web.humoruniv.com/board/humor/list.html?table=poll&pg=2 took longer than 30.0 seconds..
2017-10-11 14:34:33 [scrapy.core.scraper] ERROR: Error downloading <GET http://web.humoruniv.com/board/humor/list.html?table=workshop&pg=2>
Traceback (most recent call last):
  File "c:\users\xkdlr\appdata\local\programs\python\python36-32\lib\site-packages\twisted\internet\defer.py", line 1384, in _inlineCallbacks
    result = result.throwExceptionIntoGenerator(g)
  File "c:\users\xkdlr\appdata\local\programs\python\python36-32\lib\site-packages\twisted\python\failure.py", line 408, in throwExceptionIntoGenerator
    return g.throw(self.type, self.value, self.tb)
  File "c:\users\xkdlr\appdata\local\programs\python\python36-32\lib\site-packages\scrapy\core\downloader\middleware.py", line 43, in process_request
    defer.returnValue((yield download_func(request=request,spider=spider)))
  File "c:\users\xkdlr\appdata\local\programs\python\python36-32\lib\site-packages\twisted\internet\defer.py", line 653, in _runCallbacks
    current.result = callback(current.result, *args, **kw)
  File "c:\users\xkdlr\appdata\local\programs\python\python36-32\lib\site-packages\scrapy\core\downloader\handlers\http11.py", line 320, in _cb_timeout
    raise TimeoutError("Getting %s took longer than %s seconds." % (url, timeout))
twisted.internet.error.TimeoutError: User timeout caused connection failure: Getting http://web.humoruniv.com/board/humor/list.html?table=workshop&pg=2 took longer than 30.0 seconds..
2017-10-11 14:34:33 [scrapy.core.scraper] ERROR: Error downloading <GET http://web.humoruniv.com/board/humor/list.html?table=moofama&pg=2>
Traceback (most recent call last):
  File "c:\users\xkdlr\appdata\local\programs\python\python36-32\lib\site-packages\twisted\internet\defer.py", line 1384, in _inlineCallbacks
    result = result.throwExceptionIntoGenerator(g)
  File "c:\users\xkdlr\appdata\local\programs\python\python36-32\lib\site-packages\twisted\python\failure.py", line 408, in throwExceptionIntoGenerator
    return g.throw(self.type, self.value, self.tb)
  File "c:\users\xkdlr\appdata\local\programs\python\python36-32\lib\site-packages\scrapy\core\downloader\middleware.py", line 43, in process_request
    defer.returnValue((yield download_func(request=request,spider=spider)))
  File "c:\users\xkdlr\appdata\local\programs\python\python36-32\lib\site-packages\twisted\internet\defer.py", line 653, in _runCallbacks
    current.result = callback(current.result, *args, **kw)
  File "c:\users\xkdlr\appdata\local\programs\python\python36-32\lib\site-packages\scrapy\core\downloader\handlers\http11.py", line 320, in _cb_timeout
    raise TimeoutError("Getting %s took longer than %s seconds." % (url, timeout))
twisted.internet.error.TimeoutError: User timeout caused connection failure: Getting http://web.humoruniv.com/board/humor/list.html?table=moofama&pg=2 took longer than 30.0 seconds..
2017-10-11 14:34:43 [scrapy.core.scraper] ERROR: Error downloading <GET http://web.humoruniv.com/board/humor/list.html?table=thema3&pg=2>
Traceback (most recent call last):
  File "c:\users\xkdlr\appdata\local\programs\python\python36-32\lib\site-packages\twisted\internet\defer.py", line 1384, in _inlineCallbacks
    result = result.throwExceptionIntoGenerator(g)
  File "c:\users\xkdlr\appdata\local\programs\python\python36-32\lib\site-packages\twisted\python\failure.py", line 408, in throwExceptionIntoGenerator
    return g.throw(self.type, self.value, self.tb)
  File "c:\users\xkdlr\appdata\local\programs\python\python36-32\lib\site-packages\scrapy\core\downloader\middleware.py", line 43, in process_request
    defer.returnValue((yield download_func(request=request,spider=spider)))
  File "c:\users\xkdlr\appdata\local\programs\python\python36-32\lib\site-packages\twisted\internet\defer.py", line 653, in _runCallbacks
    current.result = callback(current.result, *args, **kw)
  File "c:\users\xkdlr\appdata\local\programs\python\python36-32\lib\site-packages\scrapy\core\downloader\handlers\http11.py", line 320, in _cb_timeout
    raise TimeoutError("Getting %s took longer than %s seconds." % (url, timeout))
twisted.internet.error.TimeoutError: User timeout caused connection failure: Getting http://web.humoruniv.com/board/humor/list.html?table=thema3&pg=2 took longer than 30.0 seconds..
2017-10-11 14:35:11 [scrapy.core.scraper] ERROR: Error downloading <GET http://web.humoruniv.com/board/humor/list.html?table=muzik&pg=2>
Traceback (most recent call last):
  File "c:\users\xkdlr\appdata\local\programs\python\python36-32\lib\site-packages\twisted\internet\defer.py", line 1384, in _inlineCallbacks
    result = result.throwExceptionIntoGenerator(g)
  File "c:\users\xkdlr\appdata\local\programs\python\python36-32\lib\site-packages\twisted\python\failure.py", line 408, in throwExceptionIntoGenerator
    return g.throw(self.type, self.value, self.tb)
  File "c:\users\xkdlr\appdata\local\programs\python\python36-32\lib\site-packages\scrapy\core\downloader\middleware.py", line 43, in process_request
    defer.returnValue((yield download_func(request=request,spider=spider)))
  File "c:\users\xkdlr\appdata\local\programs\python\python36-32\lib\site-packages\twisted\internet\defer.py", line 653, in _runCallbacks
    current.result = callback(current.result, *args, **kw)
  File "c:\users\xkdlr\appdata\local\programs\python\python36-32\lib\site-packages\scrapy\core\downloader\handlers\http11.py", line 320, in _cb_timeout
    raise TimeoutError("Getting %s took longer than %s seconds." % (url, timeout))
twisted.internet.error.TimeoutError: User timeout caused connection failure: Getting http://web.humoruniv.com/board/humor/list.html?table=muzik&pg=2 took longer than 30.0 seconds..
2017-10-11 14:35:14 [scrapy.core.scraper] ERROR: Error downloading <GET http://web.humoruniv.com/board/humor/list.html?table=com&pg=2>
Traceback (most recent call last):
  File "c:\users\xkdlr\appdata\local\programs\python\python36-32\lib\site-packages\twisted\internet\defer.py", line 1384, in _inlineCallbacks
    result = result.throwExceptionIntoGenerator(g)
  File "c:\users\xkdlr\appdata\local\programs\python\python36-32\lib\site-packages\twisted\python\failure.py", line 408, in throwExceptionIntoGenerator
    return g.throw(self.type, self.value, self.tb)
  File "c:\users\xkdlr\appdata\local\programs\python\python36-32\lib\site-packages\scrapy\core\downloader\middleware.py", line 43, in process_request
    defer.returnValue((yield download_func(request=request,spider=spider)))
  File "c:\users\xkdlr\appdata\local\programs\python\python36-32\lib\site-packages\twisted\internet\defer.py", line 653, in _runCallbacks
    current.result = callback(current.result, *args, **kw)
  File "c:\users\xkdlr\appdata\local\programs\python\python36-32\lib\site-packages\scrapy\core\downloader\handlers\http11.py", line 320, in _cb_timeout
    raise TimeoutError("Getting %s took longer than %s seconds." % (url, timeout))
twisted.internet.error.TimeoutError: User timeout caused connection failure: Getting http://web.humoruniv.com/board/humor/list.html?table=com&pg=2 took longer than 30.0 seconds..
2017-10-11 14:35:14 [scrapy.core.scraper] ERROR: Error downloading <GET http://web.humoruniv.com/board/humor/list.html?table=whitehand&pg=2>
Traceback (most recent call last):
  File "c:\users\xkdlr\appdata\local\programs\python\python36-32\lib\site-packages\twisted\internet\defer.py", line 1384, in _inlineCallbacks
    result = result.throwExceptionIntoGenerator(g)
  File "c:\users\xkdlr\appdata\local\programs\python\python36-32\lib\site-packages\twisted\python\failure.py", line 408, in throwExceptionIntoGenerator
    return g.throw(self.type, self.value, self.tb)
  File "c:\users\xkdlr\appdata\local\programs\python\python36-32\lib\site-packages\scrapy\core\downloader\middleware.py", line 43, in process_request
    defer.returnValue((yield download_func(request=request,spider=spider)))
  File "c:\users\xkdlr\appdata\local\programs\python\python36-32\lib\site-packages\twisted\internet\defer.py", line 653, in _runCallbacks
    current.result = callback(current.result, *args, **kw)
  File "c:\users\xkdlr\appdata\local\programs\python\python36-32\lib\site-packages\scrapy\core\downloader\handlers\http11.py", line 320, in _cb_timeout
    raise TimeoutError("Getting %s took longer than %s seconds." % (url, timeout))
twisted.internet.error.TimeoutError: User timeout caused connection failure: Getting http://web.humoruniv.com/board/humor/list.html?table=whitehand&pg=2 took longer than 30.0 seconds..
2017-10-11 14:35:14 [scrapy.core.scraper] ERROR: Error downloading <GET http://web.humoruniv.com//board/humor/list.html?table=kin&pg=3>
Traceback (most recent call last):
  File "c:\users\xkdlr\appdata\local\programs\python\python36-32\lib\site-packages\twisted\internet\defer.py", line 1384, in _inlineCallbacks
    result = result.throwExceptionIntoGenerator(g)
  File "c:\users\xkdlr\appdata\local\programs\python\python36-32\lib\site-packages\twisted\python\failure.py", line 408, in throwExceptionIntoGenerator
    return g.throw(self.type, self.value, self.tb)
  File "c:\users\xkdlr\appdata\local\programs\python\python36-32\lib\site-packages\scrapy\core\downloader\middleware.py", line 43, in process_request
    defer.returnValue((yield download_func(request=request,spider=spider)))
  File "c:\users\xkdlr\appdata\local\programs\python\python36-32\lib\site-packages\twisted\internet\defer.py", line 653, in _runCallbacks
    current.result = callback(current.result, *args, **kw)
  File "c:\users\xkdlr\appdata\local\programs\python\python36-32\lib\site-packages\scrapy\core\downloader\handlers\http11.py", line 320, in _cb_timeout
    raise TimeoutError("Getting %s took longer than %s seconds." % (url, timeout))
twisted.internet.error.TimeoutError: User timeout caused connection failure: Getting http://web.humoruniv.com//board/humor/list.html?table=kin&pg=3 took longer than 30.0 seconds..
2017-10-11 14:35:17 [scrapy.core.scraper] ERROR: Error downloading <GET http://web.humoruniv.com/board/humor/list.html?table=sns&pg=2>
Traceback (most recent call last):
  File "c:\users\xkdlr\appdata\local\programs\python\python36-32\lib\site-packages\twisted\internet\defer.py", line 1384, in _inlineCallbacks
    result = result.throwExceptionIntoGenerator(g)
  File "c:\users\xkdlr\appdata\local\programs\python\python36-32\lib\site-packages\twisted\python\failure.py", line 408, in throwExceptionIntoGenerator
    return g.throw(self.type, self.value, self.tb)
  File "c:\users\xkdlr\appdata\local\programs\python\python36-32\lib\site-packages\scrapy\core\downloader\middleware.py", line 43, in process_request
    defer.returnValue((yield download_func(request=request,spider=spider)))
  File "c:\users\xkdlr\appdata\local\programs\python\python36-32\lib\site-packages\twisted\internet\defer.py", line 653, in _runCallbacks
    current.result = callback(current.result, *args, **kw)
  File "c:\users\xkdlr\appdata\local\programs\python\python36-32\lib\site-packages\scrapy\core\downloader\handlers\http11.py", line 320, in _cb_timeout
    raise TimeoutError("Getting %s took longer than %s seconds." % (url, timeout))
twisted.internet.error.TimeoutError: User timeout caused connection failure: Getting http://web.humoruniv.com/board/humor/list.html?table=sns&pg=2 took longer than 30.0 seconds..
2017-10-11 14:35:17 [scrapy.core.scraper] ERROR: Error downloading <GET http://web.humoruniv.com/board/humor/list.html?table=love&pg=2>
Traceback (most recent call last):
  File "c:\users\xkdlr\appdata\local\programs\python\python36-32\lib\site-packages\twisted\internet\defer.py", line 1384, in _inlineCallbacks
    result = result.throwExceptionIntoGenerator(g)
  File "c:\users\xkdlr\appdata\local\programs\python\python36-32\lib\site-packages\twisted\python\failure.py", line 408, in throwExceptionIntoGenerator
    return g.throw(self.type, self.value, self.tb)
  File "c:\users\xkdlr\appdata\local\programs\python\python36-32\lib\site-packages\scrapy\core\downloader\middleware.py", line 43, in process_request
    defer.returnValue((yield download_func(request=request,spider=spider)))
  File "c:\users\xkdlr\appdata\local\programs\python\python36-32\lib\site-packages\twisted\internet\defer.py", line 653, in _runCallbacks
    current.result = callback(current.result, *args, **kw)
  File "c:\users\xkdlr\appdata\local\programs\python\python36-32\lib\site-packages\scrapy\core\downloader\handlers\http11.py", line 320, in _cb_timeout
    raise TimeoutError("Getting %s took longer than %s seconds." % (url, timeout))
twisted.internet.error.TimeoutError: User timeout caused connection failure: Getting http://web.humoruniv.com/board/humor/list.html?table=love&pg=2 took longer than 30.0 seconds..
2017-10-11 14:35:26 [scrapy.core.scraper] ERROR: Error downloading <GET http://web.humoruniv.com/board/humor/list.html?table=dump&pg=2>
Traceback (most recent call last):
  File "c:\users\xkdlr\appdata\local\programs\python\python36-32\lib\site-packages\twisted\internet\defer.py", line 1384, in _inlineCallbacks
    result = result.throwExceptionIntoGenerator(g)
  File "c:\users\xkdlr\appdata\local\programs\python\python36-32\lib\site-packages\twisted\python\failure.py", line 408, in throwExceptionIntoGenerator
    return g.throw(self.type, self.value, self.tb)
  File "c:\users\xkdlr\appdata\local\programs\python\python36-32\lib\site-packages\scrapy\core\downloader\middleware.py", line 43, in process_request
    defer.returnValue((yield download_func(request=request,spider=spider)))
  File "c:\users\xkdlr\appdata\local\programs\python\python36-32\lib\site-packages\twisted\internet\defer.py", line 653, in _runCallbacks
    current.result = callback(current.result, *args, **kw)
  File "c:\users\xkdlr\appdata\local\programs\python\python36-32\lib\site-packages\scrapy\core\downloader\handlers\http11.py", line 320, in _cb_timeout
    raise TimeoutError("Getting %s took longer than %s seconds." % (url, timeout))
twisted.internet.error.TimeoutError: User timeout caused connection failure: Getting http://web.humoruniv.com/board/humor/list.html?table=dump&pg=2 took longer than 30.0 seconds..
2017-10-11 14:35:47 [scrapy.core.scraper] ERROR: Error downloading <GET http://web.humoruniv.com/board/humor/list.html?table=worldcup&pg=2>: [<twisted.python.failure.Failure twisted.internet.error.ConnectionDone: Connection was closed cleanly.>]
2017-10-11 14:35:47 [scrapy.core.scraper] ERROR: Error downloading <GET http://web.humoruniv.com/board/humor/list.html?table=car&pg=2>
Traceback (most recent call last):
  File "c:\users\xkdlr\appdata\local\programs\python\python36-32\lib\site-packages\twisted\internet\defer.py", line 1384, in _inlineCallbacks
    result = result.throwExceptionIntoGenerator(g)
  File "c:\users\xkdlr\appdata\local\programs\python\python36-32\lib\site-packages\twisted\python\failure.py", line 408, in throwExceptionIntoGenerator
    return g.throw(self.type, self.value, self.tb)
  File "c:\users\xkdlr\appdata\local\programs\python\python36-32\lib\site-packages\scrapy\core\downloader\middleware.py", line 43, in process_request
    defer.returnValue((yield download_func(request=request,spider=spider)))
  File "c:\users\xkdlr\appdata\local\programs\python\python36-32\lib\site-packages\twisted\internet\defer.py", line 653, in _runCallbacks
    current.result = callback(current.result, *args, **kw)
  File "c:\users\xkdlr\appdata\local\programs\python\python36-32\lib\site-packages\scrapy\core\downloader\handlers\http11.py", line 320, in _cb_timeout
    raise TimeoutError("Getting %s took longer than %s seconds." % (url, timeout))
twisted.internet.error.TimeoutError: User timeout caused connection failure: Getting http://web.humoruniv.com/board/humor/list.html?table=car&pg=2 took longer than 30.0 seconds..
2017-10-11 14:35:54 [scrapy.core.scraper] ERROR: Error downloading <GET http://web.humoruniv.com/board/humor/list.html?table=studying&pg=2>
Traceback (most recent call last):
  File "c:\users\xkdlr\appdata\local\programs\python\python36-32\lib\site-packages\twisted\internet\defer.py", line 1384, in _inlineCallbacks
    result = result.throwExceptionIntoGenerator(g)
  File "c:\users\xkdlr\appdata\local\programs\python\python36-32\lib\site-packages\twisted\python\failure.py", line 408, in throwExceptionIntoGenerator
    return g.throw(self.type, self.value, self.tb)
  File "c:\users\xkdlr\appdata\local\programs\python\python36-32\lib\site-packages\scrapy\core\downloader\middleware.py", line 43, in process_request
    defer.returnValue((yield download_func(request=request,spider=spider)))
  File "c:\users\xkdlr\appdata\local\programs\python\python36-32\lib\site-packages\twisted\internet\defer.py", line 653, in _runCallbacks
    current.result = callback(current.result, *args, **kw)
  File "c:\users\xkdlr\appdata\local\programs\python\python36-32\lib\site-packages\scrapy\core\downloader\handlers\http11.py", line 320, in _cb_timeout
    raise TimeoutError("Getting %s took longer than %s seconds." % (url, timeout))
twisted.internet.error.TimeoutError: User timeout caused connection failure: Getting http://web.humoruniv.com/board/humor/list.html?table=studying&pg=2 took longer than 30.0 seconds..
2017-10-11 14:35:57 [scrapy.core.scraper] ERROR: Error downloading <GET http://web.humoruniv.com/board/humor/list.html?table=spnatural&pg=2>
Traceback (most recent call last):
  File "c:\users\xkdlr\appdata\local\programs\python\python36-32\lib\site-packages\twisted\internet\defer.py", line 1384, in _inlineCallbacks
    result = result.throwExceptionIntoGenerator(g)
  File "c:\users\xkdlr\appdata\local\programs\python\python36-32\lib\site-packages\twisted\python\failure.py", line 408, in throwExceptionIntoGenerator
    return g.throw(self.type, self.value, self.tb)
  File "c:\users\xkdlr\appdata\local\programs\python\python36-32\lib\site-packages\scrapy\core\downloader\middleware.py", line 43, in process_request
    defer.returnValue((yield download_func(request=request,spider=spider)))
  File "c:\users\xkdlr\appdata\local\programs\python\python36-32\lib\site-packages\twisted\internet\defer.py", line 653, in _runCallbacks
    current.result = callback(current.result, *args, **kw)
  File "c:\users\xkdlr\appdata\local\programs\python\python36-32\lib\site-packages\scrapy\core\downloader\handlers\http11.py", line 320, in _cb_timeout
    raise TimeoutError("Getting %s took longer than %s seconds." % (url, timeout))
twisted.internet.error.TimeoutError: User timeout caused connection failure: Getting http://web.humoruniv.com/board/humor/list.html?table=spnatural&pg=2 took longer than 30.0 seconds..
2017-10-11 14:35:57 [scrapy.core.scraper] ERROR: Error downloading <GET http://web.humoruniv.com/board/humor/list.html?table=memory&pg=2>
Traceback (most recent call last):
  File "c:\users\xkdlr\appdata\local\programs\python\python36-32\lib\site-packages\twisted\internet\defer.py", line 1384, in _inlineCallbacks
    result = result.throwExceptionIntoGenerator(g)
  File "c:\users\xkdlr\appdata\local\programs\python\python36-32\lib\site-packages\twisted\python\failure.py", line 408, in throwExceptionIntoGenerator
    return g.throw(self.type, self.value, self.tb)
  File "c:\users\xkdlr\appdata\local\programs\python\python36-32\lib\site-packages\scrapy\core\downloader\middleware.py", line 43, in process_request
    defer.returnValue((yield download_func(request=request,spider=spider)))
  File "c:\users\xkdlr\appdata\local\programs\python\python36-32\lib\site-packages\twisted\internet\defer.py", line 653, in _runCallbacks
    current.result = callback(current.result, *args, **kw)
  File "c:\users\xkdlr\appdata\local\programs\python\python36-32\lib\site-packages\scrapy\core\downloader\handlers\http11.py", line 320, in _cb_timeout
    raise TimeoutError("Getting %s took longer than %s seconds." % (url, timeout))
twisted.internet.error.TimeoutError: User timeout caused connection failure: Getting http://web.humoruniv.com/board/humor/list.html?table=memory&pg=2 took longer than 30.0 seconds..
2017-10-11 14:36:01 [scrapy.core.scraper] ERROR: Error downloading <GET http://web.humoruniv.com/board/humor/list.html?table=cabinet&pg=2>: [<twisted.python.failure.Failure twisted.internet.error.ConnectionDone: Connection was closed cleanly.>]
2017-10-11 14:36:05 [scrapy.core.scraper] ERROR: Error downloading <GET http://web.humoruniv.com/board/humor/list.html?table=phone&pg=2>
Traceback (most recent call last):
  File "c:\users\xkdlr\appdata\local\programs\python\python36-32\lib\site-packages\twisted\internet\defer.py", line 1384, in _inlineCallbacks
    result = result.throwExceptionIntoGenerator(g)
  File "c:\users\xkdlr\appdata\local\programs\python\python36-32\lib\site-packages\twisted\python\failure.py", line 408, in throwExceptionIntoGenerator
    return g.throw(self.type, self.value, self.tb)
  File "c:\users\xkdlr\appdata\local\programs\python\python36-32\lib\site-packages\scrapy\core\downloader\middleware.py", line 43, in process_request
    defer.returnValue((yield download_func(request=request,spider=spider)))
  File "c:\users\xkdlr\appdata\local\programs\python\python36-32\lib\site-packages\twisted\internet\defer.py", line 653, in _runCallbacks
    current.result = callback(current.result, *args, **kw)
  File "c:\users\xkdlr\appdata\local\programs\python\python36-32\lib\site-packages\scrapy\core\downloader\handlers\http11.py", line 320, in _cb_timeout
    raise TimeoutError("Getting %s took longer than %s seconds." % (url, timeout))
twisted.internet.error.TimeoutError: User timeout caused connection failure: Getting http://web.humoruniv.com/board/humor/list.html?table=phone&pg=2 took longer than 30.0 seconds..
2017-10-11 14:36:05 [scrapy.core.scraper] ERROR: Error downloading <GET http://web.humoruniv.com//board/humor/list.html?table=pdswait&pg=3>
Traceback (most recent call last):
  File "c:\users\xkdlr\appdata\local\programs\python\python36-32\lib\site-packages\twisted\internet\defer.py", line 1384, in _inlineCallbacks
    result = result.throwExceptionIntoGenerator(g)
  File "c:\users\xkdlr\appdata\local\programs\python\python36-32\lib\site-packages\twisted\python\failure.py", line 408, in throwExceptionIntoGenerator
    return g.throw(self.type, self.value, self.tb)
  File "c:\users\xkdlr\appdata\local\programs\python\python36-32\lib\site-packages\scrapy\core\downloader\middleware.py", line 43, in process_request
    defer.returnValue((yield download_func(request=request,spider=spider)))
  File "c:\users\xkdlr\appdata\local\programs\python\python36-32\lib\site-packages\twisted\internet\defer.py", line 653, in _runCallbacks
    current.result = callback(current.result, *args, **kw)
  File "c:\users\xkdlr\appdata\local\programs\python\python36-32\lib\site-packages\scrapy\core\downloader\handlers\http11.py", line 320, in _cb_timeout
    raise TimeoutError("Getting %s took longer than %s seconds." % (url, timeout))
twisted.internet.error.TimeoutError: User timeout caused connection failure: Getting http://web.humoruniv.com//board/humor/list.html?table=pdswait&pg=3 took longer than 30.0 seconds..
2017-10-11 14:36:29 [scrapy.core.scraper] ERROR: Error downloading <GET http://web.humoruniv.com/board/humor/list.html?table=fear&pg=3>
Traceback (most recent call last):
  File "c:\users\xkdlr\appdata\local\programs\python\python36-32\lib\site-packages\twisted\internet\defer.py", line 1384, in _inlineCallbacks
    result = result.throwExceptionIntoGenerator(g)
  File "c:\users\xkdlr\appdata\local\programs\python\python36-32\lib\site-packages\twisted\python\failure.py", line 408, in throwExceptionIntoGenerator
    return g.throw(self.type, self.value, self.tb)
  File "c:\users\xkdlr\appdata\local\programs\python\python36-32\lib\site-packages\scrapy\core\downloader\middleware.py", line 43, in process_request
    defer.returnValue((yield download_func(request=request,spider=spider)))
  File "c:\users\xkdlr\appdata\local\programs\python\python36-32\lib\site-packages\twisted\internet\defer.py", line 653, in _runCallbacks
    current.result = callback(current.result, *args, **kw)
  File "c:\users\xkdlr\appdata\local\programs\python\python36-32\lib\site-packages\scrapy\core\downloader\handlers\http11.py", line 320, in _cb_timeout
    raise TimeoutError("Getting %s took longer than %s seconds." % (url, timeout))
twisted.internet.error.TimeoutError: User timeout caused connection failure: Getting http://web.humoruniv.com/board/humor/list.html?table=fear&pg=3 took longer than 30.0 seconds..
2017-10-11 14:36:29 [scrapy.core.scraper] ERROR: Error downloading <GET http://web.humoruniv.com/board/humor/list.html?table=pds&pg=3>
Traceback (most recent call last):
  File "c:\users\xkdlr\appdata\local\programs\python\python36-32\lib\site-packages\twisted\internet\defer.py", line 1384, in _inlineCallbacks
    result = result.throwExceptionIntoGenerator(g)
  File "c:\users\xkdlr\appdata\local\programs\python\python36-32\lib\site-packages\twisted\python\failure.py", line 408, in throwExceptionIntoGenerator
    return g.throw(self.type, self.value, self.tb)
  File "c:\users\xkdlr\appdata\local\programs\python\python36-32\lib\site-packages\scrapy\core\downloader\middleware.py", line 43, in process_request
    defer.returnValue((yield download_func(request=request,spider=spider)))
  File "c:\users\xkdlr\appdata\local\programs\python\python36-32\lib\site-packages\twisted\internet\defer.py", line 653, in _runCallbacks
    current.result = callback(current.result, *args, **kw)
  File "c:\users\xkdlr\appdata\local\programs\python\python36-32\lib\site-packages\scrapy\core\downloader\handlers\http11.py", line 320, in _cb_timeout
    raise TimeoutError("Getting %s took longer than %s seconds." % (url, timeout))
twisted.internet.error.TimeoutError: User timeout caused connection failure: Getting http://web.humoruniv.com/board/humor/list.html?table=pds&pg=3 took longer than 30.0 seconds..
2017-10-11 14:42:43 [scrapy.core.scraper] ERROR: Error downloading <GET http://web.humoruniv.com/board/humor/list.html?table=memory&pg=3>
Traceback (most recent call last):
  File "c:\users\xkdlr\appdata\local\programs\python\python36-32\lib\site-packages\twisted\internet\defer.py", line 1384, in _inlineCallbacks
    result = result.throwExceptionIntoGenerator(g)
  File "c:\users\xkdlr\appdata\local\programs\python\python36-32\lib\site-packages\twisted\python\failure.py", line 408, in throwExceptionIntoGenerator
    return g.throw(self.type, self.value, self.tb)
  File "c:\users\xkdlr\appdata\local\programs\python\python36-32\lib\site-packages\scrapy\core\downloader\middleware.py", line 43, in process_request
    defer.returnValue((yield download_func(request=request,spider=spider)))
  File "c:\users\xkdlr\appdata\local\programs\python\python36-32\lib\site-packages\twisted\internet\defer.py", line 653, in _runCallbacks
    current.result = callback(current.result, *args, **kw)
  File "c:\users\xkdlr\appdata\local\programs\python\python36-32\lib\site-packages\scrapy\core\downloader\handlers\http11.py", line 320, in _cb_timeout
    raise TimeoutError("Getting %s took longer than %s seconds." % (url, timeout))
twisted.internet.error.TimeoutError: User timeout caused connection failure: Getting http://web.humoruniv.com/board/humor/list.html?table=memory&pg=3 took longer than 30.0 seconds..
2017-10-11 14:42:43 [scrapy.core.scraper] ERROR: Error downloading <GET http://web.humoruniv.com/board/humor/list.html?table=studying&pg=3>
Traceback (most recent call last):
  File "c:\users\xkdlr\appdata\local\programs\python\python36-32\lib\site-packages\twisted\internet\defer.py", line 1384, in _inlineCallbacks
    result = result.throwExceptionIntoGenerator(g)
  File "c:\users\xkdlr\appdata\local\programs\python\python36-32\lib\site-packages\twisted\python\failure.py", line 408, in throwExceptionIntoGenerator
    return g.throw(self.type, self.value, self.tb)
  File "c:\users\xkdlr\appdata\local\programs\python\python36-32\lib\site-packages\scrapy\core\downloader\middleware.py", line 43, in process_request
    defer.returnValue((yield download_func(request=request,spider=spider)))
  File "c:\users\xkdlr\appdata\local\programs\python\python36-32\lib\site-packages\twisted\internet\defer.py", line 653, in _runCallbacks
    current.result = callback(current.result, *args, **kw)
  File "c:\users\xkdlr\appdata\local\programs\python\python36-32\lib\site-packages\scrapy\core\downloader\handlers\http11.py", line 320, in _cb_timeout
    raise TimeoutError("Getting %s took longer than %s seconds." % (url, timeout))
twisted.internet.error.TimeoutError: User timeout caused connection failure: Getting http://web.humoruniv.com/board/humor/list.html?table=studying&pg=3 took longer than 30.0 seconds..
2017-10-11 14:42:48 [scrapy.core.scraper] ERROR: Error downloading <GET http://web.humoruniv.com/board/humor/list.html?table=solo&pg=3>
Traceback (most recent call last):
  File "c:\users\xkdlr\appdata\local\programs\python\python36-32\lib\site-packages\twisted\internet\defer.py", line 1384, in _inlineCallbacks
    result = result.throwExceptionIntoGenerator(g)
  File "c:\users\xkdlr\appdata\local\programs\python\python36-32\lib\site-packages\twisted\python\failure.py", line 408, in throwExceptionIntoGenerator
    return g.throw(self.type, self.value, self.tb)
  File "c:\users\xkdlr\appdata\local\programs\python\python36-32\lib\site-packages\scrapy\core\downloader\middleware.py", line 43, in process_request
    defer.returnValue((yield download_func(request=request,spider=spider)))
  File "c:\users\xkdlr\appdata\local\programs\python\python36-32\lib\site-packages\twisted\internet\defer.py", line 653, in _runCallbacks
    current.result = callback(current.result, *args, **kw)
  File "c:\users\xkdlr\appdata\local\programs\python\python36-32\lib\site-packages\scrapy\core\downloader\handlers\http11.py", line 320, in _cb_timeout
    raise TimeoutError("Getting %s took longer than %s seconds." % (url, timeout))
twisted.internet.error.TimeoutError: User timeout caused connection failure: Getting http://web.humoruniv.com/board/humor/list.html?table=solo&pg=3 took longer than 30.0 seconds..
2017-10-11 14:42:48 [scrapy.core.scraper] ERROR: Error downloading <GET http://web.humoruniv.com/board/humor/list.html?table=love&pg=3>
Traceback (most recent call last):
  File "c:\users\xkdlr\appdata\local\programs\python\python36-32\lib\site-packages\twisted\internet\defer.py", line 1384, in _inlineCallbacks
    result = result.throwExceptionIntoGenerator(g)
  File "c:\users\xkdlr\appdata\local\programs\python\python36-32\lib\site-packages\twisted\python\failure.py", line 408, in throwExceptionIntoGenerator
    return g.throw(self.type, self.value, self.tb)
  File "c:\users\xkdlr\appdata\local\programs\python\python36-32\lib\site-packages\scrapy\core\downloader\middleware.py", line 43, in process_request
    defer.returnValue((yield download_func(request=request,spider=spider)))
  File "c:\users\xkdlr\appdata\local\programs\python\python36-32\lib\site-packages\twisted\internet\defer.py", line 653, in _runCallbacks
    current.result = callback(current.result, *args, **kw)
  File "c:\users\xkdlr\appdata\local\programs\python\python36-32\lib\site-packages\scrapy\core\downloader\handlers\http11.py", line 320, in _cb_timeout
    raise TimeoutError("Getting %s took longer than %s seconds." % (url, timeout))
twisted.internet.error.TimeoutError: User timeout caused connection failure: Getting http://web.humoruniv.com/board/humor/list.html?table=love&pg=3 took longer than 30.0 seconds..
2017-10-11 14:43:20 [scrapy.core.scraper] ERROR: Error downloading <GET http://web.humoruniv.com/board/humor/list.html?table=spnatural&pg=3>
Traceback (most recent call last):
  File "c:\users\xkdlr\appdata\local\programs\python\python36-32\lib\site-packages\twisted\internet\defer.py", line 1384, in _inlineCallbacks
    result = result.throwExceptionIntoGenerator(g)
  File "c:\users\xkdlr\appdata\local\programs\python\python36-32\lib\site-packages\twisted\python\failure.py", line 408, in throwExceptionIntoGenerator
    return g.throw(self.type, self.value, self.tb)
  File "c:\users\xkdlr\appdata\local\programs\python\python36-32\lib\site-packages\scrapy\core\downloader\middleware.py", line 43, in process_request
    defer.returnValue((yield download_func(request=request,spider=spider)))
  File "c:\users\xkdlr\appdata\local\programs\python\python36-32\lib\site-packages\twisted\internet\defer.py", line 653, in _runCallbacks
    current.result = callback(current.result, *args, **kw)
  File "c:\users\xkdlr\appdata\local\programs\python\python36-32\lib\site-packages\scrapy\core\downloader\handlers\http11.py", line 320, in _cb_timeout
    raise TimeoutError("Getting %s took longer than %s seconds." % (url, timeout))
twisted.internet.error.TimeoutError: User timeout caused connection failure: Getting http://web.humoruniv.com/board/humor/list.html?table=spnatural&pg=3 took longer than 30.0 seconds..
2017-10-11 14:43:20 [scrapy.core.scraper] ERROR: Error downloading <GET http://web.humoruniv.com/board/humor/list.html?table=sns&pg=3>
Traceback (most recent call last):
  File "c:\users\xkdlr\appdata\local\programs\python\python36-32\lib\site-packages\twisted\internet\defer.py", line 1384, in _inlineCallbacks
    result = result.throwExceptionIntoGenerator(g)
  File "c:\users\xkdlr\appdata\local\programs\python\python36-32\lib\site-packages\twisted\python\failure.py", line 408, in throwExceptionIntoGenerator
    return g.throw(self.type, self.value, self.tb)
  File "c:\users\xkdlr\appdata\local\programs\python\python36-32\lib\site-packages\scrapy\core\downloader\middleware.py", line 43, in process_request
    defer.returnValue((yield download_func(request=request,spider=spider)))
  File "c:\users\xkdlr\appdata\local\programs\python\python36-32\lib\site-packages\twisted\internet\defer.py", line 653, in _runCallbacks
    current.result = callback(current.result, *args, **kw)
  File "c:\users\xkdlr\appdata\local\programs\python\python36-32\lib\site-packages\scrapy\core\downloader\handlers\http11.py", line 320, in _cb_timeout
    raise TimeoutError("Getting %s took longer than %s seconds." % (url, timeout))
twisted.internet.error.TimeoutError: User timeout caused connection failure: Getting http://web.humoruniv.com/board/humor/list.html?table=sns&pg=3 took longer than 30.0 seconds..
2017-10-11 14:47:30 [scrapy.core.scraper] ERROR: Error downloading <GET http://web.humoruniv.com/board/humor/list.html?table=guest&pg=4>: [<twisted.python.failure.Failure twisted.internet.error.ConnectionDone: Connection was closed cleanly.>]
2017-10-11 14:47:30 [scrapy.core.scraper] ERROR: Error downloading <GET http://web.humoruniv.com/board/humor/list.html?table=fear&pg=4>: [<twisted.python.failure.Failure twisted.internet.error.ConnectionDone: Connection was closed cleanly.>]
2017-10-11 14:48:16 [scrapy.core.scraper] ERROR: Error downloading <GET http://web.humoruniv.com/board/humor/list.html?table=thema2&pg=4>
Traceback (most recent call last):
  File "c:\users\xkdlr\appdata\local\programs\python\python36-32\lib\site-packages\twisted\internet\defer.py", line 1384, in _inlineCallbacks
    result = result.throwExceptionIntoGenerator(g)
  File "c:\users\xkdlr\appdata\local\programs\python\python36-32\lib\site-packages\twisted\python\failure.py", line 408, in throwExceptionIntoGenerator
    return g.throw(self.type, self.value, self.tb)
  File "c:\users\xkdlr\appdata\local\programs\python\python36-32\lib\site-packages\scrapy\core\downloader\middleware.py", line 43, in process_request
    defer.returnValue((yield download_func(request=request,spider=spider)))
  File "c:\users\xkdlr\appdata\local\programs\python\python36-32\lib\site-packages\twisted\internet\defer.py", line 653, in _runCallbacks
    current.result = callback(current.result, *args, **kw)
  File "c:\users\xkdlr\appdata\local\programs\python\python36-32\lib\site-packages\scrapy\core\downloader\handlers\http11.py", line 320, in _cb_timeout
    raise TimeoutError("Getting %s took longer than %s seconds." % (url, timeout))
twisted.internet.error.TimeoutError: User timeout caused connection failure: Getting http://web.humoruniv.com/board/humor/list.html?table=thema2&pg=4 took longer than 30.0 seconds..
2017-10-11 14:48:21 [scrapy.core.scraper] ERROR: Error downloading <GET http://web.humoruniv.com/board/humor/list.html?table=lol&pg=4>
Traceback (most recent call last):
  File "c:\users\xkdlr\appdata\local\programs\python\python36-32\lib\site-packages\twisted\internet\defer.py", line 1384, in _inlineCallbacks
    result = result.throwExceptionIntoGenerator(g)
  File "c:\users\xkdlr\appdata\local\programs\python\python36-32\lib\site-packages\twisted\python\failure.py", line 408, in throwExceptionIntoGenerator
    return g.throw(self.type, self.value, self.tb)
  File "c:\users\xkdlr\appdata\local\programs\python\python36-32\lib\site-packages\scrapy\core\downloader\middleware.py", line 43, in process_request
    defer.returnValue((yield download_func(request=request,spider=spider)))
  File "c:\users\xkdlr\appdata\local\programs\python\python36-32\lib\site-packages\twisted\internet\defer.py", line 653, in _runCallbacks
    current.result = callback(current.result, *args, **kw)
  File "c:\users\xkdlr\appdata\local\programs\python\python36-32\lib\site-packages\scrapy\core\downloader\handlers\http11.py", line 320, in _cb_timeout
    raise TimeoutError("Getting %s took longer than %s seconds." % (url, timeout))
twisted.internet.error.TimeoutError: User timeout caused connection failure: Getting http://web.humoruniv.com/board/humor/list.html?table=lol&pg=4 took longer than 30.0 seconds..
2017-10-11 14:49:05 [scrapy.core.scraper] ERROR: Error downloading <GET http://web.humoruniv.com/board/humor/list.html?table=thema3&pg=4>
Traceback (most recent call last):
  File "c:\users\xkdlr\appdata\local\programs\python\python36-32\lib\site-packages\twisted\internet\defer.py", line 1384, in _inlineCallbacks
    result = result.throwExceptionIntoGenerator(g)
  File "c:\users\xkdlr\appdata\local\programs\python\python36-32\lib\site-packages\twisted\python\failure.py", line 408, in throwExceptionIntoGenerator
    return g.throw(self.type, self.value, self.tb)
  File "c:\users\xkdlr\appdata\local\programs\python\python36-32\lib\site-packages\scrapy\core\downloader\middleware.py", line 43, in process_request
    defer.returnValue((yield download_func(request=request,spider=spider)))
  File "c:\users\xkdlr\appdata\local\programs\python\python36-32\lib\site-packages\twisted\internet\defer.py", line 653, in _runCallbacks
    current.result = callback(current.result, *args, **kw)
  File "c:\users\xkdlr\appdata\local\programs\python\python36-32\lib\site-packages\scrapy\core\downloader\handlers\http11.py", line 320, in _cb_timeout
    raise TimeoutError("Getting %s took longer than %s seconds." % (url, timeout))
twisted.internet.error.TimeoutError: User timeout caused connection failure: Getting http://web.humoruniv.com/board/humor/list.html?table=thema3&pg=4 took longer than 30.0 seconds..
2017-10-11 14:49:05 [scrapy.core.scraper] ERROR: Error downloading <GET http://web.humoruniv.com/board/humor/list.html?table=muzik&pg=4>
Traceback (most recent call last):
  File "c:\users\xkdlr\appdata\local\programs\python\python36-32\lib\site-packages\twisted\internet\defer.py", line 1384, in _inlineCallbacks
    result = result.throwExceptionIntoGenerator(g)
  File "c:\users\xkdlr\appdata\local\programs\python\python36-32\lib\site-packages\twisted\python\failure.py", line 408, in throwExceptionIntoGenerator
    return g.throw(self.type, self.value, self.tb)
  File "c:\users\xkdlr\appdata\local\programs\python\python36-32\lib\site-packages\scrapy\core\downloader\middleware.py", line 43, in process_request
    defer.returnValue((yield download_func(request=request,spider=spider)))
  File "c:\users\xkdlr\appdata\local\programs\python\python36-32\lib\site-packages\twisted\internet\defer.py", line 653, in _runCallbacks
    current.result = callback(current.result, *args, **kw)
  File "c:\users\xkdlr\appdata\local\programs\python\python36-32\lib\site-packages\scrapy\core\downloader\handlers\http11.py", line 320, in _cb_timeout
    raise TimeoutError("Getting %s took longer than %s seconds." % (url, timeout))
twisted.internet.error.TimeoutError: User timeout caused connection failure: Getting http://web.humoruniv.com/board/humor/list.html?table=muzik&pg=4 took longer than 30.0 seconds..
2017-10-11 14:49:35 [scrapy.core.scraper] ERROR: Error downloading <GET http://web.humoruniv.com/board/humor/list.html?table=pride&pg=4>
Traceback (most recent call last):
  File "c:\users\xkdlr\appdata\local\programs\python\python36-32\lib\site-packages\twisted\internet\defer.py", line 1384, in _inlineCallbacks
    result = result.throwExceptionIntoGenerator(g)
  File "c:\users\xkdlr\appdata\local\programs\python\python36-32\lib\site-packages\twisted\python\failure.py", line 408, in throwExceptionIntoGenerator
    return g.throw(self.type, self.value, self.tb)
  File "c:\users\xkdlr\appdata\local\programs\python\python36-32\lib\site-packages\scrapy\core\downloader\middleware.py", line 43, in process_request
    defer.returnValue((yield download_func(request=request,spider=spider)))
  File "c:\users\xkdlr\appdata\local\programs\python\python36-32\lib\site-packages\twisted\internet\defer.py", line 653, in _runCallbacks
    current.result = callback(current.result, *args, **kw)
  File "c:\users\xkdlr\appdata\local\programs\python\python36-32\lib\site-packages\scrapy\core\downloader\handlers\http11.py", line 320, in _cb_timeout
    raise TimeoutError("Getting %s took longer than %s seconds." % (url, timeout))
twisted.internet.error.TimeoutError: User timeout caused connection failure: Getting http://web.humoruniv.com/board/humor/list.html?table=pride&pg=4 took longer than 30.0 seconds..
2017-10-11 14:51:45 [scrapy.core.scraper] ERROR: Error downloading <GET http://web.humoruniv.com/board/humor/list.html?table=lol&pg=5>: [<twisted.python.failure.Failure twisted.internet.error.ConnectionDone: Connection was closed cleanly.>]
2017-10-11 14:51:45 [scrapy.core.scraper] ERROR: Error downloading <GET http://web.humoruniv.com/board/humor/list.html?table=muzik&pg=5>: [<twisted.python.failure.Failure twisted.internet.error.ConnectionDone: Connection was closed cleanly.>]
2017-10-11 14:51:45 [scrapy.core.scraper] ERROR: Error downloading <GET http://web.humoruniv.com/board/humor/list.html?table=pride&pg=5>: [<twisted.python.failure.Failure twisted.internet.error.ConnectionDone: Connection was closed cleanly.>]
2017-10-11 14:52:53 [scrapy.core.scraper] ERROR: Error downloading <GET http://web.humoruniv.com/board/humor/list.html?table=studying&pg=5>
Traceback (most recent call last):
  File "c:\users\xkdlr\appdata\local\programs\python\python36-32\lib\site-packages\twisted\internet\defer.py", line 1384, in _inlineCallbacks
    result = result.throwExceptionIntoGenerator(g)
  File "c:\users\xkdlr\appdata\local\programs\python\python36-32\lib\site-packages\twisted\python\failure.py", line 408, in throwExceptionIntoGenerator
    return g.throw(self.type, self.value, self.tb)
  File "c:\users\xkdlr\appdata\local\programs\python\python36-32\lib\site-packages\scrapy\core\downloader\middleware.py", line 43, in process_request
    defer.returnValue((yield download_func(request=request,spider=spider)))
  File "c:\users\xkdlr\appdata\local\programs\python\python36-32\lib\site-packages\twisted\internet\defer.py", line 653, in _runCallbacks
    current.result = callback(current.result, *args, **kw)
  File "c:\users\xkdlr\appdata\local\programs\python\python36-32\lib\site-packages\scrapy\core\downloader\handlers\http11.py", line 320, in _cb_timeout
    raise TimeoutError("Getting %s took longer than %s seconds." % (url, timeout))
twisted.internet.error.TimeoutError: User timeout caused connection failure: Getting http://web.humoruniv.com/board/humor/list.html?table=studying&pg=5 took longer than 30.0 seconds..
2017-10-11 14:53:57 [scrapy.core.scraper] ERROR: Error downloading <GET http://web.humoruniv.com/board/humor/list.html?table=sns&pg=5>: [<twisted.python.failure.Failure twisted.internet.error.ConnectionDone: Connection was closed cleanly.>]
2017-10-11 14:53:57 [scrapy.core.scraper] ERROR: Error downloading <GET http://web.humoruniv.com//board/humor/list.html?table=nova_toon&pg=6>: [<twisted.python.failure.Failure twisted.internet.error.ConnectionDone: Connection was closed cleanly.>]
2017-10-11 14:53:57 [scrapy.core.scraper] ERROR: Error downloading <GET http://web.humoruniv.com/board/humor/list.html?table=dump&pg=5>: [<twisted.python.failure.Failure twisted.internet.error.ConnectionDone: Connection was closed cleanly.>]
2017-10-11 14:53:57 [scrapy.core.scraper] ERROR: Error downloading <GET http://web.humoruniv.com//board/humor/list.html?table=art_toon&pg=6>: [<twisted.python.failure.Failure twisted.internet.error.ConnectionDone: Connection was closed cleanly.>]
2017-10-11 14:54:03 [scrapy.core.scraper] ERROR: Error downloading <GET http://web.humoruniv.com//board/humor/list.html?table=kin&pg=6>
Traceback (most recent call last):
  File "c:\users\xkdlr\appdata\local\programs\python\python36-32\lib\site-packages\twisted\internet\defer.py", line 1384, in _inlineCallbacks
    result = result.throwExceptionIntoGenerator(g)
  File "c:\users\xkdlr\appdata\local\programs\python\python36-32\lib\site-packages\twisted\python\failure.py", line 408, in throwExceptionIntoGenerator
    return g.throw(self.type, self.value, self.tb)
  File "c:\users\xkdlr\appdata\local\programs\python\python36-32\lib\site-packages\scrapy\core\downloader\middleware.py", line 43, in process_request
    defer.returnValue((yield download_func(request=request,spider=spider)))
  File "c:\users\xkdlr\appdata\local\programs\python\python36-32\lib\site-packages\twisted\internet\defer.py", line 653, in _runCallbacks
    current.result = callback(current.result, *args, **kw)
  File "c:\users\xkdlr\appdata\local\programs\python\python36-32\lib\site-packages\scrapy\core\downloader\handlers\http11.py", line 320, in _cb_timeout
    raise TimeoutError("Getting %s took longer than %s seconds." % (url, timeout))
twisted.internet.error.TimeoutError: User timeout caused connection failure: Getting http://web.humoruniv.com//board/humor/list.html?table=kin&pg=6 took longer than 30.0 seconds..
2017-10-11 14:55:29 [scrapy.core.scraper] ERROR: Error downloading <GET http://web.humoruniv.com/board/humor/list.html?table=cabinet&pg=5>
Traceback (most recent call last):
  File "c:\users\xkdlr\appdata\local\programs\python\python36-32\lib\site-packages\twisted\internet\defer.py", line 1384, in _inlineCallbacks
    result = result.throwExceptionIntoGenerator(g)
  File "c:\users\xkdlr\appdata\local\programs\python\python36-32\lib\site-packages\twisted\python\failure.py", line 408, in throwExceptionIntoGenerator
    return g.throw(self.type, self.value, self.tb)
  File "c:\users\xkdlr\appdata\local\programs\python\python36-32\lib\site-packages\scrapy\core\downloader\middleware.py", line 43, in process_request
    defer.returnValue((yield download_func(request=request,spider=spider)))
  File "c:\users\xkdlr\appdata\local\programs\python\python36-32\lib\site-packages\twisted\internet\defer.py", line 653, in _runCallbacks
    current.result = callback(current.result, *args, **kw)
  File "c:\users\xkdlr\appdata\local\programs\python\python36-32\lib\site-packages\scrapy\core\downloader\handlers\http11.py", line 320, in _cb_timeout
    raise TimeoutError("Getting %s took longer than %s seconds." % (url, timeout))
twisted.internet.error.TimeoutError: User timeout caused connection failure: Getting http://web.humoruniv.com/board/humor/list.html?table=cabinet&pg=5 took longer than 30.0 seconds..
2017-10-11 14:55:29 [scrapy.core.scraper] ERROR: Error downloading <GET http://web.humoruniv.com/board/humor/list.html?table=pds&pg=6>
Traceback (most recent call last):
  File "c:\users\xkdlr\appdata\local\programs\python\python36-32\lib\site-packages\twisted\internet\defer.py", line 1384, in _inlineCallbacks
    result = result.throwExceptionIntoGenerator(g)
  File "c:\users\xkdlr\appdata\local\programs\python\python36-32\lib\site-packages\twisted\python\failure.py", line 408, in throwExceptionIntoGenerator
    return g.throw(self.type, self.value, self.tb)
  File "c:\users\xkdlr\appdata\local\programs\python\python36-32\lib\site-packages\scrapy\core\downloader\middleware.py", line 43, in process_request
    defer.returnValue((yield download_func(request=request,spider=spider)))
  File "c:\users\xkdlr\appdata\local\programs\python\python36-32\lib\site-packages\twisted\internet\defer.py", line 653, in _runCallbacks
    current.result = callback(current.result, *args, **kw)
  File "c:\users\xkdlr\appdata\local\programs\python\python36-32\lib\site-packages\scrapy\core\downloader\handlers\http11.py", line 320, in _cb_timeout
    raise TimeoutError("Getting %s took longer than %s seconds." % (url, timeout))
twisted.internet.error.TimeoutError: User timeout caused connection failure: Getting http://web.humoruniv.com/board/humor/list.html?table=pds&pg=6 took longer than 30.0 seconds..
2017-10-11 14:55:30 [scrapy.core.scraper] ERROR: Error downloading <GET http://web.humoruniv.com//board/humor/list.html?table=pdswait&pg=6>
Traceback (most recent call last):
  File "c:\users\xkdlr\appdata\local\programs\python\python36-32\lib\site-packages\twisted\internet\defer.py", line 1384, in _inlineCallbacks
    result = result.throwExceptionIntoGenerator(g)
  File "c:\users\xkdlr\appdata\local\programs\python\python36-32\lib\site-packages\twisted\python\failure.py", line 408, in throwExceptionIntoGenerator
    return g.throw(self.type, self.value, self.tb)
  File "c:\users\xkdlr\appdata\local\programs\python\python36-32\lib\site-packages\scrapy\core\downloader\middleware.py", line 43, in process_request
    defer.returnValue((yield download_func(request=request,spider=spider)))
  File "c:\users\xkdlr\appdata\local\programs\python\python36-32\lib\site-packages\twisted\internet\defer.py", line 653, in _runCallbacks
    current.result = callback(current.result, *args, **kw)
  File "c:\users\xkdlr\appdata\local\programs\python\python36-32\lib\site-packages\scrapy\core\downloader\handlers\http11.py", line 320, in _cb_timeout
    raise TimeoutError("Getting %s took longer than %s seconds." % (url, timeout))
twisted.internet.error.TimeoutError: User timeout caused connection failure: Getting http://web.humoruniv.com//board/humor/list.html?table=pdswait&pg=6 took longer than 30.0 seconds..
2017-10-11 14:55:31 [scrapy.core.scraper] ERROR: Error downloading <GET http://web.humoruniv.com/board/humor/list.html?table=worldcup&pg=5>
Traceback (most recent call last):
  File "c:\users\xkdlr\appdata\local\programs\python\python36-32\lib\site-packages\twisted\internet\defer.py", line 1384, in _inlineCallbacks
    result = result.throwExceptionIntoGenerator(g)
  File "c:\users\xkdlr\appdata\local\programs\python\python36-32\lib\site-packages\twisted\python\failure.py", line 408, in throwExceptionIntoGenerator
    return g.throw(self.type, self.value, self.tb)
  File "c:\users\xkdlr\appdata\local\programs\python\python36-32\lib\site-packages\scrapy\core\downloader\middleware.py", line 43, in process_request
    defer.returnValue((yield download_func(request=request,spider=spider)))
  File "c:\users\xkdlr\appdata\local\programs\python\python36-32\lib\site-packages\twisted\internet\defer.py", line 653, in _runCallbacks
    current.result = callback(current.result, *args, **kw)
  File "c:\users\xkdlr\appdata\local\programs\python\python36-32\lib\site-packages\scrapy\core\downloader\handlers\http11.py", line 320, in _cb_timeout
    raise TimeoutError("Getting %s took longer than %s seconds." % (url, timeout))
twisted.internet.error.TimeoutError: User timeout caused connection failure: Getting http://web.humoruniv.com/board/humor/list.html?table=worldcup&pg=5 took longer than 30.0 seconds..
2017-10-11 14:55:31 [scrapy.core.scraper] ERROR: Error downloading <GET http://web.humoruniv.com//board/humor/list.html?table=otl&pg=6>
Traceback (most recent call last):
  File "c:\users\xkdlr\appdata\local\programs\python\python36-32\lib\site-packages\twisted\internet\defer.py", line 1384, in _inlineCallbacks
    result = result.throwExceptionIntoGenerator(g)
  File "c:\users\xkdlr\appdata\local\programs\python\python36-32\lib\site-packages\twisted\python\failure.py", line 408, in throwExceptionIntoGenerator
    return g.throw(self.type, self.value, self.tb)
  File "c:\users\xkdlr\appdata\local\programs\python\python36-32\lib\site-packages\scrapy\core\downloader\middleware.py", line 43, in process_request
    defer.returnValue((yield download_func(request=request,spider=spider)))
  File "c:\users\xkdlr\appdata\local\programs\python\python36-32\lib\site-packages\twisted\internet\defer.py", line 653, in _runCallbacks
    current.result = callback(current.result, *args, **kw)
  File "c:\users\xkdlr\appdata\local\programs\python\python36-32\lib\site-packages\scrapy\core\downloader\handlers\http11.py", line 320, in _cb_timeout
    raise TimeoutError("Getting %s took longer than %s seconds." % (url, timeout))
twisted.internet.error.TimeoutError: User timeout caused connection failure: Getting http://web.humoruniv.com//board/humor/list.html?table=otl&pg=6 took longer than 30.0 seconds..
2017-10-11 14:56:07 [scrapy.core.scraper] ERROR: Error downloading <GET http://web.humoruniv.com/board/humor/list.html?table=mild&pg=6>
Traceback (most recent call last):
  File "c:\users\xkdlr\appdata\local\programs\python\python36-32\lib\site-packages\twisted\internet\defer.py", line 1384, in _inlineCallbacks
    result = result.throwExceptionIntoGenerator(g)
  File "c:\users\xkdlr\appdata\local\programs\python\python36-32\lib\site-packages\twisted\python\failure.py", line 408, in throwExceptionIntoGenerator
    return g.throw(self.type, self.value, self.tb)
  File "c:\users\xkdlr\appdata\local\programs\python\python36-32\lib\site-packages\scrapy\core\downloader\middleware.py", line 43, in process_request
    defer.returnValue((yield download_func(request=request,spider=spider)))
  File "c:\users\xkdlr\appdata\local\programs\python\python36-32\lib\site-packages\twisted\internet\defer.py", line 653, in _runCallbacks
    current.result = callback(current.result, *args, **kw)
  File "c:\users\xkdlr\appdata\local\programs\python\python36-32\lib\site-packages\scrapy\core\downloader\handlers\http11.py", line 320, in _cb_timeout
    raise TimeoutError("Getting %s took longer than %s seconds." % (url, timeout))
twisted.internet.error.TimeoutError: User timeout caused connection failure: Getting http://web.humoruniv.com/board/humor/list.html?table=mild&pg=6 took longer than 30.0 seconds..
2017-10-11 14:56:07 [scrapy.core.scraper] ERROR: Error downloading <GET http://web.humoruniv.com/board/humor/list.html?table=free&pg=6>
Traceback (most recent call last):
  File "c:\users\xkdlr\appdata\local\programs\python\python36-32\lib\site-packages\twisted\internet\defer.py", line 1384, in _inlineCallbacks
    result = result.throwExceptionIntoGenerator(g)
  File "c:\users\xkdlr\appdata\local\programs\python\python36-32\lib\site-packages\twisted\python\failure.py", line 408, in throwExceptionIntoGenerator
    return g.throw(self.type, self.value, self.tb)
  File "c:\users\xkdlr\appdata\local\programs\python\python36-32\lib\site-packages\scrapy\core\downloader\middleware.py", line 43, in process_request
    defer.returnValue((yield download_func(request=request,spider=spider)))
  File "c:\users\xkdlr\appdata\local\programs\python\python36-32\lib\site-packages\twisted\internet\defer.py", line 653, in _runCallbacks
    current.result = callback(current.result, *args, **kw)
  File "c:\users\xkdlr\appdata\local\programs\python\python36-32\lib\site-packages\scrapy\core\downloader\handlers\http11.py", line 320, in _cb_timeout
    raise TimeoutError("Getting %s took longer than %s seconds." % (url, timeout))
twisted.internet.error.TimeoutError: User timeout caused connection failure: Getting http://web.humoruniv.com/board/humor/list.html?table=free&pg=6 took longer than 30.0 seconds..
2017-10-11 14:56:07 [scrapy.core.scraper] ERROR: Error downloading <GET http://web.humoruniv.com/board/humor/list.html?table=poll&pg=6>
Traceback (most recent call last):
  File "c:\users\xkdlr\appdata\local\programs\python\python36-32\lib\site-packages\twisted\internet\defer.py", line 1384, in _inlineCallbacks
    result = result.throwExceptionIntoGenerator(g)
  File "c:\users\xkdlr\appdata\local\programs\python\python36-32\lib\site-packages\twisted\python\failure.py", line 408, in throwExceptionIntoGenerator
    return g.throw(self.type, self.value, self.tb)
  File "c:\users\xkdlr\appdata\local\programs\python\python36-32\lib\site-packages\scrapy\core\downloader\middleware.py", line 43, in process_request
    defer.returnValue((yield download_func(request=request,spider=spider)))
  File "c:\users\xkdlr\appdata\local\programs\python\python36-32\lib\site-packages\twisted\internet\defer.py", line 653, in _runCallbacks
    current.result = callback(current.result, *args, **kw)
  File "c:\users\xkdlr\appdata\local\programs\python\python36-32\lib\site-packages\scrapy\core\downloader\handlers\http11.py", line 320, in _cb_timeout
    raise TimeoutError("Getting %s took longer than %s seconds." % (url, timeout))
twisted.internet.error.TimeoutError: User timeout caused connection failure: Getting http://web.humoruniv.com/board/humor/list.html?table=poll&pg=6 took longer than 30.0 seconds..
2017-10-11 14:56:22 [scrapy.core.scraper] ERROR: Error downloading <GET http://web.humoruniv.com/board/humor/list.html?table=fear&pg=6>
Traceback (most recent call last):
  File "c:\users\xkdlr\appdata\local\programs\python\python36-32\lib\site-packages\twisted\internet\defer.py", line 1384, in _inlineCallbacks
    result = result.throwExceptionIntoGenerator(g)
  File "c:\users\xkdlr\appdata\local\programs\python\python36-32\lib\site-packages\twisted\python\failure.py", line 408, in throwExceptionIntoGenerator
    return g.throw(self.type, self.value, self.tb)
  File "c:\users\xkdlr\appdata\local\programs\python\python36-32\lib\site-packages\scrapy\core\downloader\middleware.py", line 43, in process_request
    defer.returnValue((yield download_func(request=request,spider=spider)))
  File "c:\users\xkdlr\appdata\local\programs\python\python36-32\lib\site-packages\twisted\internet\defer.py", line 653, in _runCallbacks
    current.result = callback(current.result, *args, **kw)
  File "c:\users\xkdlr\appdata\local\programs\python\python36-32\lib\site-packages\scrapy\core\downloader\handlers\http11.py", line 320, in _cb_timeout
    raise TimeoutError("Getting %s took longer than %s seconds." % (url, timeout))
twisted.internet.error.TimeoutError: User timeout caused connection failure: Getting http://web.humoruniv.com/board/humor/list.html?table=fear&pg=6 took longer than 30.0 seconds..
2017-10-11 14:56:23 [scrapy.core.scraper] ERROR: Error downloading <GET http://web.humoruniv.com/board/humor/list.html?table=guest&pg=6>
Traceback (most recent call last):
  File "c:\users\xkdlr\appdata\local\programs\python\python36-32\lib\site-packages\twisted\internet\defer.py", line 1384, in _inlineCallbacks
    result = result.throwExceptionIntoGenerator(g)
  File "c:\users\xkdlr\appdata\local\programs\python\python36-32\lib\site-packages\twisted\python\failure.py", line 408, in throwExceptionIntoGenerator
    return g.throw(self.type, self.value, self.tb)
  File "c:\users\xkdlr\appdata\local\programs\python\python36-32\lib\site-packages\scrapy\core\downloader\middleware.py", line 43, in process_request
    defer.returnValue((yield download_func(request=request,spider=spider)))
  File "c:\users\xkdlr\appdata\local\programs\python\python36-32\lib\site-packages\twisted\internet\defer.py", line 653, in _runCallbacks
    current.result = callback(current.result, *args, **kw)
  File "c:\users\xkdlr\appdata\local\programs\python\python36-32\lib\site-packages\scrapy\core\downloader\handlers\http11.py", line 320, in _cb_timeout
    raise TimeoutError("Getting %s took longer than %s seconds." % (url, timeout))
twisted.internet.error.TimeoutError: User timeout caused connection failure: Getting http://web.humoruniv.com/board/humor/list.html?table=guest&pg=6 took longer than 30.0 seconds..
2017-10-11 15:04:45 [scrapy.core.scraper] ERROR: Error downloading <GET http://web.humoruniv.com/board/humor/list.html?table=solo&pg=6>: [<twisted.python.failure.Failure twisted.internet.error.ConnectionDone: Connection was closed cleanly.>]
2017-10-11 15:06:47 [scrapy.core.scraper] ERROR: Error downloading <GET http://web.humoruniv.com/board/humor/list.html?table=workshop&pg=6>
Traceback (most recent call last):
  File "c:\users\xkdlr\appdata\local\programs\python\python36-32\lib\site-packages\twisted\internet\defer.py", line 1384, in _inlineCallbacks
    result = result.throwExceptionIntoGenerator(g)
  File "c:\users\xkdlr\appdata\local\programs\python\python36-32\lib\site-packages\twisted\python\failure.py", line 408, in throwExceptionIntoGenerator
    return g.throw(self.type, self.value, self.tb)
  File "c:\users\xkdlr\appdata\local\programs\python\python36-32\lib\site-packages\scrapy\core\downloader\middleware.py", line 43, in process_request
    defer.returnValue((yield download_func(request=request,spider=spider)))
  File "c:\users\xkdlr\appdata\local\programs\python\python36-32\lib\site-packages\twisted\internet\defer.py", line 653, in _runCallbacks
    current.result = callback(current.result, *args, **kw)
  File "c:\users\xkdlr\appdata\local\programs\python\python36-32\lib\site-packages\scrapy\core\downloader\handlers\http11.py", line 320, in _cb_timeout
    raise TimeoutError("Getting %s took longer than %s seconds." % (url, timeout))
twisted.internet.error.TimeoutError: User timeout caused connection failure: Getting http://web.humoruniv.com/board/humor/list.html?table=workshop&pg=6 took longer than 30.0 seconds..
2017-10-11 15:08:14 [scrapy.core.scraper] ERROR: Error downloading <GET http://web.humoruniv.com/board/humor/list.html?table=spnatural&pg=6>
Traceback (most recent call last):
  File "c:\users\xkdlr\appdata\local\programs\python\python36-32\lib\site-packages\twisted\internet\defer.py", line 1384, in _inlineCallbacks
    result = result.throwExceptionIntoGenerator(g)
  File "c:\users\xkdlr\appdata\local\programs\python\python36-32\lib\site-packages\twisted\python\failure.py", line 408, in throwExceptionIntoGenerator
    return g.throw(self.type, self.value, self.tb)
  File "c:\users\xkdlr\appdata\local\programs\python\python36-32\lib\site-packages\scrapy\core\downloader\middleware.py", line 43, in process_request
    defer.returnValue((yield download_func(request=request,spider=spider)))
  File "c:\users\xkdlr\appdata\local\programs\python\python36-32\lib\site-packages\twisted\internet\defer.py", line 653, in _runCallbacks
    current.result = callback(current.result, *args, **kw)
  File "c:\users\xkdlr\appdata\local\programs\python\python36-32\lib\site-packages\scrapy\core\downloader\handlers\http11.py", line 320, in _cb_timeout
    raise TimeoutError("Getting %s took longer than %s seconds." % (url, timeout))
twisted.internet.error.TimeoutError: User timeout caused connection failure: Getting http://web.humoruniv.com/board/humor/list.html?table=spnatural&pg=6 took longer than 30.0 seconds..
2017-10-11 15:08:14 [scrapy.core.scraper] ERROR: Error downloading <GET http://web.humoruniv.com/board/humor/list.html?table=car&pg=6>
Traceback (most recent call last):
  File "c:\users\xkdlr\appdata\local\programs\python\python36-32\lib\site-packages\twisted\internet\defer.py", line 1384, in _inlineCallbacks
    result = result.throwExceptionIntoGenerator(g)
  File "c:\users\xkdlr\appdata\local\programs\python\python36-32\lib\site-packages\twisted\python\failure.py", line 408, in throwExceptionIntoGenerator
    return g.throw(self.type, self.value, self.tb)
  File "c:\users\xkdlr\appdata\local\programs\python\python36-32\lib\site-packages\scrapy\core\downloader\middleware.py", line 43, in process_request
    defer.returnValue((yield download_func(request=request,spider=spider)))
  File "c:\users\xkdlr\appdata\local\programs\python\python36-32\lib\site-packages\twisted\internet\defer.py", line 653, in _runCallbacks
    current.result = callback(current.result, *args, **kw)
  File "c:\users\xkdlr\appdata\local\programs\python\python36-32\lib\site-packages\scrapy\core\downloader\handlers\http11.py", line 320, in _cb_timeout
    raise TimeoutError("Getting %s took longer than %s seconds." % (url, timeout))
twisted.internet.error.TimeoutError: User timeout caused connection failure: Getting http://web.humoruniv.com/board/humor/list.html?table=car&pg=6 took longer than 30.0 seconds..
2017-10-11 15:10:11 [scrapy.core.scraper] ERROR: Error downloading <GET http://web.humoruniv.com/board/humor/list.html?table=game&pg=7>
Traceback (most recent call last):
  File "c:\users\xkdlr\appdata\local\programs\python\python36-32\lib\site-packages\twisted\internet\defer.py", line 1384, in _inlineCallbacks
    result = result.throwExceptionIntoGenerator(g)
  File "c:\users\xkdlr\appdata\local\programs\python\python36-32\lib\site-packages\twisted\python\failure.py", line 408, in throwExceptionIntoGenerator
    return g.throw(self.type, self.value, self.tb)
  File "c:\users\xkdlr\appdata\local\programs\python\python36-32\lib\site-packages\scrapy\core\downloader\middleware.py", line 43, in process_request
    defer.returnValue((yield download_func(request=request,spider=spider)))
  File "c:\users\xkdlr\appdata\local\programs\python\python36-32\lib\site-packages\twisted\internet\defer.py", line 653, in _runCallbacks
    current.result = callback(current.result, *args, **kw)
  File "c:\users\xkdlr\appdata\local\programs\python\python36-32\lib\site-packages\scrapy\core\downloader\handlers\http11.py", line 320, in _cb_timeout
    raise TimeoutError("Getting %s took longer than %s seconds." % (url, timeout))
twisted.internet.error.TimeoutError: User timeout caused connection failure: Getting http://web.humoruniv.com/board/humor/list.html?table=game&pg=7 took longer than 30.0 seconds..
2017-10-11 15:10:11 [scrapy.core.scraper] ERROR: Error downloading <GET http://web.humoruniv.com/board/humor/list.html?table=thema2&pg=7>
Traceback (most recent call last):
  File "c:\users\xkdlr\appdata\local\programs\python\python36-32\lib\site-packages\twisted\internet\defer.py", line 1384, in _inlineCallbacks
    result = result.throwExceptionIntoGenerator(g)
  File "c:\users\xkdlr\appdata\local\programs\python\python36-32\lib\site-packages\twisted\python\failure.py", line 408, in throwExceptionIntoGenerator
    return g.throw(self.type, self.value, self.tb)
  File "c:\users\xkdlr\appdata\local\programs\python\python36-32\lib\site-packages\scrapy\core\downloader\middleware.py", line 43, in process_request
    defer.returnValue((yield download_func(request=request,spider=spider)))
  File "c:\users\xkdlr\appdata\local\programs\python\python36-32\lib\site-packages\twisted\internet\defer.py", line 653, in _runCallbacks
    current.result = callback(current.result, *args, **kw)
  File "c:\users\xkdlr\appdata\local\programs\python\python36-32\lib\site-packages\scrapy\core\downloader\handlers\http11.py", line 320, in _cb_timeout
    raise TimeoutError("Getting %s took longer than %s seconds." % (url, timeout))
twisted.internet.error.TimeoutError: User timeout caused connection failure: Getting http://web.humoruniv.com/board/humor/list.html?table=thema2&pg=7 took longer than 30.0 seconds..
2017-10-11 15:10:16 [scrapy.core.scraper] ERROR: Error downloading <GET http://web.humoruniv.com/board/humor/list.html?table=fear&pg=7>
Traceback (most recent call last):
  File "c:\users\xkdlr\appdata\local\programs\python\python36-32\lib\site-packages\twisted\internet\defer.py", line 1384, in _inlineCallbacks
    result = result.throwExceptionIntoGenerator(g)
  File "c:\users\xkdlr\appdata\local\programs\python\python36-32\lib\site-packages\twisted\python\failure.py", line 408, in throwExceptionIntoGenerator
    return g.throw(self.type, self.value, self.tb)
  File "c:\users\xkdlr\appdata\local\programs\python\python36-32\lib\site-packages\scrapy\core\downloader\middleware.py", line 43, in process_request
    defer.returnValue((yield download_func(request=request,spider=spider)))
  File "c:\users\xkdlr\appdata\local\programs\python\python36-32\lib\site-packages\twisted\internet\defer.py", line 653, in _runCallbacks
    current.result = callback(current.result, *args, **kw)
  File "c:\users\xkdlr\appdata\local\programs\python\python36-32\lib\site-packages\scrapy\core\downloader\handlers\http11.py", line 320, in _cb_timeout
    raise TimeoutError("Getting %s took longer than %s seconds." % (url, timeout))
twisted.internet.error.TimeoutError: User timeout caused connection failure: Getting http://web.humoruniv.com/board/humor/list.html?table=fear&pg=7 took longer than 30.0 seconds..
2017-10-11 15:10:16 [scrapy.core.scraper] ERROR: Error downloading <GET http://web.humoruniv.com/board/humor/list.html?table=guest&pg=7>
Traceback (most recent call last):
  File "c:\users\xkdlr\appdata\local\programs\python\python36-32\lib\site-packages\twisted\internet\defer.py", line 1384, in _inlineCallbacks
    result = result.throwExceptionIntoGenerator(g)
  File "c:\users\xkdlr\appdata\local\programs\python\python36-32\lib\site-packages\twisted\python\failure.py", line 408, in throwExceptionIntoGenerator
    return g.throw(self.type, self.value, self.tb)
  File "c:\users\xkdlr\appdata\local\programs\python\python36-32\lib\site-packages\scrapy\core\downloader\middleware.py", line 43, in process_request
    defer.returnValue((yield download_func(request=request,spider=spider)))
  File "c:\users\xkdlr\appdata\local\programs\python\python36-32\lib\site-packages\twisted\internet\defer.py", line 653, in _runCallbacks
    current.result = callback(current.result, *args, **kw)
  File "c:\users\xkdlr\appdata\local\programs\python\python36-32\lib\site-packages\scrapy\core\downloader\handlers\http11.py", line 320, in _cb_timeout
    raise TimeoutError("Getting %s took longer than %s seconds." % (url, timeout))
twisted.internet.error.TimeoutError: User timeout caused connection failure: Getting http://web.humoruniv.com/board/humor/list.html?table=guest&pg=7 took longer than 30.0 seconds..
2017-10-11 15:10:23 [scrapy.core.scraper] ERROR: Error downloading <GET http://web.humoruniv.com/board/humor/list.html?table=mild&pg=7>
Traceback (most recent call last):
  File "c:\users\xkdlr\appdata\local\programs\python\python36-32\lib\site-packages\twisted\internet\defer.py", line 1384, in _inlineCallbacks
    result = result.throwExceptionIntoGenerator(g)
  File "c:\users\xkdlr\appdata\local\programs\python\python36-32\lib\site-packages\twisted\python\failure.py", line 408, in throwExceptionIntoGenerator
    return g.throw(self.type, self.value, self.tb)
  File "c:\users\xkdlr\appdata\local\programs\python\python36-32\lib\site-packages\scrapy\core\downloader\middleware.py", line 43, in process_request
    defer.returnValue((yield download_func(request=request,spider=spider)))
  File "c:\users\xkdlr\appdata\local\programs\python\python36-32\lib\site-packages\twisted\internet\defer.py", line 653, in _runCallbacks
    current.result = callback(current.result, *args, **kw)
  File "c:\users\xkdlr\appdata\local\programs\python\python36-32\lib\site-packages\scrapy\core\downloader\handlers\http11.py", line 320, in _cb_timeout
    raise TimeoutError("Getting %s took longer than %s seconds." % (url, timeout))
twisted.internet.error.TimeoutError: User timeout caused connection failure: Getting http://web.humoruniv.com/board/humor/list.html?table=mild&pg=7 took longer than 30.0 seconds..
2017-10-11 15:10:23 [scrapy.core.scraper] ERROR: Error downloading <GET http://web.humoruniv.com/board/humor/list.html?table=lol&pg=7>
Traceback (most recent call last):
  File "c:\users\xkdlr\appdata\local\programs\python\python36-32\lib\site-packages\twisted\internet\defer.py", line 1384, in _inlineCallbacks
    result = result.throwExceptionIntoGenerator(g)
  File "c:\users\xkdlr\appdata\local\programs\python\python36-32\lib\site-packages\twisted\python\failure.py", line 408, in throwExceptionIntoGenerator
    return g.throw(self.type, self.value, self.tb)
  File "c:\users\xkdlr\appdata\local\programs\python\python36-32\lib\site-packages\scrapy\core\downloader\middleware.py", line 43, in process_request
    defer.returnValue((yield download_func(request=request,spider=spider)))
  File "c:\users\xkdlr\appdata\local\programs\python\python36-32\lib\site-packages\twisted\internet\defer.py", line 653, in _runCallbacks
    current.result = callback(current.result, *args, **kw)
  File "c:\users\xkdlr\appdata\local\programs\python\python36-32\lib\site-packages\scrapy\core\downloader\handlers\http11.py", line 320, in _cb_timeout
    raise TimeoutError("Getting %s took longer than %s seconds." % (url, timeout))
twisted.internet.error.TimeoutError: User timeout caused connection failure: Getting http://web.humoruniv.com/board/humor/list.html?table=lol&pg=7 took longer than 30.0 seconds..
2017-10-11 15:10:23 [scrapy.core.scraper] ERROR: Error downloading <GET http://web.humoruniv.com/board/humor/list.html?table=love&pg=7>
Traceback (most recent call last):
  File "c:\users\xkdlr\appdata\local\programs\python\python36-32\lib\site-packages\twisted\internet\defer.py", line 1384, in _inlineCallbacks
    result = result.throwExceptionIntoGenerator(g)
  File "c:\users\xkdlr\appdata\local\programs\python\python36-32\lib\site-packages\twisted\python\failure.py", line 408, in throwExceptionIntoGenerator
    return g.throw(self.type, self.value, self.tb)
  File "c:\users\xkdlr\appdata\local\programs\python\python36-32\lib\site-packages\scrapy\core\downloader\middleware.py", line 43, in process_request
    defer.returnValue((yield download_func(request=request,spider=spider)))
  File "c:\users\xkdlr\appdata\local\programs\python\python36-32\lib\site-packages\twisted\internet\defer.py", line 653, in _runCallbacks
    current.result = callback(current.result, *args, **kw)
  File "c:\users\xkdlr\appdata\local\programs\python\python36-32\lib\site-packages\scrapy\core\downloader\handlers\http11.py", line 320, in _cb_timeout
    raise TimeoutError("Getting %s took longer than %s seconds." % (url, timeout))
twisted.internet.error.TimeoutError: User timeout caused connection failure: Getting http://web.humoruniv.com/board/humor/list.html?table=love&pg=7 took longer than 30.0 seconds..
2017-10-11 15:10:31 [scrapy.core.scraper] ERROR: Error downloading <GET http://web.humoruniv.com/board/humor/list.html?table=pride&pg=7>: [<twisted.python.failure.Failure twisted.internet.error.ConnectionDone: Connection was closed cleanly.>]
2017-10-11 15:10:31 [scrapy.core.scraper] ERROR: Error downloading <GET http://web.humoruniv.com/board/humor/list.html?table=spnatural&pg=7>: [<twisted.python.failure.Failure twisted.internet.error.ConnectionDone: Connection was closed cleanly.>]
2017-10-11 15:10:31 [scrapy.core.scraper] ERROR: Error downloading <GET http://web.humoruniv.com/board/humor/list.html?table=muzik&pg=7>: [<twisted.python.failure.Failure twisted.internet.error.ConnectionDone: Connection was closed cleanly.>]
2017-10-11 15:10:43 [scrapy.core.scraper] ERROR: Error downloading <GET http://web.humoruniv.com/board/humor/list.html?table=sympathy&pg=7>: [<twisted.python.failure.Failure twisted.internet.error.ConnectionDone: Connection was closed cleanly.>]
2017-10-11 15:13:53 [scrapy.core.scraper] ERROR: Error downloading <GET http://web.humoruniv.com/board/humor/list.html?table=workshop&pg=7>: [<twisted.python.failure.Failure twisted.internet.error.ConnectionDone: Connection was closed cleanly.>]
2017-10-11 15:13:53 [scrapy.core.scraper] ERROR: Error downloading <GET http://web.humoruniv.com/board/humor/list.html?table=whitehand&pg=7>: [<twisted.python.failure.Failure twisted.internet.error.ConnectionDone: Connection was closed cleanly.>]
2017-10-11 15:13:53 [scrapy.core.scraper] ERROR: Error downloading <GET http://web.humoruniv.com/board/humor/list.html?table=moofama&pg=7>: [<twisted.python.failure.Failure twisted.internet.error.ConnectionDone: Connection was closed cleanly.>]
2017-10-11 15:13:55 [scrapy.core.scraper] ERROR: Error downloading <GET http://web.humoruniv.com/board/humor/list.html?table=solo&pg=7>
Traceback (most recent call last):
  File "c:\users\xkdlr\appdata\local\programs\python\python36-32\lib\site-packages\twisted\internet\defer.py", line 1384, in _inlineCallbacks
    result = result.throwExceptionIntoGenerator(g)
  File "c:\users\xkdlr\appdata\local\programs\python\python36-32\lib\site-packages\twisted\python\failure.py", line 408, in throwExceptionIntoGenerator
    return g.throw(self.type, self.value, self.tb)
  File "c:\users\xkdlr\appdata\local\programs\python\python36-32\lib\site-packages\scrapy\core\downloader\middleware.py", line 43, in process_request
    defer.returnValue((yield download_func(request=request,spider=spider)))
  File "c:\users\xkdlr\appdata\local\programs\python\python36-32\lib\site-packages\twisted\internet\defer.py", line 653, in _runCallbacks
    current.result = callback(current.result, *args, **kw)
  File "c:\users\xkdlr\appdata\local\programs\python\python36-32\lib\site-packages\scrapy\core\downloader\handlers\http11.py", line 320, in _cb_timeout
    raise TimeoutError("Getting %s took longer than %s seconds." % (url, timeout))
twisted.internet.error.TimeoutError: User timeout caused connection failure: Getting http://web.humoruniv.com/board/humor/list.html?table=solo&pg=7 took longer than 30.0 seconds..
2017-10-11 15:13:55 [scrapy.core.scraper] ERROR: Error downloading <GET http://web.humoruniv.com/board/humor/list.html?table=army&pg=8>
Traceback (most recent call last):
  File "c:\users\xkdlr\appdata\local\programs\python\python36-32\lib\site-packages\twisted\internet\defer.py", line 1384, in _inlineCallbacks
    result = result.throwExceptionIntoGenerator(g)
  File "c:\users\xkdlr\appdata\local\programs\python\python36-32\lib\site-packages\twisted\python\failure.py", line 408, in throwExceptionIntoGenerator
    return g.throw(self.type, self.value, self.tb)
  File "c:\users\xkdlr\appdata\local\programs\python\python36-32\lib\site-packages\scrapy\core\downloader\middleware.py", line 43, in process_request
    defer.returnValue((yield download_func(request=request,spider=spider)))
  File "c:\users\xkdlr\appdata\local\programs\python\python36-32\lib\site-packages\twisted\internet\defer.py", line 653, in _runCallbacks
    current.result = callback(current.result, *args, **kw)
  File "c:\users\xkdlr\appdata\local\programs\python\python36-32\lib\site-packages\scrapy\core\downloader\handlers\http11.py", line 320, in _cb_timeout
    raise TimeoutError("Getting %s took longer than %s seconds." % (url, timeout))
twisted.internet.error.TimeoutError: User timeout caused connection failure: Getting http://web.humoruniv.com/board/humor/list.html?table=army&pg=8 took longer than 30.0 seconds..
2017-10-11 15:14:04 [scrapy.core.scraper] ERROR: Error downloading <GET http://web.humoruniv.com/board/humor/list.html?table=program&pg=8>: User timeout caused connection failure.
