2017-10-11 23:00:36 [scrapy.core.scraper] ERROR: Error downloading <GET http://web.humoruniv.com/board/humor/list.html?table=love&pg=0>
Traceback (most recent call last):
  File "c:\users\xkdlr\appdata\local\programs\python\python36-32\lib\site-packages\twisted\internet\defer.py", line 1384, in _inlineCallbacks
    result = result.throwExceptionIntoGenerator(g)
  File "c:\users\xkdlr\appdata\local\programs\python\python36-32\lib\site-packages\twisted\python\failure.py", line 408, in throwExceptionIntoGenerator
    return g.throw(self.type, self.value, self.tb)
  File "c:\users\xkdlr\appdata\local\programs\python\python36-32\lib\site-packages\scrapy\core\downloader\middleware.py", line 43, in process_request
    defer.returnValue((yield download_func(request=request,spider=spider)))
  File "c:\users\xkdlr\appdata\local\programs\python\python36-32\lib\site-packages\twisted\internet\defer.py", line 653, in _runCallbacks
    current.result = callback(current.result, *args, **kw)
  File "c:\users\xkdlr\appdata\local\programs\python\python36-32\lib\site-packages\scrapy\core\downloader\handlers\http11.py", line 320, in _cb_timeout
    raise TimeoutError("Getting %s took longer than %s seconds." % (url, timeout))
twisted.internet.error.TimeoutError: User timeout caused connection failure: Getting http://web.humoruniv.com/board/humor/list.html?table=love&pg=0 took longer than 30.0 seconds..
2017-10-11 23:00:36 [scrapy.core.scraper] ERROR: Error downloading <GET http://web.humoruniv.com/board/humor/list.html?table=sns&pg=0>: [<twisted.python.failure.Failure twisted.internet.error.ConnectionDone: Connection was closed cleanly.>]
2017-10-11 23:00:36 [scrapy.core.scraper] ERROR: Error downloading <GET http://web.humoruniv.com/board/humor/list.html?table=spnatural&pg=0>: [<twisted.python.failure.Failure twisted.internet.error.ConnectionDone: Connection was closed cleanly.>]
2017-10-11 23:00:36 [scrapy.core.scraper] ERROR: Error downloading <GET http://web.humoruniv.com/board/humor/list.html?table=car&pg=0>: [<twisted.python.failure.Failure twisted.internet.error.ConnectionDone: Connection was closed cleanly.>]
2017-10-11 23:02:57 [scrapy.core.scraper] ERROR: Spider error processing <GET http://web.humoruniv.com/board/humor/list.html?table=game&pg=3> (referer: None)
Traceback (most recent call last):
  File "c:\users\xkdlr\appdata\local\programs\python\python36-32\lib\site-packages\urllib3\connection.py", line 141, in _new_conn
    (self.host, self.port), self.timeout, **extra_kw)
  File "c:\users\xkdlr\appdata\local\programs\python\python36-32\lib\site-packages\urllib3\util\connection.py", line 83, in create_connection
    raise err
  File "c:\users\xkdlr\appdata\local\programs\python\python36-32\lib\site-packages\urllib3\util\connection.py", line 73, in create_connection
    sock.connect(sa)
TimeoutError: [WinError 10060] 연결된 구성원으로부터 응답이 없어 연결하지 못했거나, 호스트로부터 응답이 없어 연결이 끊어졌습니다

During handling of the above exception, another exception occurred:

Traceback (most recent call last):
  File "c:\users\xkdlr\appdata\local\programs\python\python36-32\lib\site-packages\urllib3\connectionpool.py", line 601, in urlopen
    chunked=chunked)
  File "c:\users\xkdlr\appdata\local\programs\python\python36-32\lib\site-packages\urllib3\connectionpool.py", line 357, in _make_request
    conn.request(method, url, **httplib_request_kw)
  File "c:\users\xkdlr\appdata\local\programs\python\python36-32\lib\http\client.py", line 1239, in request
    self._send_request(method, url, body, headers, encode_chunked)
  File "c:\users\xkdlr\appdata\local\programs\python\python36-32\lib\http\client.py", line 1285, in _send_request
    self.endheaders(body, encode_chunked=encode_chunked)
  File "c:\users\xkdlr\appdata\local\programs\python\python36-32\lib\http\client.py", line 1234, in endheaders
    self._send_output(message_body, encode_chunked=encode_chunked)
  File "c:\users\xkdlr\appdata\local\programs\python\python36-32\lib\http\client.py", line 1026, in _send_output
    self.send(msg)
  File "c:\users\xkdlr\appdata\local\programs\python\python36-32\lib\http\client.py", line 964, in send
    self.connect()
  File "c:\users\xkdlr\appdata\local\programs\python\python36-32\lib\site-packages\urllib3\connection.py", line 166, in connect
    conn = self._new_conn()
  File "c:\users\xkdlr\appdata\local\programs\python\python36-32\lib\site-packages\urllib3\connection.py", line 150, in _new_conn
    self, "Failed to establish a new connection: %s" % e)
urllib3.exceptions.NewConnectionError: <urllib3.connection.HTTPConnection object at 0x073CF370>: Failed to establish a new connection: [WinError 10060] 연결된 구성원으로부터 응답이 없어 연결하지 못했거나, 호스트로부터 응답이 없어 연결이 끊어졌습니다

During handling of the above exception, another exception occurred:

Traceback (most recent call last):
  File "c:\users\xkdlr\appdata\local\programs\python\python36-32\lib\site-packages\requests\adapters.py", line 440, in send
    timeout=timeout
  File "c:\users\xkdlr\appdata\local\programs\python\python36-32\lib\site-packages\urllib3\connectionpool.py", line 639, in urlopen
    _stacktrace=sys.exc_info()[2])
  File "c:\users\xkdlr\appdata\local\programs\python\python36-32\lib\site-packages\urllib3\util\retry.py", line 388, in increment
    raise MaxRetryError(_pool, url, error or ResponseError(cause))
urllib3.exceptions.MaxRetryError: HTTPConnectionPool(host='web.humoruniv.com', port=80): Max retries exceeded with url: /board/humor/read.html?table=game&pg=3&number=2389663 (Caused by NewConnectionError('<urllib3.connection.HTTPConnection object at 0x073CF370>: Failed to establish a new connection: [WinError 10060] 연결된 구성원으로부터 응답이 없어 연결하지 못했거나, 호스트로부터 응답이 없어 연결이 끊어졌습니다',))

During handling of the above exception, another exception occurred:

Traceback (most recent call last):
  File "c:\users\xkdlr\appdata\local\programs\python\python36-32\lib\site-packages\scrapy\utils\defer.py", line 102, in iter_errback
    yield next(it)
  File "c:\users\xkdlr\appdata\local\programs\python\python36-32\lib\site-packages\scrapy\spidermiddlewares\offsite.py", line 29, in process_spider_output
    for x in result:
  File "c:\users\xkdlr\appdata\local\programs\python\python36-32\lib\site-packages\scrapy\spidermiddlewares\referer.py", line 339, in <genexpr>
    return (_set_referer(r) for r in result or ())
  File "c:\users\xkdlr\appdata\local\programs\python\python36-32\lib\site-packages\scrapy\spidermiddlewares\urllength.py", line 37, in <genexpr>
    return (r for r in result or () if _filter(r))
  File "c:\users\xkdlr\appdata\local\programs\python\python36-32\lib\site-packages\scrapy\spidermiddlewares\depth.py", line 58, in <genexpr>
    return (r for r in result or () if _filter(r))
  File "D:\CapstoneDesign\Damoa\Git_Crawler\DamoaCrawler\Crawler\spiders\HumorUniv.py", line 118, in parse_site
    item['text'] = createItemUseBs4(item['link'], tagName, tagAttr, encoding="CP949", texttype="")
  File "D:\CapstoneDesign\Damoa\Git_Crawler\DamoaCrawler\Crawler\CreateItem.py", line 32, in createItemUseBs4
    JoinPostUrl = BeautifulSoup(requests.get(url).content, "html.parser", from_encoding=encoding)
  File "c:\users\xkdlr\appdata\local\programs\python\python36-32\lib\site-packages\requests\api.py", line 72, in get
    return request('get', url, params=params, **kwargs)
  File "c:\users\xkdlr\appdata\local\programs\python\python36-32\lib\site-packages\requests\api.py", line 58, in request
    return session.request(method=method, url=url, **kwargs)
  File "c:\users\xkdlr\appdata\local\programs\python\python36-32\lib\site-packages\requests\sessions.py", line 508, in request
    resp = self.send(prep, **send_kwargs)
  File "c:\users\xkdlr\appdata\local\programs\python\python36-32\lib\site-packages\requests\sessions.py", line 618, in send
    r = adapter.send(request, **kwargs)
  File "c:\users\xkdlr\appdata\local\programs\python\python36-32\lib\site-packages\requests\adapters.py", line 508, in send
    raise ConnectionError(e, request=request)
requests.exceptions.ConnectionError: HTTPConnectionPool(host='web.humoruniv.com', port=80): Max retries exceeded with url: /board/humor/read.html?table=game&pg=3&number=2389663 (Caused by NewConnectionError('<urllib3.connection.HTTPConnection object at 0x073CF370>: Failed to establish a new connection: [WinError 10060] 연결된 구성원으로부터 응답이 없어 연결하지 못했거나, 호스트로부터 응답이 없어 연결이 끊어졌습니다',))
2017-10-11 23:03:12 [scrapy.core.scraper] ERROR: Error downloading <GET http://web.humoruniv.com/board/humor/list.html?table=thema2&pg=1>: [<twisted.python.failure.Failure twisted.internet.error.ConnectionDone: Connection was closed cleanly.>]
2017-10-11 23:03:12 [scrapy.core.scraper] ERROR: Error downloading <GET http://web.humoruniv.com/board/humor/list.html?table=poll&pg=1>: [<twisted.python.failure.Failure twisted.internet.error.ConnectionDone: Connection was closed cleanly.>]
2017-10-11 23:03:12 [scrapy.core.scraper] ERROR: Error downloading <GET http://web.humoruniv.com/board/humor/list.html?table=cabinet&pg=0>: [<twisted.python.failure.Failure twisted.internet.error.ConnectionDone: Connection was closed cleanly.>]
2017-10-11 23:03:19 [scrapy.core.scraper] ERROR: Error downloading <GET http://web.humoruniv.com/board/humor/list.html?table=pride&pg=1>
Traceback (most recent call last):
  File "c:\users\xkdlr\appdata\local\programs\python\python36-32\lib\site-packages\twisted\internet\defer.py", line 1384, in _inlineCallbacks
    result = result.throwExceptionIntoGenerator(g)
  File "c:\users\xkdlr\appdata\local\programs\python\python36-32\lib\site-packages\twisted\python\failure.py", line 408, in throwExceptionIntoGenerator
    return g.throw(self.type, self.value, self.tb)
  File "c:\users\xkdlr\appdata\local\programs\python\python36-32\lib\site-packages\scrapy\core\downloader\middleware.py", line 43, in process_request
    defer.returnValue((yield download_func(request=request,spider=spider)))
  File "c:\users\xkdlr\appdata\local\programs\python\python36-32\lib\site-packages\twisted\internet\defer.py", line 653, in _runCallbacks
    current.result = callback(current.result, *args, **kw)
  File "c:\users\xkdlr\appdata\local\programs\python\python36-32\lib\site-packages\scrapy\core\downloader\handlers\http11.py", line 320, in _cb_timeout
    raise TimeoutError("Getting %s took longer than %s seconds." % (url, timeout))
twisted.internet.error.TimeoutError: User timeout caused connection failure: Getting http://web.humoruniv.com/board/humor/list.html?table=pride&pg=1 took longer than 30.0 seconds..
2017-10-11 23:03:53 [scrapy.core.scraper] ERROR: Error downloading <GET http://web.humoruniv.com/board/humor/list.html?table=guest&pg=1>
Traceback (most recent call last):
  File "c:\users\xkdlr\appdata\local\programs\python\python36-32\lib\site-packages\twisted\internet\defer.py", line 1384, in _inlineCallbacks
    result = result.throwExceptionIntoGenerator(g)
  File "c:\users\xkdlr\appdata\local\programs\python\python36-32\lib\site-packages\twisted\python\failure.py", line 408, in throwExceptionIntoGenerator
    return g.throw(self.type, self.value, self.tb)
  File "c:\users\xkdlr\appdata\local\programs\python\python36-32\lib\site-packages\scrapy\core\downloader\middleware.py", line 43, in process_request
    defer.returnValue((yield download_func(request=request,spider=spider)))
  File "c:\users\xkdlr\appdata\local\programs\python\python36-32\lib\site-packages\twisted\internet\defer.py", line 653, in _runCallbacks
    current.result = callback(current.result, *args, **kw)
  File "c:\users\xkdlr\appdata\local\programs\python\python36-32\lib\site-packages\scrapy\core\downloader\handlers\http11.py", line 320, in _cb_timeout
    raise TimeoutError("Getting %s took longer than %s seconds." % (url, timeout))
twisted.internet.error.TimeoutError: User timeout caused connection failure: Getting http://web.humoruniv.com/board/humor/list.html?table=guest&pg=1 took longer than 30.0 seconds..
2017-10-11 23:03:53 [scrapy.core.scraper] ERROR: Error downloading <GET http://web.humoruniv.com/board/humor/list.html?table=free&pg=1>
Traceback (most recent call last):
  File "c:\users\xkdlr\appdata\local\programs\python\python36-32\lib\site-packages\twisted\internet\defer.py", line 1384, in _inlineCallbacks
    result = result.throwExceptionIntoGenerator(g)
  File "c:\users\xkdlr\appdata\local\programs\python\python36-32\lib\site-packages\twisted\python\failure.py", line 408, in throwExceptionIntoGenerator
    return g.throw(self.type, self.value, self.tb)
  File "c:\users\xkdlr\appdata\local\programs\python\python36-32\lib\site-packages\scrapy\core\downloader\middleware.py", line 43, in process_request
    defer.returnValue((yield download_func(request=request,spider=spider)))
  File "c:\users\xkdlr\appdata\local\programs\python\python36-32\lib\site-packages\twisted\internet\defer.py", line 653, in _runCallbacks
    current.result = callback(current.result, *args, **kw)
  File "c:\users\xkdlr\appdata\local\programs\python\python36-32\lib\site-packages\scrapy\core\downloader\handlers\http11.py", line 320, in _cb_timeout
    raise TimeoutError("Getting %s took longer than %s seconds." % (url, timeout))
twisted.internet.error.TimeoutError: User timeout caused connection failure: Getting http://web.humoruniv.com/board/humor/list.html?table=free&pg=1 took longer than 30.0 seconds..
2017-10-11 23:03:53 [scrapy.core.scraper] ERROR: Error downloading <GET http://web.humoruniv.com/board/humor/list.html?table=lol&pg=1>
Traceback (most recent call last):
  File "c:\users\xkdlr\appdata\local\programs\python\python36-32\lib\site-packages\twisted\internet\defer.py", line 1384, in _inlineCallbacks
    result = result.throwExceptionIntoGenerator(g)
  File "c:\users\xkdlr\appdata\local\programs\python\python36-32\lib\site-packages\twisted\python\failure.py", line 408, in throwExceptionIntoGenerator
    return g.throw(self.type, self.value, self.tb)
  File "c:\users\xkdlr\appdata\local\programs\python\python36-32\lib\site-packages\scrapy\core\downloader\middleware.py", line 43, in process_request
    defer.returnValue((yield download_func(request=request,spider=spider)))
  File "c:\users\xkdlr\appdata\local\programs\python\python36-32\lib\site-packages\twisted\internet\defer.py", line 653, in _runCallbacks
    current.result = callback(current.result, *args, **kw)
  File "c:\users\xkdlr\appdata\local\programs\python\python36-32\lib\site-packages\scrapy\core\downloader\handlers\http11.py", line 320, in _cb_timeout
    raise TimeoutError("Getting %s took longer than %s seconds." % (url, timeout))
twisted.internet.error.TimeoutError: User timeout caused connection failure: Getting http://web.humoruniv.com/board/humor/list.html?table=lol&pg=1 took longer than 30.0 seconds..
2017-10-11 23:03:53 [scrapy.core.scraper] ERROR: Error downloading <GET http://web.humoruniv.com/board/humor/list.html?table=mild&pg=1>
Traceback (most recent call last):
  File "c:\users\xkdlr\appdata\local\programs\python\python36-32\lib\site-packages\twisted\internet\defer.py", line 1384, in _inlineCallbacks
    result = result.throwExceptionIntoGenerator(g)
  File "c:\users\xkdlr\appdata\local\programs\python\python36-32\lib\site-packages\twisted\python\failure.py", line 408, in throwExceptionIntoGenerator
    return g.throw(self.type, self.value, self.tb)
  File "c:\users\xkdlr\appdata\local\programs\python\python36-32\lib\site-packages\scrapy\core\downloader\middleware.py", line 43, in process_request
    defer.returnValue((yield download_func(request=request,spider=spider)))
  File "c:\users\xkdlr\appdata\local\programs\python\python36-32\lib\site-packages\twisted\internet\defer.py", line 653, in _runCallbacks
    current.result = callback(current.result, *args, **kw)
  File "c:\users\xkdlr\appdata\local\programs\python\python36-32\lib\site-packages\scrapy\core\downloader\handlers\http11.py", line 320, in _cb_timeout
    raise TimeoutError("Getting %s took longer than %s seconds." % (url, timeout))
twisted.internet.error.TimeoutError: User timeout caused connection failure: Getting http://web.humoruniv.com/board/humor/list.html?table=mild&pg=1 took longer than 30.0 seconds..
2017-10-11 23:04:38 [scrapy.core.scraper] ERROR: Error downloading <GET http://web.humoruniv.com/board/humor/list.html?table=thema3&pg=1>
Traceback (most recent call last):
  File "c:\users\xkdlr\appdata\local\programs\python\python36-32\lib\site-packages\twisted\internet\defer.py", line 1384, in _inlineCallbacks
    result = result.throwExceptionIntoGenerator(g)
  File "c:\users\xkdlr\appdata\local\programs\python\python36-32\lib\site-packages\twisted\python\failure.py", line 408, in throwExceptionIntoGenerator
    return g.throw(self.type, self.value, self.tb)
  File "c:\users\xkdlr\appdata\local\programs\python\python36-32\lib\site-packages\scrapy\core\downloader\middleware.py", line 43, in process_request
    defer.returnValue((yield download_func(request=request,spider=spider)))
  File "c:\users\xkdlr\appdata\local\programs\python\python36-32\lib\site-packages\twisted\internet\defer.py", line 653, in _runCallbacks
    current.result = callback(current.result, *args, **kw)
  File "c:\users\xkdlr\appdata\local\programs\python\python36-32\lib\site-packages\scrapy\core\downloader\handlers\http11.py", line 320, in _cb_timeout
    raise TimeoutError("Getting %s took longer than %s seconds." % (url, timeout))
twisted.internet.error.TimeoutError: User timeout caused connection failure: Getting http://web.humoruniv.com/board/humor/list.html?table=thema3&pg=1 took longer than 30.0 seconds..
2017-10-11 23:05:24 [scrapy.core.scraper] ERROR: Error downloading <GET http://web.humoruniv.com/board/humor/list.html?table=whitehand&pg=1>
Traceback (most recent call last):
  File "c:\users\xkdlr\appdata\local\programs\python\python36-32\lib\site-packages\twisted\internet\defer.py", line 1384, in _inlineCallbacks
    result = result.throwExceptionIntoGenerator(g)
  File "c:\users\xkdlr\appdata\local\programs\python\python36-32\lib\site-packages\twisted\python\failure.py", line 408, in throwExceptionIntoGenerator
    return g.throw(self.type, self.value, self.tb)
  File "c:\users\xkdlr\appdata\local\programs\python\python36-32\lib\site-packages\scrapy\core\downloader\middleware.py", line 43, in process_request
    defer.returnValue((yield download_func(request=request,spider=spider)))
  File "c:\users\xkdlr\appdata\local\programs\python\python36-32\lib\site-packages\twisted\internet\defer.py", line 653, in _runCallbacks
    current.result = callback(current.result, *args, **kw)
  File "c:\users\xkdlr\appdata\local\programs\python\python36-32\lib\site-packages\scrapy\core\downloader\handlers\http11.py", line 320, in _cb_timeout
    raise TimeoutError("Getting %s took longer than %s seconds." % (url, timeout))
twisted.internet.error.TimeoutError: User timeout caused connection failure: Getting http://web.humoruniv.com/board/humor/list.html?table=whitehand&pg=1 took longer than 30.0 seconds..
2017-10-11 23:05:24 [scrapy.core.scraper] ERROR: Error downloading <GET http://web.humoruniv.com/board/humor/list.html?table=solo&pg=1>
Traceback (most recent call last):
  File "c:\users\xkdlr\appdata\local\programs\python\python36-32\lib\site-packages\twisted\internet\defer.py", line 1384, in _inlineCallbacks
    result = result.throwExceptionIntoGenerator(g)
  File "c:\users\xkdlr\appdata\local\programs\python\python36-32\lib\site-packages\twisted\python\failure.py", line 408, in throwExceptionIntoGenerator
    return g.throw(self.type, self.value, self.tb)
  File "c:\users\xkdlr\appdata\local\programs\python\python36-32\lib\site-packages\scrapy\core\downloader\middleware.py", line 43, in process_request
    defer.returnValue((yield download_func(request=request,spider=spider)))
  File "c:\users\xkdlr\appdata\local\programs\python\python36-32\lib\site-packages\twisted\internet\defer.py", line 653, in _runCallbacks
    current.result = callback(current.result, *args, **kw)
  File "c:\users\xkdlr\appdata\local\programs\python\python36-32\lib\site-packages\scrapy\core\downloader\handlers\http11.py", line 320, in _cb_timeout
    raise TimeoutError("Getting %s took longer than %s seconds." % (url, timeout))
twisted.internet.error.TimeoutError: User timeout caused connection failure: Getting http://web.humoruniv.com/board/humor/list.html?table=solo&pg=1 took longer than 30.0 seconds..
2017-10-11 23:05:24 [scrapy.core.scraper] ERROR: Error downloading <GET http://web.humoruniv.com/board/humor/list.html?table=moofama&pg=1>
Traceback (most recent call last):
  File "c:\users\xkdlr\appdata\local\programs\python\python36-32\lib\site-packages\twisted\internet\defer.py", line 1384, in _inlineCallbacks
    result = result.throwExceptionIntoGenerator(g)
  File "c:\users\xkdlr\appdata\local\programs\python\python36-32\lib\site-packages\twisted\python\failure.py", line 408, in throwExceptionIntoGenerator
    return g.throw(self.type, self.value, self.tb)
  File "c:\users\xkdlr\appdata\local\programs\python\python36-32\lib\site-packages\scrapy\core\downloader\middleware.py", line 43, in process_request
    defer.returnValue((yield download_func(request=request,spider=spider)))
  File "c:\users\xkdlr\appdata\local\programs\python\python36-32\lib\site-packages\twisted\internet\defer.py", line 653, in _runCallbacks
    current.result = callback(current.result, *args, **kw)
  File "c:\users\xkdlr\appdata\local\programs\python\python36-32\lib\site-packages\scrapy\core\downloader\handlers\http11.py", line 320, in _cb_timeout
    raise TimeoutError("Getting %s took longer than %s seconds." % (url, timeout))
twisted.internet.error.TimeoutError: User timeout caused connection failure: Getting http://web.humoruniv.com/board/humor/list.html?table=moofama&pg=1 took longer than 30.0 seconds..
2017-10-11 23:05:24 [scrapy.core.scraper] ERROR: Error downloading <GET http://web.humoruniv.com/board/humor/list.html?table=workshop&pg=1>
Traceback (most recent call last):
  File "c:\users\xkdlr\appdata\local\programs\python\python36-32\lib\site-packages\twisted\internet\defer.py", line 1384, in _inlineCallbacks
    result = result.throwExceptionIntoGenerator(g)
  File "c:\users\xkdlr\appdata\local\programs\python\python36-32\lib\site-packages\twisted\python\failure.py", line 408, in throwExceptionIntoGenerator
    return g.throw(self.type, self.value, self.tb)
  File "c:\users\xkdlr\appdata\local\programs\python\python36-32\lib\site-packages\scrapy\core\downloader\middleware.py", line 43, in process_request
    defer.returnValue((yield download_func(request=request,spider=spider)))
  File "c:\users\xkdlr\appdata\local\programs\python\python36-32\lib\site-packages\twisted\internet\defer.py", line 653, in _runCallbacks
    current.result = callback(current.result, *args, **kw)
  File "c:\users\xkdlr\appdata\local\programs\python\python36-32\lib\site-packages\scrapy\core\downloader\handlers\http11.py", line 320, in _cb_timeout
    raise TimeoutError("Getting %s took longer than %s seconds." % (url, timeout))
twisted.internet.error.TimeoutError: User timeout caused connection failure: Getting http://web.humoruniv.com/board/humor/list.html?table=workshop&pg=1 took longer than 30.0 seconds..
2017-10-11 23:05:46 [scrapy.core.scraper] ERROR: Error downloading <GET http://web.humoruniv.com/board/humor/list.html?table=spnatural&pg=1>: [<twisted.python.failure.Failure twisted.internet.error.ConnectionDone: Connection was closed cleanly.>]
2017-10-11 23:05:46 [scrapy.core.scraper] ERROR: Error downloading <GET http://web.humoruniv.com/board/humor/list.html?table=dump&pg=1>: [<twisted.python.failure.Failure twisted.internet.error.ConnectionDone: Connection was closed cleanly.>]
2017-10-11 23:05:46 [scrapy.core.scraper] ERROR: Error downloading <GET http://web.humoruniv.com/board/humor/list.html?table=sns&pg=1>: [<twisted.python.failure.Failure twisted.internet.error.ConnectionDone: Connection was closed cleanly.>]
2017-10-11 23:05:46 [scrapy.core.scraper] ERROR: Error downloading <GET http://web.humoruniv.com/board/humor/list.html?table=memory&pg=1>: [<twisted.python.failure.Failure twisted.internet.error.ConnectionDone: Connection was closed cleanly.>]
2017-10-11 23:05:46 [scrapy.core.scraper] ERROR: Error downloading <GET http://web.humoruniv.com/board/humor/list.html?table=studying&pg=1>: [<twisted.python.failure.Failure twisted.internet.error.ConnectionDone: Connection was closed cleanly.>]
2017-10-11 23:07:01 [scrapy.core.scraper] ERROR: Error downloading <GET http://web.humoruniv.com/board/humor/list.html?table=phone&pg=1>
Traceback (most recent call last):
  File "c:\users\xkdlr\appdata\local\programs\python\python36-32\lib\site-packages\twisted\internet\defer.py", line 1384, in _inlineCallbacks
    result = result.throwExceptionIntoGenerator(g)
  File "c:\users\xkdlr\appdata\local\programs\python\python36-32\lib\site-packages\twisted\python\failure.py", line 408, in throwExceptionIntoGenerator
    return g.throw(self.type, self.value, self.tb)
  File "c:\users\xkdlr\appdata\local\programs\python\python36-32\lib\site-packages\scrapy\core\downloader\middleware.py", line 43, in process_request
    defer.returnValue((yield download_func(request=request,spider=spider)))
  File "c:\users\xkdlr\appdata\local\programs\python\python36-32\lib\site-packages\twisted\internet\defer.py", line 653, in _runCallbacks
    current.result = callback(current.result, *args, **kw)
  File "c:\users\xkdlr\appdata\local\programs\python\python36-32\lib\site-packages\scrapy\core\downloader\handlers\http11.py", line 320, in _cb_timeout
    raise TimeoutError("Getting %s took longer than %s seconds." % (url, timeout))
twisted.internet.error.TimeoutError: User timeout caused connection failure: Getting http://web.humoruniv.com/board/humor/list.html?table=phone&pg=1 took longer than 30.0 seconds..
2017-10-11 23:07:01 [scrapy.core.scraper] ERROR: Error downloading <GET http://web.humoruniv.com/board/humor/list.html?table=army&pg=1>
Traceback (most recent call last):
  File "c:\users\xkdlr\appdata\local\programs\python\python36-32\lib\site-packages\twisted\internet\defer.py", line 1384, in _inlineCallbacks
    result = result.throwExceptionIntoGenerator(g)
  File "c:\users\xkdlr\appdata\local\programs\python\python36-32\lib\site-packages\twisted\python\failure.py", line 408, in throwExceptionIntoGenerator
    return g.throw(self.type, self.value, self.tb)
  File "c:\users\xkdlr\appdata\local\programs\python\python36-32\lib\site-packages\scrapy\core\downloader\middleware.py", line 43, in process_request
    defer.returnValue((yield download_func(request=request,spider=spider)))
  File "c:\users\xkdlr\appdata\local\programs\python\python36-32\lib\site-packages\twisted\internet\defer.py", line 653, in _runCallbacks
    current.result = callback(current.result, *args, **kw)
  File "c:\users\xkdlr\appdata\local\programs\python\python36-32\lib\site-packages\scrapy\core\downloader\handlers\http11.py", line 320, in _cb_timeout
    raise TimeoutError("Getting %s took longer than %s seconds." % (url, timeout))
twisted.internet.error.TimeoutError: User timeout caused connection failure: Getting http://web.humoruniv.com/board/humor/list.html?table=army&pg=1 took longer than 30.0 seconds..
2017-10-11 23:07:05 [scrapy.core.scraper] ERROR: Error downloading <GET http://web.humoruniv.com//board/humor/list.html?table=nova_toon&pg=2>: [<twisted.python.failure.Failure twisted.internet.error.ConnectionDone: Connection was closed cleanly.>]
2017-10-11 23:07:05 [scrapy.core.scraper] ERROR: Error downloading <GET http://web.humoruniv.com/board/humor/list.html?table=fear&pg=2>: [<twisted.python.failure.Failure twisted.internet.error.ConnectionDone: Connection was closed cleanly.>]
2017-10-11 23:07:07 [scrapy.core.scraper] ERROR: Error downloading <GET http://web.humoruniv.com//board/humor/list.html?table=otl&pg=2>
Traceback (most recent call last):
  File "c:\users\xkdlr\appdata\local\programs\python\python36-32\lib\site-packages\twisted\internet\defer.py", line 1384, in _inlineCallbacks
    result = result.throwExceptionIntoGenerator(g)
  File "c:\users\xkdlr\appdata\local\programs\python\python36-32\lib\site-packages\twisted\python\failure.py", line 408, in throwExceptionIntoGenerator
    return g.throw(self.type, self.value, self.tb)
  File "c:\users\xkdlr\appdata\local\programs\python\python36-32\lib\site-packages\scrapy\core\downloader\middleware.py", line 43, in process_request
    defer.returnValue((yield download_func(request=request,spider=spider)))
  File "c:\users\xkdlr\appdata\local\programs\python\python36-32\lib\site-packages\twisted\internet\defer.py", line 653, in _runCallbacks
    current.result = callback(current.result, *args, **kw)
  File "c:\users\xkdlr\appdata\local\programs\python\python36-32\lib\site-packages\scrapy\core\downloader\handlers\http11.py", line 320, in _cb_timeout
    raise TimeoutError("Getting %s took longer than %s seconds." % (url, timeout))
twisted.internet.error.TimeoutError: User timeout caused connection failure: Getting http://web.humoruniv.com//board/humor/list.html?table=otl&pg=2 took longer than 30.0 seconds..
2017-10-11 23:07:39 [scrapy.core.scraper] ERROR: Error downloading <GET http://web.humoruniv.com//board/humor/list.html?table=art_toon&pg=2>
Traceback (most recent call last):
  File "c:\users\xkdlr\appdata\local\programs\python\python36-32\lib\site-packages\twisted\internet\defer.py", line 1384, in _inlineCallbacks
    result = result.throwExceptionIntoGenerator(g)
  File "c:\users\xkdlr\appdata\local\programs\python\python36-32\lib\site-packages\twisted\python\failure.py", line 408, in throwExceptionIntoGenerator
    return g.throw(self.type, self.value, self.tb)
  File "c:\users\xkdlr\appdata\local\programs\python\python36-32\lib\site-packages\scrapy\core\downloader\middleware.py", line 43, in process_request
    defer.returnValue((yield download_func(request=request,spider=spider)))
  File "c:\users\xkdlr\appdata\local\programs\python\python36-32\lib\site-packages\twisted\internet\defer.py", line 653, in _runCallbacks
    current.result = callback(current.result, *args, **kw)
  File "c:\users\xkdlr\appdata\local\programs\python\python36-32\lib\site-packages\scrapy\core\downloader\handlers\http11.py", line 320, in _cb_timeout
    raise TimeoutError("Getting %s took longer than %s seconds." % (url, timeout))
twisted.internet.error.TimeoutError: User timeout caused connection failure: Getting http://web.humoruniv.com//board/humor/list.html?table=art_toon&pg=2 took longer than 30.0 seconds..
2017-10-11 23:12:26 [scrapy.core.scraper] ERROR: Error downloading <GET http://web.humoruniv.com/board/humor/list.html?table=love&pg=2>: [<twisted.python.failure.Failure twisted.internet.error.ConnectionDone: Connection was closed cleanly.>]
2017-10-11 23:12:26 [scrapy.core.scraper] ERROR: Error downloading <GET http://web.humoruniv.com/board/humor/list.html?table=solo&pg=2>
Traceback (most recent call last):
  File "c:\users\xkdlr\appdata\local\programs\python\python36-32\lib\site-packages\twisted\internet\defer.py", line 1384, in _inlineCallbacks
    result = result.throwExceptionIntoGenerator(g)
  File "c:\users\xkdlr\appdata\local\programs\python\python36-32\lib\site-packages\twisted\python\failure.py", line 408, in throwExceptionIntoGenerator
    return g.throw(self.type, self.value, self.tb)
  File "c:\users\xkdlr\appdata\local\programs\python\python36-32\lib\site-packages\scrapy\core\downloader\middleware.py", line 43, in process_request
    defer.returnValue((yield download_func(request=request,spider=spider)))
  File "c:\users\xkdlr\appdata\local\programs\python\python36-32\lib\site-packages\twisted\internet\defer.py", line 653, in _runCallbacks
    current.result = callback(current.result, *args, **kw)
  File "c:\users\xkdlr\appdata\local\programs\python\python36-32\lib\site-packages\scrapy\core\downloader\handlers\http11.py", line 320, in _cb_timeout
    raise TimeoutError("Getting %s took longer than %s seconds." % (url, timeout))
twisted.internet.error.TimeoutError: User timeout caused connection failure: Getting http://web.humoruniv.com/board/humor/list.html?table=solo&pg=2 took longer than 30.0 seconds..
2017-10-11 23:12:35 [scrapy.core.scraper] ERROR: Error downloading <GET http://web.humoruniv.com/board/humor/list.html?table=spnatural&pg=2>
Traceback (most recent call last):
  File "c:\users\xkdlr\appdata\local\programs\python\python36-32\lib\site-packages\twisted\internet\defer.py", line 1384, in _inlineCallbacks
    result = result.throwExceptionIntoGenerator(g)
  File "c:\users\xkdlr\appdata\local\programs\python\python36-32\lib\site-packages\twisted\python\failure.py", line 408, in throwExceptionIntoGenerator
    return g.throw(self.type, self.value, self.tb)
  File "c:\users\xkdlr\appdata\local\programs\python\python36-32\lib\site-packages\scrapy\core\downloader\middleware.py", line 43, in process_request
    defer.returnValue((yield download_func(request=request,spider=spider)))
  File "c:\users\xkdlr\appdata\local\programs\python\python36-32\lib\site-packages\twisted\internet\defer.py", line 653, in _runCallbacks
    current.result = callback(current.result, *args, **kw)
  File "c:\users\xkdlr\appdata\local\programs\python\python36-32\lib\site-packages\scrapy\core\downloader\handlers\http11.py", line 320, in _cb_timeout
    raise TimeoutError("Getting %s took longer than %s seconds." % (url, timeout))
twisted.internet.error.TimeoutError: User timeout caused connection failure: Getting http://web.humoruniv.com/board/humor/list.html?table=spnatural&pg=2 took longer than 30.0 seconds..
2017-10-11 23:13:10 [scrapy.core.scraper] ERROR: Error downloading <GET http://web.humoruniv.com/board/humor/list.html?table=sns&pg=2>: [<twisted.python.failure.Failure twisted.internet.error.ConnectionDone: Connection was closed cleanly.>]
2017-10-11 23:15:10 [scrapy.core.scraper] ERROR: Error downloading <GET http://web.humoruniv.com/board/humor/list.html?table=thema2&pg=3>: [<twisted.python.failure.Failure twisted.internet.error.ConnectionDone: Connection was closed cleanly.>]
2017-10-11 23:15:10 [scrapy.core.scraper] ERROR: Error downloading <GET http://web.humoruniv.com/board/humor/list.html?table=animaluniv&pg=3>: [<twisted.python.failure.Failure twisted.internet.error.ConnectionDone: Connection was closed cleanly.>]
2017-10-11 23:15:23 [scrapy.core.scraper] ERROR: Error downloading <GET http://web.humoruniv.com/board/humor/list.html?table=moofama&pg=3>
Traceback (most recent call last):
  File "c:\users\xkdlr\appdata\local\programs\python\python36-32\lib\site-packages\twisted\internet\defer.py", line 1384, in _inlineCallbacks
    result = result.throwExceptionIntoGenerator(g)
  File "c:\users\xkdlr\appdata\local\programs\python\python36-32\lib\site-packages\twisted\python\failure.py", line 408, in throwExceptionIntoGenerator
    return g.throw(self.type, self.value, self.tb)
  File "c:\users\xkdlr\appdata\local\programs\python\python36-32\lib\site-packages\scrapy\core\downloader\middleware.py", line 43, in process_request
    defer.returnValue((yield download_func(request=request,spider=spider)))
  File "c:\users\xkdlr\appdata\local\programs\python\python36-32\lib\site-packages\twisted\internet\defer.py", line 653, in _runCallbacks
    current.result = callback(current.result, *args, **kw)
  File "c:\users\xkdlr\appdata\local\programs\python\python36-32\lib\site-packages\scrapy\core\downloader\handlers\http11.py", line 320, in _cb_timeout
    raise TimeoutError("Getting %s took longer than %s seconds." % (url, timeout))
twisted.internet.error.TimeoutError: User timeout caused connection failure: Getting http://web.humoruniv.com/board/humor/list.html?table=moofama&pg=3 took longer than 30.0 seconds..
2017-10-11 23:15:23 [scrapy.core.scraper] ERROR: Error downloading <GET http://web.humoruniv.com/board/humor/list.html?table=lol&pg=3>
Traceback (most recent call last):
  File "c:\users\xkdlr\appdata\local\programs\python\python36-32\lib\site-packages\twisted\internet\defer.py", line 1384, in _inlineCallbacks
    result = result.throwExceptionIntoGenerator(g)
  File "c:\users\xkdlr\appdata\local\programs\python\python36-32\lib\site-packages\twisted\python\failure.py", line 408, in throwExceptionIntoGenerator
    return g.throw(self.type, self.value, self.tb)
  File "c:\users\xkdlr\appdata\local\programs\python\python36-32\lib\site-packages\scrapy\core\downloader\middleware.py", line 43, in process_request
    defer.returnValue((yield download_func(request=request,spider=spider)))
  File "c:\users\xkdlr\appdata\local\programs\python\python36-32\lib\site-packages\twisted\internet\defer.py", line 653, in _runCallbacks
    current.result = callback(current.result, *args, **kw)
  File "c:\users\xkdlr\appdata\local\programs\python\python36-32\lib\site-packages\scrapy\core\downloader\handlers\http11.py", line 320, in _cb_timeout
    raise TimeoutError("Getting %s took longer than %s seconds." % (url, timeout))
twisted.internet.error.TimeoutError: User timeout caused connection failure: Getting http://web.humoruniv.com/board/humor/list.html?table=lol&pg=3 took longer than 30.0 seconds..
2017-10-11 23:15:37 [scrapy.core.scraper] ERROR: Error downloading <GET http://web.humoruniv.com/board/humor/list.html?table=pride&pg=3>
Traceback (most recent call last):
  File "c:\users\xkdlr\appdata\local\programs\python\python36-32\lib\site-packages\twisted\internet\defer.py", line 1384, in _inlineCallbacks
    result = result.throwExceptionIntoGenerator(g)
  File "c:\users\xkdlr\appdata\local\programs\python\python36-32\lib\site-packages\twisted\python\failure.py", line 408, in throwExceptionIntoGenerator
    return g.throw(self.type, self.value, self.tb)
  File "c:\users\xkdlr\appdata\local\programs\python\python36-32\lib\site-packages\scrapy\core\downloader\middleware.py", line 43, in process_request
    defer.returnValue((yield download_func(request=request,spider=spider)))
  File "c:\users\xkdlr\appdata\local\programs\python\python36-32\lib\site-packages\twisted\internet\defer.py", line 653, in _runCallbacks
    current.result = callback(current.result, *args, **kw)
  File "c:\users\xkdlr\appdata\local\programs\python\python36-32\lib\site-packages\scrapy\core\downloader\handlers\http11.py", line 320, in _cb_timeout
    raise TimeoutError("Getting %s took longer than %s seconds." % (url, timeout))
twisted.internet.error.TimeoutError: User timeout caused connection failure: Getting http://web.humoruniv.com/board/humor/list.html?table=pride&pg=3 took longer than 30.0 seconds..
2017-10-11 23:15:40 [scrapy.core.scraper] ERROR: Error downloading <GET http://web.humoruniv.com/board/humor/list.html?table=thema3&pg=3>: [<twisted.python.failure.Failure twisted.internet.error.ConnectionDone: Connection was closed cleanly.>]
2017-10-11 23:16:00 [scrapy.core.scraper] ERROR: Error downloading <GET http://web.humoruniv.com/board/humor/list.html?table=spnatural&pg=3>
Traceback (most recent call last):
  File "c:\users\xkdlr\appdata\local\programs\python\python36-32\lib\site-packages\twisted\internet\defer.py", line 1384, in _inlineCallbacks
    result = result.throwExceptionIntoGenerator(g)
  File "c:\users\xkdlr\appdata\local\programs\python\python36-32\lib\site-packages\twisted\python\failure.py", line 408, in throwExceptionIntoGenerator
    return g.throw(self.type, self.value, self.tb)
  File "c:\users\xkdlr\appdata\local\programs\python\python36-32\lib\site-packages\scrapy\core\downloader\middleware.py", line 43, in process_request
    defer.returnValue((yield download_func(request=request,spider=spider)))
  File "c:\users\xkdlr\appdata\local\programs\python\python36-32\lib\site-packages\twisted\internet\defer.py", line 653, in _runCallbacks
    current.result = callback(current.result, *args, **kw)
  File "c:\users\xkdlr\appdata\local\programs\python\python36-32\lib\site-packages\scrapy\core\downloader\handlers\http11.py", line 320, in _cb_timeout
    raise TimeoutError("Getting %s took longer than %s seconds." % (url, timeout))
twisted.internet.error.TimeoutError: User timeout caused connection failure: Getting http://web.humoruniv.com/board/humor/list.html?table=spnatural&pg=3 took longer than 30.0 seconds..
2017-10-11 23:16:03 [scrapy.core.scraper] ERROR: Error downloading <GET http://web.humoruniv.com/board/humor/list.html?table=solo&pg=3>: [<twisted.python.failure.Failure twisted.internet.error.ConnectionDone: Connection was closed cleanly.>]
2017-10-11 23:16:21 [scrapy.core.scraper] ERROR: Error downloading <GET http://web.humoruniv.com/board/humor/list.html?table=whitehand&pg=3>: [<twisted.python.failure.Failure twisted.internet.error.ConnectionDone: Connection was closed cleanly.>]
2017-10-11 23:16:28 [scrapy.core.scraper] ERROR: Error downloading <GET http://web.humoruniv.com/board/humor/list.html?table=workshop&pg=3>
Traceback (most recent call last):
  File "c:\users\xkdlr\appdata\local\programs\python\python36-32\lib\site-packages\twisted\internet\defer.py", line 1384, in _inlineCallbacks
    result = result.throwExceptionIntoGenerator(g)
  File "c:\users\xkdlr\appdata\local\programs\python\python36-32\lib\site-packages\twisted\python\failure.py", line 408, in throwExceptionIntoGenerator
    return g.throw(self.type, self.value, self.tb)
  File "c:\users\xkdlr\appdata\local\programs\python\python36-32\lib\site-packages\scrapy\core\downloader\middleware.py", line 43, in process_request
    defer.returnValue((yield download_func(request=request,spider=spider)))
  File "c:\users\xkdlr\appdata\local\programs\python\python36-32\lib\site-packages\twisted\internet\defer.py", line 653, in _runCallbacks
    current.result = callback(current.result, *args, **kw)
  File "c:\users\xkdlr\appdata\local\programs\python\python36-32\lib\site-packages\scrapy\core\downloader\handlers\http11.py", line 320, in _cb_timeout
    raise TimeoutError("Getting %s took longer than %s seconds." % (url, timeout))
twisted.internet.error.TimeoutError: User timeout caused connection failure: Getting http://web.humoruniv.com/board/humor/list.html?table=workshop&pg=3 took longer than 30.0 seconds..
2017-10-11 23:16:31 [scrapy.core.scraper] ERROR: Error downloading <GET http://web.humoruniv.com/board/humor/list.html?table=sns&pg=3>
Traceback (most recent call last):
  File "c:\users\xkdlr\appdata\local\programs\python\python36-32\lib\site-packages\twisted\internet\defer.py", line 1384, in _inlineCallbacks
    result = result.throwExceptionIntoGenerator(g)
  File "c:\users\xkdlr\appdata\local\programs\python\python36-32\lib\site-packages\twisted\python\failure.py", line 408, in throwExceptionIntoGenerator
    return g.throw(self.type, self.value, self.tb)
  File "c:\users\xkdlr\appdata\local\programs\python\python36-32\lib\site-packages\scrapy\core\downloader\middleware.py", line 43, in process_request
    defer.returnValue((yield download_func(request=request,spider=spider)))
  File "c:\users\xkdlr\appdata\local\programs\python\python36-32\lib\site-packages\twisted\internet\defer.py", line 653, in _runCallbacks
    current.result = callback(current.result, *args, **kw)
  File "c:\users\xkdlr\appdata\local\programs\python\python36-32\lib\site-packages\scrapy\core\downloader\handlers\http11.py", line 320, in _cb_timeout
    raise TimeoutError("Getting %s took longer than %s seconds." % (url, timeout))
twisted.internet.error.TimeoutError: User timeout caused connection failure: Getting http://web.humoruniv.com/board/humor/list.html?table=sns&pg=3 took longer than 30.0 seconds..
2017-10-11 23:18:46 [scrapy.core.scraper] ERROR: Error downloading <GET http://web.humoruniv.com//board/humor/list.html?table=art_toon&pg=4>
Traceback (most recent call last):
  File "c:\users\xkdlr\appdata\local\programs\python\python36-32\lib\site-packages\twisted\internet\defer.py", line 1384, in _inlineCallbacks
    result = result.throwExceptionIntoGenerator(g)
  File "c:\users\xkdlr\appdata\local\programs\python\python36-32\lib\site-packages\twisted\python\failure.py", line 408, in throwExceptionIntoGenerator
    return g.throw(self.type, self.value, self.tb)
  File "c:\users\xkdlr\appdata\local\programs\python\python36-32\lib\site-packages\scrapy\core\downloader\middleware.py", line 43, in process_request
    defer.returnValue((yield download_func(request=request,spider=spider)))
  File "c:\users\xkdlr\appdata\local\programs\python\python36-32\lib\site-packages\twisted\internet\defer.py", line 653, in _runCallbacks
    current.result = callback(current.result, *args, **kw)
  File "c:\users\xkdlr\appdata\local\programs\python\python36-32\lib\site-packages\scrapy\core\downloader\handlers\http11.py", line 320, in _cb_timeout
    raise TimeoutError("Getting %s took longer than %s seconds." % (url, timeout))
twisted.internet.error.TimeoutError: User timeout caused connection failure: Getting http://web.humoruniv.com//board/humor/list.html?table=art_toon&pg=4 took longer than 30.0 seconds..
2017-10-11 23:18:46 [scrapy.core.scraper] ERROR: Error downloading <GET http://web.humoruniv.com//board/humor/list.html?table=kin&pg=4>
Traceback (most recent call last):
  File "c:\users\xkdlr\appdata\local\programs\python\python36-32\lib\site-packages\twisted\internet\defer.py", line 1384, in _inlineCallbacks
    result = result.throwExceptionIntoGenerator(g)
  File "c:\users\xkdlr\appdata\local\programs\python\python36-32\lib\site-packages\twisted\python\failure.py", line 408, in throwExceptionIntoGenerator
    return g.throw(self.type, self.value, self.tb)
  File "c:\users\xkdlr\appdata\local\programs\python\python36-32\lib\site-packages\scrapy\core\downloader\middleware.py", line 43, in process_request
    defer.returnValue((yield download_func(request=request,spider=spider)))
  File "c:\users\xkdlr\appdata\local\programs\python\python36-32\lib\site-packages\twisted\internet\defer.py", line 653, in _runCallbacks
    current.result = callback(current.result, *args, **kw)
  File "c:\users\xkdlr\appdata\local\programs\python\python36-32\lib\site-packages\scrapy\core\downloader\handlers\http11.py", line 320, in _cb_timeout
    raise TimeoutError("Getting %s took longer than %s seconds." % (url, timeout))
twisted.internet.error.TimeoutError: User timeout caused connection failure: Getting http://web.humoruniv.com//board/humor/list.html?table=kin&pg=4 took longer than 30.0 seconds..
2017-10-11 23:18:49 [scrapy.core.scraper] ERROR: Error downloading <GET http://web.humoruniv.com/board/humor/list.html?table=fear&pg=4>
Traceback (most recent call last):
  File "c:\users\xkdlr\appdata\local\programs\python\python36-32\lib\site-packages\twisted\internet\defer.py", line 1384, in _inlineCallbacks
    result = result.throwExceptionIntoGenerator(g)
  File "c:\users\xkdlr\appdata\local\programs\python\python36-32\lib\site-packages\twisted\python\failure.py", line 408, in throwExceptionIntoGenerator
    return g.throw(self.type, self.value, self.tb)
  File "c:\users\xkdlr\appdata\local\programs\python\python36-32\lib\site-packages\scrapy\core\downloader\middleware.py", line 43, in process_request
    defer.returnValue((yield download_func(request=request,spider=spider)))
  File "c:\users\xkdlr\appdata\local\programs\python\python36-32\lib\site-packages\twisted\internet\defer.py", line 653, in _runCallbacks
    current.result = callback(current.result, *args, **kw)
  File "c:\users\xkdlr\appdata\local\programs\python\python36-32\lib\site-packages\scrapy\core\downloader\handlers\http11.py", line 320, in _cb_timeout
    raise TimeoutError("Getting %s took longer than %s seconds." % (url, timeout))
twisted.internet.error.TimeoutError: User timeout caused connection failure: Getting http://web.humoruniv.com/board/humor/list.html?table=fear&pg=4 took longer than 30.0 seconds..
2017-10-11 23:18:58 [scrapy.core.scraper] ERROR: Error downloading <GET http://web.humoruniv.com//board/humor/list.html?table=nova_toon&pg=4>: [<twisted.python.failure.Failure twisted.internet.error.ConnectionDone: Connection was closed cleanly.>]
2017-10-11 23:19:27 [scrapy.core.scraper] ERROR: Error downloading <GET http://web.humoruniv.com/board/humor/list.html?table=game&pg=4>
Traceback (most recent call last):
  File "c:\users\xkdlr\appdata\local\programs\python\python36-32\lib\site-packages\twisted\internet\defer.py", line 1384, in _inlineCallbacks
    result = result.throwExceptionIntoGenerator(g)
  File "c:\users\xkdlr\appdata\local\programs\python\python36-32\lib\site-packages\twisted\python\failure.py", line 408, in throwExceptionIntoGenerator
    return g.throw(self.type, self.value, self.tb)
  File "c:\users\xkdlr\appdata\local\programs\python\python36-32\lib\site-packages\scrapy\core\downloader\middleware.py", line 43, in process_request
    defer.returnValue((yield download_func(request=request,spider=spider)))
  File "c:\users\xkdlr\appdata\local\programs\python\python36-32\lib\site-packages\twisted\internet\defer.py", line 653, in _runCallbacks
    current.result = callback(current.result, *args, **kw)
  File "c:\users\xkdlr\appdata\local\programs\python\python36-32\lib\site-packages\scrapy\core\downloader\handlers\http11.py", line 320, in _cb_timeout
    raise TimeoutError("Getting %s took longer than %s seconds." % (url, timeout))
twisted.internet.error.TimeoutError: User timeout caused connection failure: Getting http://web.humoruniv.com/board/humor/list.html?table=game&pg=4 took longer than 30.0 seconds..
2017-10-11 23:19:27 [scrapy.core.scraper] ERROR: Error downloading <GET http://web.humoruniv.com/board/humor/list.html?table=thema2&pg=4>
Traceback (most recent call last):
  File "c:\users\xkdlr\appdata\local\programs\python\python36-32\lib\site-packages\twisted\internet\defer.py", line 1384, in _inlineCallbacks
    result = result.throwExceptionIntoGenerator(g)
  File "c:\users\xkdlr\appdata\local\programs\python\python36-32\lib\site-packages\twisted\python\failure.py", line 408, in throwExceptionIntoGenerator
    return g.throw(self.type, self.value, self.tb)
  File "c:\users\xkdlr\appdata\local\programs\python\python36-32\lib\site-packages\scrapy\core\downloader\middleware.py", line 43, in process_request
    defer.returnValue((yield download_func(request=request,spider=spider)))
  File "c:\users\xkdlr\appdata\local\programs\python\python36-32\lib\site-packages\twisted\internet\defer.py", line 653, in _runCallbacks
    current.result = callback(current.result, *args, **kw)
  File "c:\users\xkdlr\appdata\local\programs\python\python36-32\lib\site-packages\scrapy\core\downloader\handlers\http11.py", line 320, in _cb_timeout
    raise TimeoutError("Getting %s took longer than %s seconds." % (url, timeout))
twisted.internet.error.TimeoutError: User timeout caused connection failure: Getting http://web.humoruniv.com/board/humor/list.html?table=thema2&pg=4 took longer than 30.0 seconds..
2017-10-11 23:19:27 [scrapy.core.scraper] ERROR: Error downloading <GET http://web.humoruniv.com/board/humor/list.html?table=lol&pg=4>
Traceback (most recent call last):
  File "c:\users\xkdlr\appdata\local\programs\python\python36-32\lib\site-packages\twisted\internet\defer.py", line 1384, in _inlineCallbacks
    result = result.throwExceptionIntoGenerator(g)
  File "c:\users\xkdlr\appdata\local\programs\python\python36-32\lib\site-packages\twisted\python\failure.py", line 408, in throwExceptionIntoGenerator
    return g.throw(self.type, self.value, self.tb)
  File "c:\users\xkdlr\appdata\local\programs\python\python36-32\lib\site-packages\scrapy\core\downloader\middleware.py", line 43, in process_request
    defer.returnValue((yield download_func(request=request,spider=spider)))
  File "c:\users\xkdlr\appdata\local\programs\python\python36-32\lib\site-packages\twisted\internet\defer.py", line 653, in _runCallbacks
    current.result = callback(current.result, *args, **kw)
  File "c:\users\xkdlr\appdata\local\programs\python\python36-32\lib\site-packages\scrapy\core\downloader\handlers\http11.py", line 320, in _cb_timeout
    raise TimeoutError("Getting %s took longer than %s seconds." % (url, timeout))
twisted.internet.error.TimeoutError: User timeout caused connection failure: Getting http://web.humoruniv.com/board/humor/list.html?table=lol&pg=4 took longer than 30.0 seconds..
2017-10-11 23:19:39 [scrapy.core.scraper] ERROR: Error downloading <GET http://web.humoruniv.com/board/humor/list.html?table=poll&pg=4>
Traceback (most recent call last):
  File "c:\users\xkdlr\appdata\local\programs\python\python36-32\lib\site-packages\twisted\internet\defer.py", line 1384, in _inlineCallbacks
    result = result.throwExceptionIntoGenerator(g)
  File "c:\users\xkdlr\appdata\local\programs\python\python36-32\lib\site-packages\twisted\python\failure.py", line 408, in throwExceptionIntoGenerator
    return g.throw(self.type, self.value, self.tb)
  File "c:\users\xkdlr\appdata\local\programs\python\python36-32\lib\site-packages\scrapy\core\downloader\middleware.py", line 43, in process_request
    defer.returnValue((yield download_func(request=request,spider=spider)))
  File "c:\users\xkdlr\appdata\local\programs\python\python36-32\lib\site-packages\twisted\internet\defer.py", line 653, in _runCallbacks
    current.result = callback(current.result, *args, **kw)
  File "c:\users\xkdlr\appdata\local\programs\python\python36-32\lib\site-packages\scrapy\core\downloader\handlers\http11.py", line 320, in _cb_timeout
    raise TimeoutError("Getting %s took longer than %s seconds." % (url, timeout))
twisted.internet.error.TimeoutError: User timeout caused connection failure: Getting http://web.humoruniv.com/board/humor/list.html?table=poll&pg=4 took longer than 30.0 seconds..
2017-10-11 23:19:50 [scrapy.core.scraper] ERROR: Error downloading <GET http://web.humoruniv.com/board/humor/list.html?table=free&pg=4>
Traceback (most recent call last):
  File "c:\users\xkdlr\appdata\local\programs\python\python36-32\lib\site-packages\twisted\internet\defer.py", line 1384, in _inlineCallbacks
    result = result.throwExceptionIntoGenerator(g)
  File "c:\users\xkdlr\appdata\local\programs\python\python36-32\lib\site-packages\twisted\python\failure.py", line 408, in throwExceptionIntoGenerator
    return g.throw(self.type, self.value, self.tb)
  File "c:\users\xkdlr\appdata\local\programs\python\python36-32\lib\site-packages\scrapy\core\downloader\middleware.py", line 43, in process_request
    defer.returnValue((yield download_func(request=request,spider=spider)))
  File "c:\users\xkdlr\appdata\local\programs\python\python36-32\lib\site-packages\twisted\internet\defer.py", line 653, in _runCallbacks
    current.result = callback(current.result, *args, **kw)
  File "c:\users\xkdlr\appdata\local\programs\python\python36-32\lib\site-packages\scrapy\core\downloader\handlers\http11.py", line 320, in _cb_timeout
    raise TimeoutError("Getting %s took longer than %s seconds." % (url, timeout))
twisted.internet.error.TimeoutError: User timeout caused connection failure: Getting http://web.humoruniv.com/board/humor/list.html?table=free&pg=4 took longer than 30.0 seconds..
2017-10-11 23:19:50 [scrapy.core.scraper] ERROR: Error downloading <GET http://web.humoruniv.com/board/humor/list.html?table=guest&pg=4>
Traceback (most recent call last):
  File "c:\users\xkdlr\appdata\local\programs\python\python36-32\lib\site-packages\twisted\internet\defer.py", line 1384, in _inlineCallbacks
    result = result.throwExceptionIntoGenerator(g)
  File "c:\users\xkdlr\appdata\local\programs\python\python36-32\lib\site-packages\twisted\python\failure.py", line 408, in throwExceptionIntoGenerator
    return g.throw(self.type, self.value, self.tb)
  File "c:\users\xkdlr\appdata\local\programs\python\python36-32\lib\site-packages\scrapy\core\downloader\middleware.py", line 43, in process_request
    defer.returnValue((yield download_func(request=request,spider=spider)))
  File "c:\users\xkdlr\appdata\local\programs\python\python36-32\lib\site-packages\twisted\internet\defer.py", line 653, in _runCallbacks
    current.result = callback(current.result, *args, **kw)
  File "c:\users\xkdlr\appdata\local\programs\python\python36-32\lib\site-packages\scrapy\core\downloader\handlers\http11.py", line 320, in _cb_timeout
    raise TimeoutError("Getting %s took longer than %s seconds." % (url, timeout))
twisted.internet.error.TimeoutError: User timeout caused connection failure: Getting http://web.humoruniv.com/board/humor/list.html?table=guest&pg=4 took longer than 30.0 seconds..
2017-10-11 23:20:07 [scrapy.core.scraper] ERROR: Error downloading <GET http://web.humoruniv.com/board/humor/list.html?table=mild&pg=4>
Traceback (most recent call last):
  File "c:\users\xkdlr\appdata\local\programs\python\python36-32\lib\site-packages\twisted\internet\defer.py", line 1384, in _inlineCallbacks
    result = result.throwExceptionIntoGenerator(g)
  File "c:\users\xkdlr\appdata\local\programs\python\python36-32\lib\site-packages\twisted\python\failure.py", line 408, in throwExceptionIntoGenerator
    return g.throw(self.type, self.value, self.tb)
  File "c:\users\xkdlr\appdata\local\programs\python\python36-32\lib\site-packages\scrapy\core\downloader\middleware.py", line 43, in process_request
    defer.returnValue((yield download_func(request=request,spider=spider)))
  File "c:\users\xkdlr\appdata\local\programs\python\python36-32\lib\site-packages\twisted\internet\defer.py", line 653, in _runCallbacks
    current.result = callback(current.result, *args, **kw)
  File "c:\users\xkdlr\appdata\local\programs\python\python36-32\lib\site-packages\scrapy\core\downloader\handlers\http11.py", line 320, in _cb_timeout
    raise TimeoutError("Getting %s took longer than %s seconds." % (url, timeout))
twisted.internet.error.TimeoutError: User timeout caused connection failure: Getting http://web.humoruniv.com/board/humor/list.html?table=mild&pg=4 took longer than 30.0 seconds..
2017-10-11 23:20:07 [scrapy.core.scraper] ERROR: Error downloading <GET http://web.humoruniv.com/board/humor/list.html?table=pride&pg=4>
Traceback (most recent call last):
  File "c:\users\xkdlr\appdata\local\programs\python\python36-32\lib\site-packages\twisted\internet\defer.py", line 1384, in _inlineCallbacks
    result = result.throwExceptionIntoGenerator(g)
  File "c:\users\xkdlr\appdata\local\programs\python\python36-32\lib\site-packages\twisted\python\failure.py", line 408, in throwExceptionIntoGenerator
    return g.throw(self.type, self.value, self.tb)
  File "c:\users\xkdlr\appdata\local\programs\python\python36-32\lib\site-packages\scrapy\core\downloader\middleware.py", line 43, in process_request
    defer.returnValue((yield download_func(request=request,spider=spider)))
  File "c:\users\xkdlr\appdata\local\programs\python\python36-32\lib\site-packages\twisted\internet\defer.py", line 653, in _runCallbacks
    current.result = callback(current.result, *args, **kw)
  File "c:\users\xkdlr\appdata\local\programs\python\python36-32\lib\site-packages\scrapy\core\downloader\handlers\http11.py", line 320, in _cb_timeout
    raise TimeoutError("Getting %s took longer than %s seconds." % (url, timeout))
twisted.internet.error.TimeoutError: User timeout caused connection failure: Getting http://web.humoruniv.com/board/humor/list.html?table=pride&pg=4 took longer than 30.0 seconds..
2017-10-11 23:23:19 [scrapy.core.scraper] ERROR: Error downloading <GET http://web.humoruniv.com/board/humor/list.html?table=pride&pg=5>: [<twisted.python.failure.Failure twisted.internet.error.ConnectionDone: Connection was closed cleanly.>]
2017-10-11 23:23:28 [scrapy.core.scraper] ERROR: Error downloading <GET http://web.humoruniv.com/board/humor/list.html?table=muzik&pg=5>: [<twisted.python.failure.Failure twisted.internet.error.ConnectionDone: Connection was closed cleanly.>]
2017-10-11 23:23:53 [scrapy.core.scraper] ERROR: Error downloading <GET http://web.humoruniv.com/board/humor/list.html?table=thema2&pg=5>
Traceback (most recent call last):
  File "c:\users\xkdlr\appdata\local\programs\python\python36-32\lib\site-packages\twisted\internet\defer.py", line 1384, in _inlineCallbacks
    result = result.throwExceptionIntoGenerator(g)
  File "c:\users\xkdlr\appdata\local\programs\python\python36-32\lib\site-packages\twisted\python\failure.py", line 408, in throwExceptionIntoGenerator
    return g.throw(self.type, self.value, self.tb)
  File "c:\users\xkdlr\appdata\local\programs\python\python36-32\lib\site-packages\scrapy\core\downloader\middleware.py", line 43, in process_request
    defer.returnValue((yield download_func(request=request,spider=spider)))
  File "c:\users\xkdlr\appdata\local\programs\python\python36-32\lib\site-packages\twisted\internet\defer.py", line 653, in _runCallbacks
    current.result = callback(current.result, *args, **kw)
  File "c:\users\xkdlr\appdata\local\programs\python\python36-32\lib\site-packages\scrapy\core\downloader\handlers\http11.py", line 320, in _cb_timeout
    raise TimeoutError("Getting %s took longer than %s seconds." % (url, timeout))
twisted.internet.error.TimeoutError: User timeout caused connection failure: Getting http://web.humoruniv.com/board/humor/list.html?table=thema2&pg=5 took longer than 30.0 seconds..
2017-10-11 23:23:53 [scrapy.core.scraper] ERROR: Error downloading <GET http://web.humoruniv.com/board/humor/list.html?table=lol&pg=5>
Traceback (most recent call last):
  File "c:\users\xkdlr\appdata\local\programs\python\python36-32\lib\site-packages\twisted\internet\defer.py", line 1384, in _inlineCallbacks
    result = result.throwExceptionIntoGenerator(g)
  File "c:\users\xkdlr\appdata\local\programs\python\python36-32\lib\site-packages\twisted\python\failure.py", line 408, in throwExceptionIntoGenerator
    return g.throw(self.type, self.value, self.tb)
  File "c:\users\xkdlr\appdata\local\programs\python\python36-32\lib\site-packages\scrapy\core\downloader\middleware.py", line 43, in process_request
    defer.returnValue((yield download_func(request=request,spider=spider)))
  File "c:\users\xkdlr\appdata\local\programs\python\python36-32\lib\site-packages\twisted\internet\defer.py", line 653, in _runCallbacks
    current.result = callback(current.result, *args, **kw)
  File "c:\users\xkdlr\appdata\local\programs\python\python36-32\lib\site-packages\scrapy\core\downloader\handlers\http11.py", line 320, in _cb_timeout
    raise TimeoutError("Getting %s took longer than %s seconds." % (url, timeout))
twisted.internet.error.TimeoutError: User timeout caused connection failure: Getting http://web.humoruniv.com/board/humor/list.html?table=lol&pg=5 took longer than 30.0 seconds..
2017-10-11 23:24:32 [scrapy.core.scraper] ERROR: Error downloading <GET http://web.humoruniv.com/board/humor/list.html?table=whitehand&pg=5>: [<twisted.python.failure.Failure twisted.internet.error.ConnectionDone: Connection was closed cleanly.>]
2017-10-11 23:24:32 [scrapy.core.scraper] ERROR: Error downloading <GET http://web.humoruniv.com/board/humor/list.html?table=workshop&pg=5>: [<twisted.python.failure.Failure twisted.internet.error.ConnectionDone: Connection was closed cleanly.>]
2017-10-11 23:25:10 [scrapy.core.scraper] ERROR: Error downloading <GET http://web.humoruniv.com/board/humor/list.html?table=car&pg=5>
Traceback (most recent call last):
  File "c:\users\xkdlr\appdata\local\programs\python\python36-32\lib\site-packages\twisted\internet\defer.py", line 1384, in _inlineCallbacks
    result = result.throwExceptionIntoGenerator(g)
  File "c:\users\xkdlr\appdata\local\programs\python\python36-32\lib\site-packages\twisted\python\failure.py", line 408, in throwExceptionIntoGenerator
    return g.throw(self.type, self.value, self.tb)
  File "c:\users\xkdlr\appdata\local\programs\python\python36-32\lib\site-packages\scrapy\core\downloader\middleware.py", line 43, in process_request
    defer.returnValue((yield download_func(request=request,spider=spider)))
  File "c:\users\xkdlr\appdata\local\programs\python\python36-32\lib\site-packages\twisted\internet\defer.py", line 653, in _runCallbacks
    current.result = callback(current.result, *args, **kw)
  File "c:\users\xkdlr\appdata\local\programs\python\python36-32\lib\site-packages\scrapy\core\downloader\handlers\http11.py", line 320, in _cb_timeout
    raise TimeoutError("Getting %s took longer than %s seconds." % (url, timeout))
twisted.internet.error.TimeoutError: User timeout caused connection failure: Getting http://web.humoruniv.com/board/humor/list.html?table=car&pg=5 took longer than 30.0 seconds..
2017-10-11 23:25:10 [scrapy.core.scraper] ERROR: Error downloading <GET http://web.humoruniv.com/board/humor/list.html?table=solo&pg=5>
Traceback (most recent call last):
  File "c:\users\xkdlr\appdata\local\programs\python\python36-32\lib\site-packages\twisted\internet\defer.py", line 1384, in _inlineCallbacks
    result = result.throwExceptionIntoGenerator(g)
  File "c:\users\xkdlr\appdata\local\programs\python\python36-32\lib\site-packages\twisted\python\failure.py", line 408, in throwExceptionIntoGenerator
    return g.throw(self.type, self.value, self.tb)
  File "c:\users\xkdlr\appdata\local\programs\python\python36-32\lib\site-packages\scrapy\core\downloader\middleware.py", line 43, in process_request
    defer.returnValue((yield download_func(request=request,spider=spider)))
  File "c:\users\xkdlr\appdata\local\programs\python\python36-32\lib\site-packages\twisted\internet\defer.py", line 653, in _runCallbacks
    current.result = callback(current.result, *args, **kw)
  File "c:\users\xkdlr\appdata\local\programs\python\python36-32\lib\site-packages\scrapy\core\downloader\handlers\http11.py", line 320, in _cb_timeout
    raise TimeoutError("Getting %s took longer than %s seconds." % (url, timeout))
twisted.internet.error.TimeoutError: User timeout caused connection failure: Getting http://web.humoruniv.com/board/humor/list.html?table=solo&pg=5 took longer than 30.0 seconds..
2017-10-11 23:28:23 [scrapy.core.scraper] ERROR: Error downloading <GET http://web.humoruniv.com/board/humor/list.html?table=muzik&pg=6>: [<twisted.python.failure.Failure twisted.internet.error.ConnectionDone: Connection was closed cleanly.>]
2017-10-11 23:28:39 [scrapy.core.scraper] ERROR: Error downloading <GET http://web.humoruniv.com/board/humor/list.html?table=whitehand&pg=6>: [<twisted.python.failure.Failure twisted.internet.error.ConnectionDone: Connection was closed cleanly.>]
2017-10-11 23:28:53 [scrapy.core.scraper] ERROR: Error downloading <GET http://web.humoruniv.com/board/humor/list.html?table=workshop&pg=6>: [<twisted.python.failure.Failure twisted.internet.error.ConnectionDone: Connection was closed cleanly.>]
2017-10-11 23:30:38 [scrapy.core.scraper] ERROR: Error downloading <GET http://web.humoruniv.com/board/humor/list.html?table=fear&pg=7>: [<twisted.python.failure.Failure twisted.internet.error.ConnectionDone: Connection was closed cleanly.>]
2017-10-11 23:30:38 [scrapy.core.scraper] ERROR: Error downloading <GET http://web.humoruniv.com/board/humor/list.html?table=mild&pg=7>: [<twisted.python.failure.Failure twisted.internet.error.ConnectionDone: Connection was closed cleanly.>]
2017-10-11 23:30:38 [scrapy.core.scraper] ERROR: Error downloading <GET http://web.humoruniv.com/board/humor/list.html?table=game&pg=7>: [<twisted.python.failure.Failure twisted.internet.error.ConnectionDone: Connection was closed cleanly.>]
2017-10-11 23:30:47 [scrapy.core.scraper] ERROR: Error downloading <GET http://web.humoruniv.com/board/humor/list.html?table=thema2&pg=7>
Traceback (most recent call last):
  File "c:\users\xkdlr\appdata\local\programs\python\python36-32\lib\site-packages\twisted\internet\defer.py", line 1384, in _inlineCallbacks
    result = result.throwExceptionIntoGenerator(g)
  File "c:\users\xkdlr\appdata\local\programs\python\python36-32\lib\site-packages\twisted\python\failure.py", line 408, in throwExceptionIntoGenerator
    return g.throw(self.type, self.value, self.tb)
  File "c:\users\xkdlr\appdata\local\programs\python\python36-32\lib\site-packages\scrapy\core\downloader\middleware.py", line 43, in process_request
    defer.returnValue((yield download_func(request=request,spider=spider)))
  File "c:\users\xkdlr\appdata\local\programs\python\python36-32\lib\site-packages\twisted\internet\defer.py", line 653, in _runCallbacks
    current.result = callback(current.result, *args, **kw)
  File "c:\users\xkdlr\appdata\local\programs\python\python36-32\lib\site-packages\scrapy\core\downloader\handlers\http11.py", line 320, in _cb_timeout
    raise TimeoutError("Getting %s took longer than %s seconds." % (url, timeout))
twisted.internet.error.TimeoutError: User timeout caused connection failure: Getting http://web.humoruniv.com/board/humor/list.html?table=thema2&pg=7 took longer than 30.0 seconds..
2017-10-11 23:30:54 [scrapy.core.scraper] ERROR: Error downloading <GET http://web.humoruniv.com/board/humor/list.html?table=muzik&pg=7>: [<twisted.python.failure.Failure twisted.internet.error.ConnectionDone: Connection was closed cleanly.>]
2017-10-11 23:31:10 [scrapy.core.scraper] ERROR: Error downloading <GET http://web.humoruniv.com/board/humor/list.html?table=com&pg=7>
Traceback (most recent call last):
  File "c:\users\xkdlr\appdata\local\programs\python\python36-32\lib\site-packages\twisted\internet\defer.py", line 1384, in _inlineCallbacks
    result = result.throwExceptionIntoGenerator(g)
  File "c:\users\xkdlr\appdata\local\programs\python\python36-32\lib\site-packages\twisted\python\failure.py", line 408, in throwExceptionIntoGenerator
    return g.throw(self.type, self.value, self.tb)
  File "c:\users\xkdlr\appdata\local\programs\python\python36-32\lib\site-packages\scrapy\core\downloader\middleware.py", line 43, in process_request
    defer.returnValue((yield download_func(request=request,spider=spider)))
  File "c:\users\xkdlr\appdata\local\programs\python\python36-32\lib\site-packages\twisted\internet\defer.py", line 653, in _runCallbacks
    current.result = callback(current.result, *args, **kw)
  File "c:\users\xkdlr\appdata\local\programs\python\python36-32\lib\site-packages\scrapy\core\downloader\handlers\http11.py", line 320, in _cb_timeout
    raise TimeoutError("Getting %s took longer than %s seconds." % (url, timeout))
twisted.internet.error.TimeoutError: User timeout caused connection failure: Getting http://web.humoruniv.com/board/humor/list.html?table=com&pg=7 took longer than 30.0 seconds..
2017-10-11 23:31:12 [scrapy.core.scraper] ERROR: Error downloading <GET http://web.humoruniv.com/board/humor/list.html?table=lol&pg=7>: [<twisted.python.failure.Failure twisted.internet.error.ConnectionDone: Connection was closed cleanly.>]
2017-10-11 23:31:12 [scrapy.core.scraper] ERROR: Error downloading <GET http://web.humoruniv.com/board/humor/list.html?table=spnatural&pg=7>: [<twisted.python.failure.Failure twisted.internet.error.ConnectionDone: Connection was closed cleanly.>]
2017-10-11 23:31:31 [scrapy.core.scraper] ERROR: Error downloading <GET http://web.humoruniv.com/board/humor/list.html?table=sns&pg=7>: [<twisted.python.failure.Failure twisted.internet.error.ConnectionDone: Connection was closed cleanly.>]
2017-10-11 23:31:33 [scrapy.core.scraper] ERROR: Error downloading <GET http://web.humoruniv.com/board/humor/list.html?table=solo&pg=7>
Traceback (most recent call last):
  File "c:\users\xkdlr\appdata\local\programs\python\python36-32\lib\site-packages\twisted\internet\defer.py", line 1384, in _inlineCallbacks
    result = result.throwExceptionIntoGenerator(g)
  File "c:\users\xkdlr\appdata\local\programs\python\python36-32\lib\site-packages\twisted\python\failure.py", line 408, in throwExceptionIntoGenerator
    return g.throw(self.type, self.value, self.tb)
  File "c:\users\xkdlr\appdata\local\programs\python\python36-32\lib\site-packages\scrapy\core\downloader\middleware.py", line 43, in process_request
    defer.returnValue((yield download_func(request=request,spider=spider)))
  File "c:\users\xkdlr\appdata\local\programs\python\python36-32\lib\site-packages\twisted\internet\defer.py", line 653, in _runCallbacks
    current.result = callback(current.result, *args, **kw)
  File "c:\users\xkdlr\appdata\local\programs\python\python36-32\lib\site-packages\scrapy\core\downloader\handlers\http11.py", line 320, in _cb_timeout
    raise TimeoutError("Getting %s took longer than %s seconds." % (url, timeout))
twisted.internet.error.TimeoutError: User timeout caused connection failure: Getting http://web.humoruniv.com/board/humor/list.html?table=solo&pg=7 took longer than 30.0 seconds..
2017-10-11 23:31:47 [scrapy.core.scraper] ERROR: Error downloading <GET http://web.humoruniv.com//board/humor/list.html?table=art_toon&pg=8>
Traceback (most recent call last):
  File "c:\users\xkdlr\appdata\local\programs\python\python36-32\lib\site-packages\twisted\internet\defer.py", line 1384, in _inlineCallbacks
    result = result.throwExceptionIntoGenerator(g)
  File "c:\users\xkdlr\appdata\local\programs\python\python36-32\lib\site-packages\twisted\python\failure.py", line 408, in throwExceptionIntoGenerator
    return g.throw(self.type, self.value, self.tb)
  File "c:\users\xkdlr\appdata\local\programs\python\python36-32\lib\site-packages\scrapy\core\downloader\middleware.py", line 43, in process_request
    defer.returnValue((yield download_func(request=request,spider=spider)))
  File "c:\users\xkdlr\appdata\local\programs\python\python36-32\lib\site-packages\twisted\internet\defer.py", line 653, in _runCallbacks
    current.result = callback(current.result, *args, **kw)
  File "c:\users\xkdlr\appdata\local\programs\python\python36-32\lib\site-packages\scrapy\core\downloader\handlers\http11.py", line 320, in _cb_timeout
    raise TimeoutError("Getting %s took longer than %s seconds." % (url, timeout))
twisted.internet.error.TimeoutError: User timeout caused connection failure: Getting http://web.humoruniv.com//board/humor/list.html?table=art_toon&pg=8 took longer than 30.0 seconds..
2017-10-11 23:31:47 [scrapy.core.scraper] ERROR: Error downloading <GET http://web.humoruniv.com/board/humor/list.html?table=fear&pg=8>
Traceback (most recent call last):
  File "c:\users\xkdlr\appdata\local\programs\python\python36-32\lib\site-packages\twisted\internet\defer.py", line 1384, in _inlineCallbacks
    result = result.throwExceptionIntoGenerator(g)
  File "c:\users\xkdlr\appdata\local\programs\python\python36-32\lib\site-packages\twisted\python\failure.py", line 408, in throwExceptionIntoGenerator
    return g.throw(self.type, self.value, self.tb)
  File "c:\users\xkdlr\appdata\local\programs\python\python36-32\lib\site-packages\scrapy\core\downloader\middleware.py", line 43, in process_request
    defer.returnValue((yield download_func(request=request,spider=spider)))
  File "c:\users\xkdlr\appdata\local\programs\python\python36-32\lib\site-packages\twisted\internet\defer.py", line 653, in _runCallbacks
    current.result = callback(current.result, *args, **kw)
  File "c:\users\xkdlr\appdata\local\programs\python\python36-32\lib\site-packages\scrapy\core\downloader\handlers\http11.py", line 320, in _cb_timeout
    raise TimeoutError("Getting %s took longer than %s seconds." % (url, timeout))
twisted.internet.error.TimeoutError: User timeout caused connection failure: Getting http://web.humoruniv.com/board/humor/list.html?table=fear&pg=8 took longer than 30.0 seconds..
2017-10-11 23:31:47 [scrapy.core.scraper] ERROR: Error downloading <GET http://web.humoruniv.com/board/humor/list.html?table=pride&pg=8>
Traceback (most recent call last):
  File "c:\users\xkdlr\appdata\local\programs\python\python36-32\lib\site-packages\twisted\internet\defer.py", line 1384, in _inlineCallbacks
    result = result.throwExceptionIntoGenerator(g)
  File "c:\users\xkdlr\appdata\local\programs\python\python36-32\lib\site-packages\twisted\python\failure.py", line 408, in throwExceptionIntoGenerator
    return g.throw(self.type, self.value, self.tb)
  File "c:\users\xkdlr\appdata\local\programs\python\python36-32\lib\site-packages\scrapy\core\downloader\middleware.py", line 43, in process_request
    defer.returnValue((yield download_func(request=request,spider=spider)))
  File "c:\users\xkdlr\appdata\local\programs\python\python36-32\lib\site-packages\twisted\internet\defer.py", line 653, in _runCallbacks
    current.result = callback(current.result, *args, **kw)
  File "c:\users\xkdlr\appdata\local\programs\python\python36-32\lib\site-packages\scrapy\core\downloader\handlers\http11.py", line 320, in _cb_timeout
    raise TimeoutError("Getting %s took longer than %s seconds." % (url, timeout))
twisted.internet.error.TimeoutError: User timeout caused connection failure: Getting http://web.humoruniv.com/board/humor/list.html?table=pride&pg=8 took longer than 30.0 seconds..
2017-10-11 23:31:47 [scrapy.core.scraper] ERROR: Error downloading <GET http://web.humoruniv.com/board/humor/list.html?table=lol&pg=8>
Traceback (most recent call last):
  File "c:\users\xkdlr\appdata\local\programs\python\python36-32\lib\site-packages\twisted\internet\defer.py", line 1384, in _inlineCallbacks
    result = result.throwExceptionIntoGenerator(g)
  File "c:\users\xkdlr\appdata\local\programs\python\python36-32\lib\site-packages\twisted\python\failure.py", line 408, in throwExceptionIntoGenerator
    return g.throw(self.type, self.value, self.tb)
  File "c:\users\xkdlr\appdata\local\programs\python\python36-32\lib\site-packages\scrapy\core\downloader\middleware.py", line 43, in process_request
    defer.returnValue((yield download_func(request=request,spider=spider)))
  File "c:\users\xkdlr\appdata\local\programs\python\python36-32\lib\site-packages\twisted\internet\defer.py", line 653, in _runCallbacks
    current.result = callback(current.result, *args, **kw)
  File "c:\users\xkdlr\appdata\local\programs\python\python36-32\lib\site-packages\scrapy\core\downloader\handlers\http11.py", line 320, in _cb_timeout
    raise TimeoutError("Getting %s took longer than %s seconds." % (url, timeout))
twisted.internet.error.TimeoutError: User timeout caused connection failure: Getting http://web.humoruniv.com/board/humor/list.html?table=lol&pg=8 took longer than 30.0 seconds..
2017-10-11 23:31:47 [scrapy.core.scraper] ERROR: Error downloading <GET http://web.humoruniv.com/board/humor/list.html?table=thema2&pg=8>
Traceback (most recent call last):
  File "c:\users\xkdlr\appdata\local\programs\python\python36-32\lib\site-packages\twisted\internet\defer.py", line 1384, in _inlineCallbacks
    result = result.throwExceptionIntoGenerator(g)
  File "c:\users\xkdlr\appdata\local\programs\python\python36-32\lib\site-packages\twisted\python\failure.py", line 408, in throwExceptionIntoGenerator
    return g.throw(self.type, self.value, self.tb)
  File "c:\users\xkdlr\appdata\local\programs\python\python36-32\lib\site-packages\scrapy\core\downloader\middleware.py", line 43, in process_request
    defer.returnValue((yield download_func(request=request,spider=spider)))
  File "c:\users\xkdlr\appdata\local\programs\python\python36-32\lib\site-packages\twisted\internet\defer.py", line 653, in _runCallbacks
    current.result = callback(current.result, *args, **kw)
  File "c:\users\xkdlr\appdata\local\programs\python\python36-32\lib\site-packages\scrapy\core\downloader\handlers\http11.py", line 320, in _cb_timeout
    raise TimeoutError("Getting %s took longer than %s seconds." % (url, timeout))
twisted.internet.error.TimeoutError: User timeout caused connection failure: Getting http://web.humoruniv.com/board/humor/list.html?table=thema2&pg=8 took longer than 30.0 seconds..
2017-10-11 23:31:51 [scrapy.core.scraper] ERROR: Error downloading <GET http://web.humoruniv.com/board/humor/list.html?table=muzik&pg=8>: [<twisted.python.failure.Failure twisted.internet.error.ConnectionDone: Connection was closed cleanly.>]
2017-10-11 23:31:51 [scrapy.core.scraper] ERROR: Error downloading <GET http://web.humoruniv.com/board/humor/list.html?table=sns&pg=8>: [<twisted.python.failure.Failure twisted.internet.error.ConnectionDone: Connection was closed cleanly.>]
